<?xml version="1.0" ?>
<!-- =================================================================================== -->
<!-- |    This document was autogenerated by xacro from export_NICOL_to_urdf.xacro     | -->
<!-- |    EDITING THIS FILE BY HAND IS NOT RECOMMENDED                                 | -->
<!-- =================================================================================== -->
<!-- ############################################## -->
<!-- Use only to export NICOL to a single urdf file -->
<!-- ############################################## -->
<robot name="NICOL">
  <!-- arg: "use_frame_arg" launch NICOL with or without robot frame -->
  <!-- Frame materials -->
  <material name="profile">
    <color rgba="0.5 0.5 0.5 1.0"/>
  </material>
  <material name="plate">
    <color rgba="0.5 0.5 0.5 1.0"/>
  </material>
  <material name="grey">
    <color rgba="0.2 0.2 0.2 1.0"/>
  </material>
  <material name="silver">
    <color rgba="0.8 0.8 0.8 1.0"/>
  </material>
  <material name="dark_white">
    <color rgba="0.9 0.9 0.9 1.0"/>
  </material>
  <material name="yellow">
    <color rgba="0 1 1 1"/>
  </material>
  <!-- RH8D -->
  <material name="rh8d_color">
    <color rgba="0.74902 0.74902 0.74902 1.0"/>
  </material>
  <!-- Gazebo -->
  <material name="black">
    <color rgba="0.0 0.0 0.0 1.0"/>
  </material>
  <material name="blue">
    <color rgba="0.0 0.0 0.8 1.0"/>
  </material>
  <material name="green">
    <color rgba="0.0 0.8 0.0 1.0"/>
  </material>
  <material name="deep_grey">
    <color rgba="0.5 0.5 0.5 1.0"/>
  </material>
  <material name="orange">
    <color rgba="1.0 0.4235294117647059 0.0392156862745098 1.0"/>
  </material>
  <material name="brown">
    <color rgba="0.8705882352941177 0.8117647058823529 0.7647058823529411 1.0"/>
  </material>
  <material name="red">
    <color rgba="0.8 0.0 0.0 1.0"/>
  </material>
  <material name="white">
    <color rgba="1.0 1.0 1.0 1.0"/>
  </material>
  <!-- ########################## properties ############################## -->
  <!-- ########################## transmission macro ############################## -->
  <!-- thumb macro -->
  <!-- finger macro -->
  <!-- Right palm macro -->
  <!--### RH8D joints ###-->
  <!-- ############################# frame macros ################################# -->
  <!-- World, center of global coordinate system-->
  <link name="world">
  </link>
  <!-- origin at center of manipulator socket -->
  <joint name="base_joint" type="fixed">
    <parent link="world"/>
    <child link="base_link"/>
    <origin xyz="0 0 0.8"/>
  </joint>
  <!-- robot frame origin at back upper center of plate -->
  <joint name="frame_joint" type="fixed">
    <parent link="world"/>
    <child link="frame_link"/>
    <origin xyz="0 0 0.8"/>
  </joint>
  <!-- visual robot frame working plate -->
  <joint name="plate_joint" type="fixed">
    <parent link="frame_link"/>
    <child link="plate_link"/>
    <origin rpy="0.0 0.0 0.0" xyz="0.0 0.0 0.0"/>
  </joint>
  <joint name="front_left_collision_joint" type="fixed">
    <parent link="frame_link"/>
    <child link="front_left_collision_link"/>
    <origin rpy="0 0 0" xyz="0.0225 -0.9775 0.50"/>
  </joint>
  <joint name="front_right_collision_joint" type="fixed">
    <parent link="frame_link"/>
    <child link="front_right_collision_link"/>
    <origin rpy="0 0 0" xyz="0.0225 0.9775 0.50"/>
  </joint>
  <joint name="rear_left_collision_joint" type="fixed">
    <parent link="frame_link"/>
    <child link="rear_left_collision_link"/>
    <origin rpy="0 0 0" xyz="0.9775 -0.9775 0.50"/>
  </joint>
  <joint name="rear_right_collision_joint" type="fixed">
    <parent link="frame_link"/>
    <child link="rear_right_collision_link"/>
    <origin rpy="0 0 0" xyz="0.9775 0.9775 0.50"/>
  </joint>
  <joint name="front_collision_joint" type="fixed">
    <parent link="frame_link"/>
    <child link="front_collision_link"/>
    <origin rpy="0 0 0" xyz="0.0225 0.0 0.92"/>
  </joint>
  <joint name="rear_collision_joint" type="fixed">
    <parent link="frame_link"/>
    <child link="rear_collision_link"/>
    <origin rpy="0 0 0" xyz="0.9775 0.0 0.92"/>
  </joint>
  <joint name="left_collision_joint" type="fixed">
    <parent link="frame_link"/>
    <child link="left_collision_link"/>
    <origin rpy="0 0 0" xyz="0.5 -0.9775 0.92"/>
  </joint>
  <joint name="right_collision_joint" type="fixed">
    <parent link="frame_link"/>
    <child link="right_collision_link"/>
    <origin rpy="0 0 0" xyz="0.5 0.9775 0.92"/>
  </joint>
  <!-- end conditional robot frame include -->
  <!-- additional collision here to model NICOL's "chest" -->
  <joint name="chest_collision_joint" type="fixed">
    <parent link="base_link"/>
    <child link="chest_collision_link"/>
    <origin rpy="0.0 0.0 0.0" xyz="0.011 0.0 0.4"/>
  </joint>
  <!-- neck joint -->
  <joint name="neck_joint" type="fixed">
    <parent link="base_link"/>
    <child link="neck_link"/>
    <origin rpy="0 0 0" xyz="0 0 0.42"/>
  </joint>
  <!-- head tilt joint -->
  <joint name="head_y" type="revolute">
    <parent link="tilt_link"/>
    <child link="head_link"/>
    <origin rpy="0 0 0" xyz="0 0 0.059"/>
    <axis xyz="0 1 0"/>
    <limit effort="30" lower="-1.553" upper="1.379" velocity="1"/>
    <dynamics damping="0.01"/>
  </joint>
  <transmission name="tran14">
    <type>transmission_interface/SimpleTransmission</type>
    <joint name="head_y">
      <hardwareInterface>hardware_interface/PositionJointInterface</hardwareInterface>
    </joint>
    <actuator name="motor14">
      <hardwareInterface>hardware_interface/PositionJointInterface</hardwareInterface>
      <mechanicalReduction>1</mechanicalReduction>
    </actuator>
  </transmission>
  <!-- head pan joint -->
  <joint name="head_z" type="revolute">
    <parent link="neck_link"/>
    <child link="tilt_link"/>
    <origin rpy="0 0 0" xyz="0.188158 -0.0002 0.1415"/>
    <axis xyz="0 0 1"/>
    <limit effort="30" lower="-3.124" upper="3.142" velocity="1"/>
    <dynamics damping="0.01"/>
  </joint>
  <transmission name="tran13">
    <type>transmission_interface/SimpleTransmission</type>
    <joint name="head_z">
      <hardwareInterface>hardware_interface/PositionJointInterface</hardwareInterface>
    </joint>
    <actuator name="motor13">
      <hardwareInterface>hardware_interface/PositionJointInterface</hardwareInterface>
      <mechanicalReduction>1</mechanicalReduction>
    </actuator>
  </transmission>
  <!-- occiput -->
  <joint name="occiput_joint" type="fixed">
    <parent link="head_link"/>
    <child link="occiput_link"/>
    <origin rpy="0 0 0" xyz="-0.0045 0 0.03"/>
  </joint>
  <!-- left eye joint -->
  <joint name="left_eye_joint" type="fixed">
    <parent link="head_link"/>
    <child link="left_eye_link"/>
    <origin rpy="0 0 0" xyz="0.108 -0.0466 0.0975"/>
  </joint>
  <!-- right eye joint -->
  <joint name="right_eye_joint" type="fixed">
    <parent link="head_link"/>
    <child link="right_eye_link"/>
    <origin rpy="0 0 0" xyz="0.108 0.0466 0.0975"/>
  </joint>
  <!-- Append head joints -->
  <!-- camera holder joint -->
  <joint name="camera_holder_joint" type="fixed">
    <parent link="world"/>
    <!-- frame tf -->
    <!-- <parent link="frame_link"/> -->
    <child link="camera_holder_link"/>
    <origin rpy="0 -2.827433388230814 0" xyz="0.9 0 1.965"/>
    <!-- frame tf -->
    <!-- <origin xyz="0.9 0 1.165" rpy="0 ${-pi*0.9} 0"/> -->
  </joint>
  <!-- camera joint -->
  <joint name="camera_joint" type="fixed">
    <parent link="camera_holder_link"/>
    <child link="camera_link"/>
    <origin rpy="0 -1.5707963267948966 0" xyz="0.035 0 0.04"/>
  </joint>
  <joint name="$realsense_joint" type="fixed">
    <!--    <origin xyz="0 0 0" rpy="0 0 0" /> -->
    <origin rpy="3.141592653589793 -1.8849555921538759 -1.5707963267948966" xyz="0 0 0"/>
    <parent link="camera_link"/>
    <child link="realsense_link"/>
  </joint>
  <!-- ################### Links ##################### -->
  <!-- NICOL holder  -->
  <link name="base_link">
    <visual>
      <origin rpy="0 0 0" xyz="0 0 0"/>
      <geometry>
        <mesh filename="/export/home/strahl/dev/gaikpy/resources/urdf/nicol/meshes/robot_frame/single_profile_45mm_holder_with_socket_centered.stl" scale="0.001 0.001 0.001"/>
      </geometry>
      <material name="silver"/>
    </visual>
    <collision>
      <!-- collision simplified to box -->
      <origin rpy="0 0 0" xyz="-0.0225 0 0.5"/>
      <geometry>
        <!-- <mesh filename="${stl_path}single_profile_45mm_holder_with_socket_centered.stl" scale="${stl_scale}"/> -->
        <box size="0.045 0.1 1.0"/>
      </geometry>
    </collision>
    <inertial>
      <origin rpy="0 -0.0005235988 0" xyz="-0.022 0.0 -0.720"/>
      <mass value="515.106"/>
      <inertia ixx="2.4662489606e01" ixy="4.29e-07" ixz="-8.927336e-03" iyy=" 2.4652408384e01" iyz="1.401e-05" izz="7.601222788"/>
    </inertial>
  </link>
  <!-- the robot frame -->
  <link name="frame_link">
    <visual>
      <origin rpy="0 0 0" xyz="0 0 0"/>
      <geometry>
        <mesh filename="/export/home/strahl/dev/gaikpy/resources/urdf/nicol/meshes/robot_frame/robot_frame_without_holder_centered.stl" scale="0.001 0.001 0.001"/>
      </geometry>
      <material name="silver"/>
    </visual>
    <collision>
      <!-- collision simplified and modeled seperately by macros -->
      <origin rpy="0 0 0" xyz="0.5 0 -0.3"/>
      <geometry>
        <!-- <mesh filename="${stl_path}robot_frame_without_holder_centered.stl" scale="${stl_scale}"/> -->
        <box size="0.001 0.001 0.001"/>
      </geometry>
    </collision>
    <inertial>
      <origin rpy="0.16 -0.00034906585 0.0" xyz="0.49976 0.00041 0.14744"/>
      <mass value="160.44921"/>
      <inertia ixx="169.08979" ixy="-0.00367" ixz="-0.02295" iyy="110.93993" iyz="0.07994" izz="109.17499"/>
    </inertial>
  </link>
  <!-- the visual working plate -->
  <link name="plate_link">
    <visual>
      <origin rpy="0 0 0" xyz="0 0 0"/>
      <geometry>
        <mesh filename="/export/home/strahl/dev/gaikpy/resources/urdf/nicol/meshes/robot_frame/plate_centered.stl" scale="0.001 0.001 0.001"/>
      </geometry>
      <material name="white"/>
    </visual>
    <collision>
      <!-- collision simplified to box -->
      <origin rpy="0 0 0" xyz="0.5 0 -0.01"/>
      <geometry>
        <!-- <mesh filename="${stl_path}plate_centered.stl" scale="${stl_scale}"/> -->
        <box size="1.0 2.0 0.02"/>
      </geometry>
    </collision>
    <inertial>
      <origin rpy="0 0 0" xyz="0.50000 0.0 -0.00500"/>
      <mass value="32.37865"/>
      <inertia ixx="10.70845" ixy="0.0" ixz="0.0" iyy="2.67842" iyz="0.0" izz="13.38633"/>
    </inertial>
  </link>
  <link name="front_left_collision_link">
    <collision>
      <origin xyz="0 0 0"/>
      <geometry>
        <!-- extend along the z axis -->
        <box size="0.045 0.045 1.0"/>
      </geometry>
    </collision>
    <!-- visualization not desired -->
    <!-- <visual>
            <origin xyz="0 0 0"/>
            <geometry>
              <box size="${profile_diameter} ${profile_diameter} ${vertical_profile_length}"/>
            </geometry>
            <material name="blue"/>
          </visual> -->
  </link>
  <link name="front_right_collision_link">
    <collision>
      <origin xyz="0 0 0"/>
      <geometry>
        <!-- extend along the z axis -->
        <box size="0.045 0.045 1.0"/>
      </geometry>
    </collision>
    <!-- visualization not desired -->
    <!-- <visual>
            <origin xyz="0 0 0"/>
            <geometry>
              <box size="${profile_diameter} ${profile_diameter} ${vertical_profile_length}"/>
            </geometry>
            <material name="blue"/>
          </visual> -->
  </link>
  <link name="rear_left_collision_link">
    <collision>
      <origin xyz="0 0 0"/>
      <geometry>
        <!-- extend along the z axis -->
        <box size="0.045 0.045 1.0"/>
      </geometry>
    </collision>
    <!-- visualization not desired -->
    <!-- <visual>
            <origin xyz="0 0 0"/>
            <geometry>
              <box size="${profile_diameter} ${profile_diameter} ${vertical_profile_length}"/>
            </geometry>
            <material name="blue"/>
          </visual> -->
  </link>
  <link name="rear_right_collision_link">
    <collision>
      <origin xyz="0 0 0"/>
      <geometry>
        <!-- extend along the z axis -->
        <box size="0.045 0.045 1.0"/>
      </geometry>
    </collision>
    <!-- visualization not desired -->
    <!-- <visual>
            <origin xyz="0 0 0"/>
            <geometry>
              <box size="${profile_diameter} ${profile_diameter} ${vertical_profile_length}"/>
            </geometry>
            <material name="blue"/>
          </visual> -->
  </link>
  <link name="front_collision_link">
    <collision>
      <origin xyz="0 0 0"/>
      <geometry>
        <!-- extend along the y axis -->
        <box size="0.045 1.91 0.045"/>
      </geometry>
    </collision>
    <!-- visualization not desired -->
    <!-- <visual>
            <origin xyz="0 0 0"/>
            <geometry>
              <box size="${profile_diameter} ${horiz_profile_length} ${profile_diameter}"/>
            </geometry>
            <material name="blue"/>
          </visual> -->
  </link>
  <link name="rear_collision_link">
    <collision>
      <origin xyz="0 0 0"/>
      <geometry>
        <!-- extend along the y axis -->
        <box size="0.045 1.91 0.045"/>
      </geometry>
    </collision>
    <!-- visualization not desired -->
    <!-- <visual>
            <origin xyz="0 0 0"/>
            <geometry>
              <box size="${profile_diameter} ${horiz_profile_length} ${profile_diameter}"/>
            </geometry>
            <material name="blue"/>
          </visual> -->
  </link>
  <link name="left_collision_link">
    <collision>
      <origin xyz="0 0 0"/>
      <geometry>
        <!-- extend along the x axis -->
        <box size="0.91 0.045 0.045"/>
      </geometry>
    </collision>
    <!-- visualization not desired -->
    <!-- <visual>
            <origin xyz="0 0 0"/>
            <geometry>
              <box size="${horiz_short_profile_length} ${profile_diameter} ${profile_diameter}"/>
            </geometry>
            <material name="blue"/>
          </visual> -->
  </link>
  <link name="right_collision_link">
    <collision>
      <origin xyz="0 0 0"/>
      <geometry>
        <!-- extend along the x axis -->
        <box size="0.91 0.045 0.045"/>
      </geometry>
    </collision>
    <!-- visualization not desired -->
    <!-- <visual>
            <origin xyz="0 0 0"/>
            <geometry>
              <box size="${horiz_short_profile_length} ${profile_diameter} ${profile_diameter}"/>
            </geometry>
            <material name="blue"/>
          </visual> -->
  </link>
  <!-- end conditional robot frame include -->
  <!-- NICOL's "chest" collision -->
  <link name="chest_collision_link">
    <!-- visualization not desired -->
    <!-- <visual>
        <origin xyz="0 0 0" rpy="0 0 0"/>
        <geometry>
          <box size="0.02 0.1 0.14"/>
        </geometry>
        <material name="blue"/>
      </visual> -->
    <collision>
      <origin rpy="0 0 0" xyz="0 0 0"/>
      <geometry>
        <box size="0.02 0.1 0.14"/>
      </geometry>
    </collision>
  </link>
  <!-- the head -->
  <link name="head_link">
    <visual>
      <origin rpy="0 0 0" xyz="0 0 0"/>
      <geometry>
        <mesh filename="/export/home/strahl/dev/gaikpy/resources/urdf/nicol/meshes/head/NICOL_13.stl" scale="0.001 0.001 0.001"/>
      </geometry>
      <material name="white"/>
    </visual>
    <collision>
      <origin rpy="0 0 0" xyz="0.017 0 0.115"/>
      <!-- simplify geometry to a cylinder -->
      <geometry>
        <!-- <mesh filename="${head_stl_path}NICOL_13.stl" scale="${stl_scale}"/> -->
        <cylinder length="0.24" radius="0.128"/>
      </geometry>
    </collision>
    <inertial>
      <origin rpy="0.03669321 -0.04752892 -0.02711174" xyz="0.04821698 -0.00085035 0.10222200"/>
      <mass value="0.49307743"/>
      <inertia ixx="0.00367200" ixy="0.00001037" ixz="-0.00004273" iyy="0.00323317" iyz="-0.00001705" izz="0.00278485"/>
    </inertial>
  </link>
  <!-- occiput link -->
  <link name="occiput_link">
    <visual>
      <origin rpy="0 0 0" xyz="0 0 0"/>
      <geometry>
        <mesh filename="/export/home/strahl/dev/gaikpy/resources/urdf/nicol/meshes/head/occiput_1x3_centered.stl" scale="0.001 0.001 0.001"/>
      </geometry>
      <material name="black"/>
    </visual>
    <collision>
      <!-- collision covered by head -->
      <origin rpy="0 0 0" xyz="0 0 0.213"/>
      <geometry>
        <!-- <mesh filename="${head_stl_path}occiput_1x3_centered.stl" scale="${stl_scale}"/> -->
        <box size="0.001 0.001 0.001"/>
      </geometry>
    </collision>
    <inertial>
      <origin rpy="-0.01418 -0.17910 0.00166" xyz="-0.05588 -0.00017 0.10147"/>
      <mass value="0.26649"/>
      <inertia ixx="0.00216" ixy="0.0" ixz="-0.00011" iyy="0.00124" iyz="0.0" izz="0.00160"/>
    </inertial>
  </link>
  <!-- left eye camera -->
  <link name="left_eye_link">
    <visual>
      <origin rpy="0 0 0" xyz="0 0 0"/>
      <geometry>
        <mesh filename="/export/home/strahl/dev/gaikpy/resources/urdf/nicol/meshes/head/BF10M10526S132C_centered.stl" scale="0.001 0.001 0.001"/>
      </geometry>
      <material name="profile"/>
    </visual>
    <collision>
      <!-- collision covered by head -->
      <origin rpy="0 0 0" xyz="-0.115 0 0.145"/>
      <geometry>
        <!-- <mesh filename="${head_stl_path}BF10M10526S132C_centered.stl" scale="${stl_scale}"/> -->
        <box size="0.001 0.001 0.001"/>
      </geometry>
    </collision>
    <inertial>
      <origin rpy="0 0 0" xyz="0.00108802 0.0 0.0"/>
      <mass value="0.00800898"/>
      <inertia ixx="0.00000044" ixy="0.0" ixz="0.0" iyy="0.00000045" iyz="0.0" izz="0.00000045"/>
    </inertial>
  </link>
  <!-- right eye camera -->
  <link name="right_eye_link">
    <visual>
      <origin rpy="0 0 0" xyz="0 0 0"/>
      <geometry>
        <mesh filename="/export/home/strahl/dev/gaikpy/resources/urdf/nicol/meshes/head/BF10M10526S132C_centered.stl" scale="0.001 0.001 0.001"/>
      </geometry>
      <material name="profile"/>
    </visual>
    <collision>
      <!-- collision covered by head -->
      <origin rpy="0 0 0" xyz="-0.115 0 0.145"/>
      <geometry>
        <!-- <mesh filename="${head_stl_path}BF10M10526S132C_centered.stl" scale="${stl_scale}"/> -->
        <box size="0.001 0.001 0.001"/>
      </geometry>
    </collision>
    <inertial>
      <origin rpy="0 0 0" xyz="0.00108802 0.0 0.0"/>
      <mass value="0.00800898"/>
      <inertia ixx="0.00000044" ixy="0.0" ixz="0.0" iyy="0.00000045" iyz="0.0" izz="0.00000045"/>
    </inertial>
  </link>
  <!-- the head tilt mechanism -->
  <link name="tilt_link">
    <visual>
      <origin rpy="0 0 0" xyz="0 0 0"/>
      <geometry>
        <mesh filename="/export/home/strahl/dev/gaikpy/resources/urdf/nicol/meshes/head/tilt_asmbly.stl" scale="0.001 0.001 0.001"/>
      </geometry>
      <material name="grey"/>
    </visual>
    <collision>
      <!-- simplify geometry to a box -->
      <origin rpy="0 0 0" xyz="0 0 -0.005"/>
      <geometry>
        <!-- <mesh filename="${head_stl_path}tilt_asmbly.stl" scale="${stl_scale}"/> -->
        <box size="0.04 0.042 0.08"/>
      </geometry>
    </collision>
    <inertial>
      <origin rpy="-0.02892225 0.00099172 -0.00026723" xyz="-0.00010125 -0.00021463 0.02966824"/>
      <mass value="0.15019367"/>
      <inertia ixx="0.00009713" ixy="0" ixz="0.00000006" iyy="0.00008905" iyz="0.00000163" izz="0.00003278"/>
    </inertial>
  </link>
  <!-- the neck -->
  <link name="neck_link">
    <visual>
      <origin rpy="0 0 0" xyz="0 0 0"/>
      <geometry>
        <mesh filename="/export/home/strahl/dev/gaikpy/resources/urdf/nicol/meshes/head/cplt_neck_asmbly.stl" scale="0.001 0.001 0.001"/>
      </geometry>
      <material name="grey"/>
    </visual>
    <collision>
      <!-- simplify geometry to a cylinder -->
      <origin rpy="0 0.7853981633974483 0" xyz="0.09 0 0.07"/>
      <geometry>
        <!-- <mesh filename="${head_stl_path}cplt_neck_asmbly.stl" scale="${stl_scale}"/> -->
        <cylinder length="0.13" radius="0.038"/>
      </geometry>
    </collision>
    <inertial>
      <origin rpy="-0.00287454 0.61701874 -0.00141275" xyz="0.07075596 0.00003485 0.05658257"/>
      <mass value="0.56992762"/>
      <inertia ixx="0.00138149" ixy="0.00000062" ixz="-0.00124881" iyy="0.00307012" iyz="0.00000024" izz="0.00225589"/>
    </inertial>
  </link>
  <!-- Append head links -->
  <!-- the camera (simulated in Gazebo config) -->
  <link name="camera_link">
    <visual>
      <origin rpy="0 0 0" xyz="0 0 0"/>
      <geometry>
        <mesh filename="/export/home/strahl/dev/gaikpy/resources/urdf/nicol/meshes/camera/Intel_RealSense_Depth_Camera_D435_centered.stl" scale="0.001 0.001 0.001"/>
      </geometry>
      <material name="profile"/>
    </visual>
    <collision>
      <!-- simplify geometry to a box -->
      <origin rpy="0 0 0" xyz="0 0 0.0"/>
      <geometry>
        <!-- <mesh filename="${camera_stl_path}Intel_RealSense_Depth_Camera_D435_centered.stl" scale="${stl_scale}"/> -->
        <box size="0.001 0.001 0.001"/>
      </geometry>
    </collision>
    <inertial>
      <origin rpy="0.00119 -0.07569 -0.00766" xyz="-0.01327 0.00168 0.0"/>
      <mass value="0.05443"/>
      <inertia ixx="0.00004" ixy="0.0" ixz="0.0" iyy="0.00001" iyz="0.0" izz="0.00004"/>
    </inertial>
  </link>
  <!-- the camera holder -->
  <link name="camera_holder_link">
    <visual>
      <origin rpy="0 0 0" xyz="0 0 0"/>
      <geometry>
        <mesh filename="/export/home/strahl/dev/gaikpy/resources/urdf/nicol/meshes/robot_frame/camera_holder_centered.stl" scale="0.001 0.001 0.001"/>
      </geometry>
      <material name="silver"/>
    </visual>
    <collision>
      <!-- simplify geometry to a box -->
      <origin rpy="0 0 0" xyz="0 0 0"/>
      <geometry>
        <!-- <mesh filename="${stl_path}camera_holder_centered.stl" scale="${stl_scale}"/> -->
        <box size="0.001 0.001 0.001"/>
      </geometry>
    </collision>
    <inertial>
      <origin rpy="0 0.7824311 0" xyz="0.01 0 0.01"/>
      <mass value="0.360"/>
      <inertia ixx="7.521032e-03" ixy="0.0" ixz="-4.2999999999999995e-08" iyy="2.5991e-05" iyz="0.0" izz="7.521032e-03"/>
    </inertial>
  </link>
  <!-- Empty link for camera transform -->
  <link name="realsense_link"/>
  <!-- condition args -->
  <!-- <xacro:property name="body_side" value="$(arg body_side)"/> -->
  <gazebo>
    <plugin filename="libgazebo_ros_control.so" name="gazebo_ros_control">
      <robotNamespace>right/open_manipulator_p</robotNamespace>
      <robotSimType>gazebo_ros_control/DefaultRobotHWSim</robotSimType>
    </plugin>
  </gazebo>
  <gazebo reference="r_link1">
    <kp>1000000.0</kp>
    <kd>100.0</kd>
    <mu1>30.0</mu1>
    <mu2>30.0</mu2>
    <maxVel>1.0</maxVel>
    <minDepth>0.001</minDepth>
    <material>Gazebo/DarkGrey</material>
  </gazebo>
  <gazebo reference="r_link2">
    <kp>1000000.0</kp>
    <kd>100.0</kd>
    <mu1>30.0</mu1>
    <mu2>30.0</mu2>
    <maxVel>1.0</maxVel>
    <minDepth>0.001</minDepth>
    <material>Gazebo/DarkGrey</material>
  </gazebo>
  <gazebo reference="r_link3">
    <kp>1000000.0</kp>
    <kd>100.0</kd>
    <mu1>30.0</mu1>
    <mu2>30.0</mu2>
    <maxVel>1.0</maxVel>
    <minDepth>0.001</minDepth>
    <material>Gazebo/DarkGrey</material>
  </gazebo>
  <gazebo reference="r_link4">
    <kp>1000000.0</kp>
    <kd>100.0</kd>
    <mu1>30.0</mu1>
    <mu2>30.0</mu2>
    <maxVel>1.0</maxVel>
    <minDepth>0.001</minDepth>
    <material>Gazebo/DarkGrey</material>
  </gazebo>
  <gazebo reference="r_link5">
    <kp>1000000.0</kp>
    <kd>100.0</kd>
    <mu1>30.0</mu1>
    <mu2>30.0</mu2>
    <maxVel>1.0</maxVel>
    <minDepth>0.001</minDepth>
    <material>Gazebo/DarkGrey</material>
  </gazebo>
  <gazebo reference="r_link6">
    <kp>1000000.0</kp>
    <kd>100.0</kd>
    <mu1>30.0</mu1>
    <mu2>30.0</mu2>
    <maxVel>1.0</maxVel>
    <minDepth>0.001</minDepth>
    <material>Gazebo/DarkGrey</material>
  </gazebo>
  <gazebo reference="r_forearm">
    <!-- <kp>1000000.0</kp>
      <kd>100.0</kd>
      <mu1>30.0</mu1>
      <mu2>30.0</mu2>
      <maxVel>1.0</maxVel>
      <minDepth>0.001</minDepth> -->
    <!-- <visual>
        <material>
          <ambient>0.74902 0.74902 0.74902 1.0</ambient>
          <diffuse>0.74902 0.74902 0.74902 1.0</diffuse>
          <specular>0.74902 0.74902 0.74902 1.0</specular>
        </material>
      </visual> -->
    <mu1>0.2</mu1>
    <mu2>0.2</mu2>
    <material>Gazebo/Grey</material>
  </gazebo>
  <gazebo reference="r_palm_axis">
    <!-- <kp>1000000.0</kp>
      <kd>100.0</kd>
      <mu1>30.0</mu1>
      <mu2>30.0</mu2>
      <maxVel>1.0</maxVel>
      <minDepth>0.001</minDepth> -->
    <!-- <visual>
        <material>
          <ambient>0.74902 0.74902 0.74902 1.0</ambient>
          <diffuse>0.74902 0.74902 0.74902 1.0</diffuse>
          <specular>0.74902 0.74902 0.74902 1.0</specular>
        </material>
      </visual> -->
    <mu1>0.2</mu1>
    <mu2>0.2</mu2>
    <material>Gazebo/Grey</material>
  </gazebo>
  <gazebo reference="r_palm">
    <!-- <kp>1000000.0</kp>
      <kd>100.0</kd>
      <mu1>30.0</mu1>
      <mu2>30.0</mu2>
      <maxVel>1.0</maxVel>
      <minDepth>0.001</minDepth> -->
    <!-- <visual>
        <material>
          <ambient>0.74902 0.74902 0.74902 1.0</ambient>
          <diffuse>0.74902 0.74902 0.74902 1.0</diffuse>
          <specular>0.74902 0.74902 0.74902 1.0</specular>
        </material>
      </visual> -->
    <mu1>0.2</mu1>
    <mu2>0.2</mu2>
    <material>Gazebo/Grey</material>
  </gazebo>
  <gazebo reference="r_Rproximal">
    <!-- <kp>1000000.0</kp>
      <kd>100.0</kd>
      <mu1>30.0</mu1>
      <mu2>30.0</mu2>
      <maxVel>1.0</maxVel>
      <minDepth>0.001</minDepth> -->
    <!-- <visual>
        <material>
          <ambient>0.74902 0.74902 0.74902 1.0</ambient>
          <diffuse>0.74902 0.74902 0.74902 1.0</diffuse>
          <specular>0.74902 0.74902 0.74902 1.0</specular>
        </material>
      </visual> -->
    <mu1>0.2</mu1>
    <mu2>0.2</mu2>
    <material>Gazebo/Grey</material>
  </gazebo>
  <gazebo reference="r_Rmiddle">
    <!-- <kp>1000000.0</kp>
      <kd>100.0</kd>
      <mu1>30.0</mu1>
      <mu2>30.0</mu2>
      <maxVel>1.0</maxVel>
      <minDepth>0.001</minDepth> -->
    <!-- <visual>
        <material>
          <ambient>0.74902 0.74902 0.74902 1.0</ambient>
          <diffuse>0.74902 0.74902 0.74902 1.0</diffuse>
          <specular>0.74902 0.74902 0.74902 1.0</specular>
        </material>
      </visual> -->
    <mu1>0.2</mu1>
    <mu2>0.2</mu2>
    <material>Gazebo/Grey</material>
  </gazebo>
  <gazebo reference="r_Rtip">
    <!-- <kp>1000000.0</kp>
      <kd>100.0</kd>
      <mu1>30.0</mu1>
      <mu2>30.0</mu2>
      <maxVel>1.0</maxVel>
      <minDepth>0.001</minDepth> -->
    <!-- <visual>
        <material>
          <ambient>0.74902 0.74902 0.74902 1.0</ambient>
          <diffuse>0.74902 0.74902 0.74902 1.0</diffuse>
          <specular>0.74902 0.74902 0.74902 1.0</specular>
        </material>
      </visual> -->
    <mu1>0.2</mu1>
    <mu2>0.2</mu2>
    <material>Gazebo/Grey</material>
  </gazebo>
  <gazebo reference="r_Mproximal">
    <!-- <kp>1000000.0</kp>
      <kd>100.0</kd>
      <mu1>30.0</mu1>
      <mu2>30.0</mu2>
      <maxVel>1.0</maxVel>
      <minDepth>0.001</minDepth> -->
    <!-- <visual>
        <material>
          <ambient>0.74902 0.74902 0.74902 1.0</ambient>
          <diffuse>0.74902 0.74902 0.74902 1.0</diffuse>
          <specular>0.74902 0.74902 0.74902 1.0</specular>
        </material>
      </visual> -->
    <mu1>0.2</mu1>
    <mu2>0.2</mu2>
    <material>Gazebo/Grey</material>
  </gazebo>
  <gazebo reference="r_Mmiddle">
    <!-- <kp>1000000.0</kp>
      <kd>100.0</kd>
      <mu1>30.0</mu1>
      <mu2>30.0</mu2>
      <maxVel>1.0</maxVel>
      <minDepth>0.001</minDepth> -->
    <!-- <visual>
        <material>
          <ambient>0.74902 0.74902 0.74902 1.0</ambient>
          <diffuse>0.74902 0.74902 0.74902 1.0</diffuse>
          <specular>0.74902 0.74902 0.74902 1.0</specular>
        </material>
      </visual> -->
    <mu1>0.2</mu1>
    <mu2>0.2</mu2>
    <material>Gazebo/Grey</material>
  </gazebo>
  <gazebo reference="r_Mtip">
    <!-- <kp>1000000.0</kp>
      <kd>100.0</kd>
      <mu1>30.0</mu1>
      <mu2>30.0</mu2>
      <maxVel>1.0</maxVel>
      <minDepth>0.001</minDepth> -->
    <!-- <visual>
        <material>
          <ambient>0.74902 0.74902 0.74902 1.0</ambient>
          <diffuse>0.74902 0.74902 0.74902 1.0</diffuse>
          <specular>0.74902 0.74902 0.74902 1.0</specular>
        </material>
      </visual> -->
    <mu1>0.2</mu1>
    <mu2>0.2</mu2>
    <material>Gazebo/Grey</material>
  </gazebo>
  <gazebo reference="r_Pproximal">
    <!-- <kp>1000000.0</kp>
      <kd>100.0</kd>
      <mu1>30.0</mu1>
      <mu2>30.0</mu2>
      <maxVel>1.0</maxVel>
      <minDepth>0.001</minDepth> -->
    <!-- <visual>
        <material>
          <ambient>0.74902 0.74902 0.74902 1.0</ambient>
          <diffuse>0.74902 0.74902 0.74902 1.0</diffuse>
          <specular>0.74902 0.74902 0.74902 1.0</specular>
        </material>
      </visual> -->
    <mu1>0.2</mu1>
    <mu2>0.2</mu2>
    <material>Gazebo/Grey</material>
  </gazebo>
  <gazebo reference="r_Pmiddle">
    <!-- <kp>1000000.0</kp>
      <kd>100.0</kd>
      <mu1>30.0</mu1>
      <mu2>30.0</mu2>
      <maxVel>1.0</maxVel>
      <minDepth>0.001</minDepth> -->
    <!-- <visual>
        <material>
          <ambient>0.74902 0.74902 0.74902 1.0</ambient>
          <diffuse>0.74902 0.74902 0.74902 1.0</diffuse>
          <specular>0.74902 0.74902 0.74902 1.0</specular>
        </material>
      </visual> -->
    <mu1>0.2</mu1>
    <mu2>0.2</mu2>
    <material>Gazebo/Grey</material>
  </gazebo>
  <gazebo reference="r_Ptip">
    <!-- <kp>1000000.0</kp>
      <kd>100.0</kd>
      <mu1>30.0</mu1>
      <mu2>30.0</mu2>
      <maxVel>1.0</maxVel>
      <minDepth>0.001</minDepth> -->
    <!-- <visual>
        <material>
          <ambient>0.74902 0.74902 0.74902 1.0</ambient>
          <diffuse>0.74902 0.74902 0.74902 1.0</diffuse>
          <specular>0.74902 0.74902 0.74902 1.0</specular>
        </material>
      </visual> -->
    <mu1>0.2</mu1>
    <mu2>0.2</mu2>
    <material>Gazebo/Grey</material>
  </gazebo>
  <gazebo reference="r_thumb_base">
    <!-- <kp>1000000.0</kp>
      <kd>100.0</kd>
      <mu1>30.0</mu1>
      <mu2>30.0</mu2>
      <maxVel>1.0</maxVel>
      <minDepth>0.001</minDepth> -->
    <!-- <visual>
        <material>
          <ambient>0.74902 0.74902 0.74902 1.0</ambient>
          <diffuse>0.74902 0.74902 0.74902 1.0</diffuse>
          <specular>0.74902 0.74902 0.74902 1.0</specular>
        </material>
      </visual> -->
    <mu1>0.2</mu1>
    <mu2>0.2</mu2>
    <material>Gazebo/Grey</material>
  </gazebo>
  <gazebo reference="r_Tproximal">
    <!-- <kp>1000000.0</kp>
      <kd>100.0</kd>
      <mu1>30.0</mu1>
      <mu2>30.0</mu2>
      <maxVel>1.0</maxVel>
      <minDepth>0.001</minDepth> -->
    <!-- <visual>
        <material>
          <ambient>0.74902 0.74902 0.74902 1.0</ambient>
          <diffuse>0.74902 0.74902 0.74902 1.0</diffuse>
          <specular>0.74902 0.74902 0.74902 1.0</specular>
        </material>
      </visual> -->
    <mu1>0.2</mu1>
    <mu2>0.2</mu2>
    <material>Gazebo/Grey</material>
  </gazebo>
  <gazebo reference="r_Tmiddle">
    <!-- <kp>1000000.0</kp>
      <kd>100.0</kd>
      <mu1>30.0</mu1>
      <mu2>30.0</mu2>
      <maxVel>1.0</maxVel>
      <minDepth>0.001</minDepth> -->
    <!-- <visual>
        <material>
          <ambient>0.74902 0.74902 0.74902 1.0</ambient>
          <diffuse>0.74902 0.74902 0.74902 1.0</diffuse>
          <specular>0.74902 0.74902 0.74902 1.0</specular>
        </material>
      </visual> -->
    <mu1>0.2</mu1>
    <mu2>0.2</mu2>
    <material>Gazebo/Grey</material>
  </gazebo>
  <gazebo reference="r_Ttip">
    <!-- <kp>1000000.0</kp>
      <kd>100.0</kd>
      <mu1>30.0</mu1>
      <mu2>30.0</mu2>
      <maxVel>1.0</maxVel>
      <minDepth>0.001</minDepth> -->
    <!-- <visual>
        <material>
          <ambient>0.74902 0.74902 0.74902 1.0</ambient>
          <diffuse>0.74902 0.74902 0.74902 1.0</diffuse>
          <specular>0.74902 0.74902 0.74902 1.0</specular>
        </material>
      </visual> -->
    <mu1>0.2</mu1>
    <mu2>0.2</mu2>
    <material>Gazebo/Grey</material>
  </gazebo>
  <gazebo reference="r_Iproximal">
    <!-- <kp>1000000.0</kp>
      <kd>100.0</kd>
      <mu1>30.0</mu1>
      <mu2>30.0</mu2>
      <maxVel>1.0</maxVel>
      <minDepth>0.001</minDepth> -->
    <!-- <visual>
        <material>
          <ambient>0.74902 0.74902 0.74902 1.0</ambient>
          <diffuse>0.74902 0.74902 0.74902 1.0</diffuse>
          <specular>0.74902 0.74902 0.74902 1.0</specular>
        </material>
      </visual> -->
    <mu1>0.2</mu1>
    <mu2>0.2</mu2>
    <material>Gazebo/Grey</material>
  </gazebo>
  <gazebo reference="r_Imiddle">
    <!-- <kp>1000000.0</kp>
      <kd>100.0</kd>
      <mu1>30.0</mu1>
      <mu2>30.0</mu2>
      <maxVel>1.0</maxVel>
      <minDepth>0.001</minDepth> -->
    <!-- <visual>
        <material>
          <ambient>0.74902 0.74902 0.74902 1.0</ambient>
          <diffuse>0.74902 0.74902 0.74902 1.0</diffuse>
          <specular>0.74902 0.74902 0.74902 1.0</specular>
        </material>
      </visual> -->
    <mu1>0.2</mu1>
    <mu2>0.2</mu2>
    <material>Gazebo/Grey</material>
  </gazebo>
  <gazebo reference="r_Itip">
    <!-- <kp>1000000.0</kp>
      <kd>100.0</kd>
      <mu1>30.0</mu1>
      <mu2>30.0</mu2>
      <maxVel>1.0</maxVel>
      <minDepth>0.001</minDepth> -->
    <!-- <visual>
        <material>
          <ambient>0.74902 0.74902 0.74902 1.0</ambient>
          <diffuse>0.74902 0.74902 0.74902 1.0</diffuse>
          <specular>0.74902 0.74902 0.74902 1.0</specular>
        </material>
      </visual> -->
    <mu1>0.2</mu1>
    <mu2>0.2</mu2>
    <material>Gazebo/Grey</material>
  </gazebo>
  <!-- <gazebo>
    <pose>0.0 0.0 0.0 0.0 0.0 0.0</pose>
  </gazebo> -->
  <link name="r_forearm">
    <inertial>
      <origin rpy="0.02118572 0.0001173 0.00029319" xyz="-0.0000047 0.00267674 0.0805699"/>
      <mass value="0.77750886"/>
      <inertia ixx="0.00152273" ixy="0.00000005" ixz="0.00000010" iyy="0.00167456" iyz="-0.00002091" izz="0.00068825"/>
    </inertial>
    <visual>
      <origin rpy="0 0 0" xyz="0 0 0"/>
      <geometry>
        <mesh filename="/export/home/strahl/dev/gaikpy/resources/urdf/nicol/meshes/RH8D/forearm_refac.stl" scale="0.001 0.001 0.001"/>
      </geometry>
      <material name="rh8d_color"/>
    </visual>
    <collision>
      <origin rpy="0 0 0" xyz="0 0 0"/>
      <geometry>
        <mesh filename="/export/home/strahl/dev/gaikpy/resources/urdf/nicol/meshes/RH8D/forearm_refac.stl" scale="0.001 0.001 0.001"/>
      </geometry>
    </collision>
  </link>
  <joint name="r_joint7" type="revolute">
    <origin rpy="1.5707963267948966 0 0" xyz="0 0.005 0.18399997"/>
    <parent link="r_forearm"/>
    <child link="r_palm_axis"/>
    <axis xyz="0 0 1"/>
    <limit effort="0.5" lower="-0.785398163397" upper="0.785398163397" velocity="1.0"/>
    <dynamics damping="0.001"/>
  </joint>
  <transmission name="tranr_7">
    <type>transmission_interface/SimpleTransmission</type>
    <joint name="r_joint7">
      <hardwareInterface>hardware_interface/PositionJointInterface</hardwareInterface>
    </joint>
    <actuator name="motorr_7">
      <hardwareInterface>hardware_interface/PositionJointInterface</hardwareInterface>
      <mechanicalReduction>1</mechanicalReduction>
    </actuator>
  </transmission>
  <link name="r_palm_axis">
    <inertial>
      <origin rpy="0.00003493 0.00015844 0.00001195" xyz="0.00000165 -0.00903164 0.00000046"/>
      <mass value="0.04827394"/>
      <inertia ixx="0.00000933" ixy="0.0" ixz="0.0" iyy="0.00001216" iyz="0.0" izz="0.00001695"/>
    </inertial>
    <visual>
      <origin rpy="0 0 0" xyz="0 0 0"/>
      <geometry>
        <mesh filename="/export/home/strahl/dev/gaikpy/resources/urdf/nicol/meshes/RH8D/palm_axis_refac.stl" scale="0.001 0.001 0.001"/>
      </geometry>
      <material name="rh8d_color"/>
    </visual>
    <collision>
      <origin rpy="0 0 0" xyz="0 0 0"/>
      <geometry>
        <mesh filename="/export/home/strahl/dev/gaikpy/resources/urdf/nicol/meshes/RH8D/palm_axis_refac.stl" scale="0.001 0.001 0.001"/>
      </geometry>
    </collision>
  </link>
  <joint name="r_joint8" type="revolute">
    <origin rpy="0 1.5707963267948966 0" xyz="0 0 0"/>
    <parent link="r_palm_axis"/>
    <child link="r_palm"/>
    <axis xyz="0 0 1"/>
    <limit effort="0.5" lower="-0.785398163397" upper="0.785398163397" velocity="1.0"/>
    <dynamics damping="0.001"/>
  </joint>
  <transmission name="tranr_8">
    <type>transmission_interface/SimpleTransmission</type>
    <joint name="r_joint8">
      <hardwareInterface>hardware_interface/PositionJointInterface</hardwareInterface>
    </joint>
    <actuator name="motorr_8">
      <hardwareInterface>hardware_interface/PositionJointInterface</hardwareInterface>
      <mechanicalReduction>1</mechanicalReduction>
    </actuator>
  </transmission>
  <link name="r_palm">
    <inertial>
      <origin rpy="0.62411571 -0.01906561 0.07874904" xyz="-0.00707205 0.03032731 0.02905062"/>
      <mass value="0.0886716"/>
      <inertia ixx="0.00010922" ixy="-0.00000616" ixz="0.00000410" iyy="0.00004316" iyz="0.00003750" izz="0.00006793"/>
    </inertial>
    <visual>
      <origin rpy="0 0 0" xyz="0 0 0"/>
      <geometry>
        <mesh filename="/export/home/strahl/dev/gaikpy/resources/urdf/nicol/meshes/RH8D/right_palm_refac.stl" scale="0.001 0.001 0.001"/>
      </geometry>
      <material name="rh8d_color"/>
    </visual>
    <collision>
      <origin rpy="0 0 0" xyz="0 0 0"/>
      <geometry>
        <mesh filename="/export/home/strahl/dev/gaikpy/resources/urdf/nicol/meshes/RH8D/right_palm_refac.stl" scale="0.001 0.001 0.001"/>
      </geometry>
    </collision>
  </link>
  <!-- tool0 for detailed end effector positioning on eef link (palm) -->
  <joint name="r_palm_to_r_tool0" type="fixed">
    <parent link="r_Rproximal"/>
    <child link="r_tool0"/>
  </joint>
  <link name="r_tool0"/>
  <joint name="r_jointT0" type="revolute">
    <origin rpy="-2.61076346 -0.65671694 0.44279479" xyz="-0.00852244 0.01530788 0.03843229"/>
    <parent link="r_palm"/>
    <child link="r_thumb_base"/>
    <axis xyz="0 0 1"/>
    <limit effort="0.5" lower="0.0" upper="1.57079632679" velocity="1.0"/>
    <dynamics damping="0.0001"/>
  </joint>
  <transmission name="tranr_T0">
    <type>transmission_interface/SimpleTransmission</type>
    <joint name="r_jointT0">
      <hardwareInterface>hardware_interface/PositionJointInterface</hardwareInterface>
    </joint>
    <actuator name="motorr_T0">
      <hardwareInterface>hardware_interface/PositionJointInterface</hardwareInterface>
      <mechanicalReduction>1</mechanicalReduction>
    </actuator>
  </transmission>
  <link name="r_thumb_base">
    <inertial>
      <origin rpy="-0.00000341 -0.00000343 0.03167803" xyz="-0.00000008 0.00000194 0.02800943"/>
      <mass value="0.00705621"/>
      <inertia ixx="0.00000058" ixy="0" ixz="0" iyy="0.00000058" iyz="0" izz="0.00000005"/>
    </inertial>
    <visual>
      <origin rpy="0 0 0" xyz="0 0 0"/>
      <geometry>
        <mesh filename="/export/home/strahl/dev/gaikpy/resources/urdf/nicol/meshes/RH8D/thumb_base_refac.stl" scale="0.001 0.001 0.001"/>
      </geometry>
      <material name="rh8d_color"/>
    </visual>
    <collision>
      <origin rpy="0 0 0" xyz="0 0 0"/>
      <geometry>
        <mesh filename="/export/home/strahl/dev/gaikpy/resources/urdf/nicol/meshes/RH8D/thumb_base_refac.stl" scale="0.001 0.001 0.001"/>
      </geometry>
    </collision>
  </link>
  <joint name="r_jointT1" type="revolute">
    <origin rpy="1.57079633 -1.01753528 -1.57079633" xyz="0 -0.0111644427 0.005490292"/>
    <parent link="r_thumb_base"/>
    <child link="r_Tproximal"/>
    <axis xyz="0 0 1"/>
    <limit effort="0.5" lower="0.0" upper="1.57079632679" velocity="1.0"/>
    <dynamics damping="0.0001"/>
  </joint>
  <transmission name="tranr_T1">
    <type>transmission_interface/SimpleTransmission</type>
    <joint name="r_jointT1">
      <hardwareInterface>hardware_interface/PositionJointInterface</hardwareInterface>
    </joint>
    <actuator name="motorr_T1">
      <hardwareInterface>hardware_interface/PositionJointInterface</hardwareInterface>
      <mechanicalReduction>1</mechanicalReduction>
    </actuator>
  </transmission>
  <link name="r_Tproximal">
    <inertial>
      <origin rpy="0.00064474 0.00155280 0.04587687" xyz="-0.00009888 -0.00895693 0.00000242"/>
      <mass value=" 0.00382508"/>
      <inertia ixx="0.00000026" ixy="-0.00000001" ixz="0" iyy="0.00000013" iyz="0" izz="0.00000023"/>
    </inertial>
    <visual>
      <origin rpy="0 0 0" xyz="0 0 0"/>
      <geometry>
        <mesh filename="/export/home/strahl/dev/gaikpy/resources/urdf/nicol/meshes/RH8D/thumb_phalanx_refac.stl" scale="0.001 0.001 0.001"/>
      </geometry>
      <material name="rh8d_color"/>
    </visual>
    <collision>
      <origin rpy="0 0 0" xyz="0 0 0"/>
      <geometry>
        <mesh filename="/export/home/strahl/dev/gaikpy/resources/urdf/nicol/meshes/RH8D/thumb_phalanx_refac.stl" scale="0.001 0.001 0.001"/>
      </geometry>
    </collision>
  </link>
  <joint name="r_jointT2" type="revolute">
    <origin rpy="0 0 0" xyz="0 -0.0215859928 0"/>
    <parent link="r_Tproximal"/>
    <child link="r_Tmiddle"/>
    <axis xyz="0 0 1"/>
    <limit effort="0.5" lower="0.0" upper="1.57079632679" velocity="1.0"/>
    <dynamics damping="0.0001"/>
  </joint>
  <transmission name="tranr_T2">
    <type>transmission_interface/SimpleTransmission</type>
    <joint name="r_jointT2">
      <hardwareInterface>hardware_interface/PositionJointInterface</hardwareInterface>
    </joint>
    <actuator name="motorr_T2">
      <hardwareInterface>hardware_interface/PositionJointInterface</hardwareInterface>
      <mechanicalReduction>1</mechanicalReduction>
    </actuator>
  </transmission>
  <link name="r_Tmiddle">
    <inertial>
      <origin rpy="0.00064474 0.00155280 0.04587687" xyz="-0.00009888 -0.00895693 0.00000242"/>
      <mass value=" 0.00382508"/>
      <inertia ixx="0.00000026" ixy="-0.00000001" ixz="0" iyy="0.00000013" iyz="0" izz="0.00000023"/>
    </inertial>
    <visual>
      <origin rpy="0 0 0" xyz="0 0 0"/>
      <geometry>
        <mesh filename="/export/home/strahl/dev/gaikpy/resources/urdf/nicol/meshes/RH8D/thumb_phalanx_refac.stl" scale="0.001 0.001 0.001"/>
      </geometry>
      <material name="rh8d_color"/>
    </visual>
    <collision>
      <origin rpy="0 0 0" xyz="0 0 0"/>
      <geometry>
        <mesh filename="/export/home/strahl/dev/gaikpy/resources/urdf/nicol/meshes/RH8D/thumb_phalanx_refac.stl" scale="0.001 0.001 0.001"/>
      </geometry>
    </collision>
  </link>
  <joint name="r_jointT3" type="revolute">
    <origin rpy="0 0 0.078" xyz="0 -0.0215859928 0"/>
    <parent link="r_Tmiddle"/>
    <child link="r_Ttip"/>
    <axis xyz="0 0 1"/>
    <limit effort="0.5" lower="0.0" upper="1.57079632679" velocity="1.0"/>
    <dynamics damping="0.0001"/>
  </joint>
  <transmission name="tranr_T3">
    <type>transmission_interface/SimpleTransmission</type>
    <joint name="r_jointT3">
      <hardwareInterface>hardware_interface/PositionJointInterface</hardwareInterface>
    </joint>
    <actuator name="motorr_T3">
      <hardwareInterface>hardware_interface/PositionJointInterface</hardwareInterface>
      <mechanicalReduction>1</mechanicalReduction>
    </actuator>
  </transmission>
  <link name="r_Ttip">
    <inertial>
      <origin rpy="0.00105402 -0.00291363 -0.08777144" xyz="0.00064228 -0.01044102 0.00000295"/>
      <mass value="0.00475224"/>
      <inertia ixx="0.00000031" ixy="0.00000001" ixz="0" iyy="0.00000014" iyz="0" izz="0.00000029"/>
    </inertial>
    <visual>
      <origin rpy="0 0 0" xyz="0 0 0"/>
      <geometry>
        <mesh filename="/export/home/strahl/dev/gaikpy/resources/urdf/nicol/meshes/RH8D/tip_refac.stl" scale="0.001 0.001 0.001"/>
      </geometry>
      <material name="rh8d_color"/>
    </visual>
    <collision>
      <origin rpy="0 0 0" xyz="0 0 0"/>
      <geometry>
        <mesh filename="/export/home/strahl/dev/gaikpy/resources/urdf/nicol/meshes/RH8D/tip_refac.stl" scale="0.001 0.001 0.001"/>
      </geometry>
    </collision>
  </link>
  <joint name="r_jointI1" type="revolute">
    <origin rpy="-0.07160374  0.18146378 -2.87864878" xyz="-0.0043044918 0.0812907302 0.0367863551"/>
    <parent link="r_palm"/>
    <child link="r_Iproximal"/>
    <axis xyz="0 0 1"/>
    <limit effort="0.5" lower="0.0" upper="1.4835298642" velocity="1.0"/>
    <dynamics damping="0.0001"/>
  </joint>
  <transmission name="tranr_I1">
    <type>transmission_interface/SimpleTransmission</type>
    <joint name="r_jointI1">
      <hardwareInterface>hardware_interface/PositionJointInterface</hardwareInterface>
    </joint>
    <actuator name="motorr_I1">
      <hardwareInterface>hardware_interface/PositionJointInterface</hardwareInterface>
      <mechanicalReduction>1</mechanicalReduction>
    </actuator>
  </transmission>
  <link name="r_Iproximal">
    <inertial>
      <origin rpy="0.00028099 0.00058278 0.03232242" xyz="-0.00009694 -0.01116046 0.00000050"/>
      <mass value="0.00475397"/>
      <inertia ixx="0.00000040" ixy="-0.00000001" ixz="0" iyy="0.00000016" iyz="0" izz="0.00000036"/>
    </inertial>
    <visual>
      <origin rpy="0 0 0" xyz="0 0 0"/>
      <geometry>
        <mesh filename="/export/home/strahl/dev/gaikpy/resources/urdf/nicol/meshes/RH8D/phalanx_refac.stl" scale="0.001 0.001 0.001"/>
      </geometry>
      <material name="rh8d_color"/>
    </visual>
    <collision>
      <origin rpy="0 0 0" xyz="0 0 0"/>
      <geometry>
        <mesh filename="/export/home/strahl/dev/gaikpy/resources/urdf/nicol/meshes/RH8D/phalanx_refac.stl" scale="0.001 0.001 0.001"/>
      </geometry>
    </collision>
  </link>
  <joint name="r_jointI2" type="revolute">
    <origin rpy="0 0 0" xyz="0 -0.0258749732 0"/>
    <parent link="r_Iproximal"/>
    <child link="r_Imiddle"/>
    <axis xyz="0 0 1"/>
    <limit effort="0.5" lower="0.0" upper="1.4835298642" velocity="1.0"/>
    <dynamics damping="0.0001"/>
  </joint>
  <transmission name="tranr_I2">
    <type>transmission_interface/SimpleTransmission</type>
    <joint name="r_jointI2">
      <hardwareInterface>hardware_interface/PositionJointInterface</hardwareInterface>
    </joint>
    <actuator name="motorr_I2">
      <hardwareInterface>hardware_interface/PositionJointInterface</hardwareInterface>
      <mechanicalReduction>1</mechanicalReduction>
    </actuator>
  </transmission>
  <link name="r_Imiddle">
    <inertial>
      <origin rpy="0.00028099 0.00058278 0.03232242" xyz="-0.00009694 -0.01116046 0.00000050"/>
      <mass value="0.00475397"/>
      <inertia ixx="0.00000040" ixy="-0.00000001" ixz="0" iyy="0.00000016" iyz="0" izz="0.00000036"/>
    </inertial>
    <visual>
      <origin rpy="0 0 0" xyz="0 0 0"/>
      <geometry>
        <mesh filename="/export/home/strahl/dev/gaikpy/resources/urdf/nicol/meshes/RH8D/phalanx_refac.stl" scale="0.001 0.001 0.001"/>
      </geometry>
      <material name="rh8d_color"/>
    </visual>
    <collision>
      <origin rpy="0 0 0" xyz="0 0 0"/>
      <geometry>
        <mesh filename="/export/home/strahl/dev/gaikpy/resources/urdf/nicol/meshes/RH8D/phalanx_refac.stl" scale="0.001 0.001 0.001"/>
      </geometry>
    </collision>
  </link>
  <joint name="r_jointI3" type="revolute">
    <origin rpy="0 0 0.078" xyz="0 -0.0258749732 0"/>
    <parent link="r_Imiddle"/>
    <child link="r_Itip"/>
    <axis xyz="0 0 1"/>
    <limit effort="0.5" lower="0.0" upper="1.4835298642" velocity="1.0"/>
    <dynamics damping="0.0001"/>
  </joint>
  <transmission name="tranr_I3">
    <type>transmission_interface/SimpleTransmission</type>
    <joint name="r_jointI3">
      <hardwareInterface>hardware_interface/PositionJointInterface</hardwareInterface>
    </joint>
    <actuator name="motorr_I3">
      <hardwareInterface>hardware_interface/PositionJointInterface</hardwareInterface>
      <mechanicalReduction>1</mechanicalReduction>
    </actuator>
  </transmission>
  <link name="r_Itip">
    <inertial>
      <origin rpy="0.00105402 -0.00291363 -0.08777144" xyz="0.00064228 -0.01044102 0.00000295"/>
      <mass value="0.00475224"/>
      <inertia ixx="0.00000031" ixy="0.00000001" ixz="0" iyy="0.00000014" iyz="0" izz="0.00000029"/>
    </inertial>
    <visual>
      <origin rpy="0 0 0" xyz="0 0 0"/>
      <geometry>
        <mesh filename="/export/home/strahl/dev/gaikpy/resources/urdf/nicol/meshes/RH8D/tip_refac.stl" scale="0.001 0.001 0.001"/>
      </geometry>
      <material name="rh8d_color"/>
    </visual>
    <collision>
      <origin rpy="0 0 0" xyz="0 0 0"/>
      <geometry>
        <mesh filename="/export/home/strahl/dev/gaikpy/resources/urdf/nicol/meshes/RH8D/tip_refac.stl" scale="0.001 0.001 0.001"/>
      </geometry>
    </collision>
  </link>
  <joint name="r_jointM1" type="revolute">
    <origin rpy="0.00745321 0.08694845 -2.88142599" xyz="-0.0012008743 0.0828960623 0.0118294206"/>
    <parent link="r_palm"/>
    <child link="r_Mproximal"/>
    <axis xyz="0 0 1"/>
    <limit effort="0.5" lower="0.0" upper="1.4835298642" velocity="1.0"/>
    <dynamics damping="0.0001"/>
  </joint>
  <transmission name="tranr_M1">
    <type>transmission_interface/SimpleTransmission</type>
    <joint name="r_jointM1">
      <hardwareInterface>hardware_interface/PositionJointInterface</hardwareInterface>
    </joint>
    <actuator name="motorr_M1">
      <hardwareInterface>hardware_interface/PositionJointInterface</hardwareInterface>
      <mechanicalReduction>1</mechanicalReduction>
    </actuator>
  </transmission>
  <link name="r_Mproximal">
    <inertial>
      <origin rpy="0.00028099 0.00058278 0.03232242" xyz="-0.00009694 -0.01116046 0.00000050"/>
      <mass value="0.00475397"/>
      <inertia ixx="0.00000040" ixy="-0.00000001" ixz="0" iyy="0.00000016" iyz="0" izz="0.00000036"/>
    </inertial>
    <visual>
      <origin rpy="0 0 0" xyz="0 0 0"/>
      <geometry>
        <mesh filename="/export/home/strahl/dev/gaikpy/resources/urdf/nicol/meshes/RH8D/phalanx_refac.stl" scale="0.001 0.001 0.001"/>
      </geometry>
      <material name="rh8d_color"/>
    </visual>
    <collision>
      <origin rpy="0 0 0" xyz="0 0 0"/>
      <geometry>
        <mesh filename="/export/home/strahl/dev/gaikpy/resources/urdf/nicol/meshes/RH8D/phalanx_refac.stl" scale="0.001 0.001 0.001"/>
      </geometry>
    </collision>
  </link>
  <joint name="r_jointM2" type="revolute">
    <origin rpy="0 0 0" xyz="0 -0.0258749732 0"/>
    <parent link="r_Mproximal"/>
    <child link="r_Mmiddle"/>
    <axis xyz="0 0 1"/>
    <limit effort="0.5" lower="0.0" upper="1.4835298642" velocity="1.0"/>
    <dynamics damping="0.0001"/>
  </joint>
  <transmission name="tranr_M2">
    <type>transmission_interface/SimpleTransmission</type>
    <joint name="r_jointM2">
      <hardwareInterface>hardware_interface/PositionJointInterface</hardwareInterface>
    </joint>
    <actuator name="motorr_M2">
      <hardwareInterface>hardware_interface/PositionJointInterface</hardwareInterface>
      <mechanicalReduction>1</mechanicalReduction>
    </actuator>
  </transmission>
  <link name="r_Mmiddle">
    <inertial>
      <origin rpy="0.00028099 0.00058278 0.03232242" xyz="-0.00009694 -0.01116046 0.00000050"/>
      <mass value="0.00475397"/>
      <inertia ixx="0.00000040" ixy="-0.00000001" ixz="0" iyy="0.00000016" iyz="0" izz="0.00000036"/>
    </inertial>
    <visual>
      <origin rpy="0 0 0" xyz="0 0 0"/>
      <geometry>
        <mesh filename="/export/home/strahl/dev/gaikpy/resources/urdf/nicol/meshes/RH8D/phalanx_refac.stl" scale="0.001 0.001 0.001"/>
      </geometry>
      <material name="rh8d_color"/>
    </visual>
    <collision>
      <origin rpy="0 0 0" xyz="0 0 0"/>
      <geometry>
        <mesh filename="/export/home/strahl/dev/gaikpy/resources/urdf/nicol/meshes/RH8D/phalanx_refac.stl" scale="0.001 0.001 0.001"/>
      </geometry>
    </collision>
  </link>
  <joint name="r_jointM3" type="revolute">
    <origin rpy="0 0 0.078" xyz="0 -0.0258749732 0"/>
    <parent link="r_Mmiddle"/>
    <child link="r_Mtip"/>
    <axis xyz="0 0 1"/>
    <limit effort="0.5" lower="0.0" upper="1.4835298642" velocity="1.0"/>
    <dynamics damping="0.0001"/>
  </joint>
  <transmission name="tranr_M3">
    <type>transmission_interface/SimpleTransmission</type>
    <joint name="r_jointM3">
      <hardwareInterface>hardware_interface/PositionJointInterface</hardwareInterface>
    </joint>
    <actuator name="motorr_M3">
      <hardwareInterface>hardware_interface/PositionJointInterface</hardwareInterface>
      <mechanicalReduction>1</mechanicalReduction>
    </actuator>
  </transmission>
  <link name="r_Mtip">
    <inertial>
      <origin rpy="0.00105402 -0.00291363 -0.08777144" xyz="0.00064228 -0.01044102 0.00000295"/>
      <mass value="0.00475224"/>
      <inertia ixx="0.00000031" ixy="0.00000001" ixz="0" iyy="0.00000014" iyz="0" izz="0.00000029"/>
    </inertial>
    <visual>
      <origin rpy="0 0 0" xyz="0 0 0"/>
      <geometry>
        <mesh filename="/export/home/strahl/dev/gaikpy/resources/urdf/nicol/meshes/RH8D/tip_refac.stl" scale="0.001 0.001 0.001"/>
      </geometry>
      <material name="rh8d_color"/>
    </visual>
    <collision>
      <origin rpy="0 0 0" xyz="0 0 0"/>
      <geometry>
        <mesh filename="/export/home/strahl/dev/gaikpy/resources/urdf/nicol/meshes/RH8D/tip_refac.stl" scale="0.001 0.001 0.001"/>
      </geometry>
    </collision>
  </link>
  <joint name="r_jointR1" type="revolute">
    <origin rpy="0.0798369 -0.09241357 -2.88345893" xyz="-0.0011171786 0.0818708881 -0.0130285291"/>
    <parent link="r_palm"/>
    <child link="r_Rproximal"/>
    <axis xyz="0 0 1"/>
    <limit effort="0.5" lower="0.0" upper="1.4835298642" velocity="1.0"/>
    <dynamics damping="0.0001"/>
  </joint>
  <transmission name="tranr_R1">
    <type>transmission_interface/SimpleTransmission</type>
    <joint name="r_jointR1">
      <hardwareInterface>hardware_interface/PositionJointInterface</hardwareInterface>
    </joint>
    <actuator name="motorr_R1">
      <hardwareInterface>hardware_interface/PositionJointInterface</hardwareInterface>
      <mechanicalReduction>1</mechanicalReduction>
    </actuator>
  </transmission>
  <link name="r_Rproximal">
    <inertial>
      <origin rpy="0.00028099 0.00058278 0.03232242" xyz="-0.00009694 -0.01116046 0.00000050"/>
      <mass value="0.00475397"/>
      <inertia ixx="0.00000040" ixy="-0.00000001" ixz="0" iyy="0.00000016" iyz="0" izz="0.00000036"/>
    </inertial>
    <visual>
      <origin rpy="0 0 0" xyz="0 0 0"/>
      <geometry>
        <mesh filename="/export/home/strahl/dev/gaikpy/resources/urdf/nicol/meshes/RH8D/phalanx_refac.stl" scale="0.001 0.001 0.001"/>
      </geometry>
      <material name="rh8d_color"/>
    </visual>
    <collision>
      <origin rpy="0 0 0" xyz="0 0 0"/>
      <geometry>
        <mesh filename="/export/home/strahl/dev/gaikpy/resources/urdf/nicol/meshes/RH8D/phalanx_refac.stl" scale="0.001 0.001 0.001"/>
      </geometry>
    </collision>
  </link>
  <joint name="r_jointR2" type="revolute">
    <origin rpy="0 0 0" xyz="0 -0.0258749732 0"/>
    <parent link="r_Rproximal"/>
    <child link="r_Rmiddle"/>
    <axis xyz="0 0 1"/>
    <limit effort="0.5" lower="0.0" upper="1.4835298642" velocity="1.0"/>
    <dynamics damping="0.0001"/>
  </joint>
  <transmission name="tranr_R2">
    <type>transmission_interface/SimpleTransmission</type>
    <joint name="r_jointR2">
      <hardwareInterface>hardware_interface/PositionJointInterface</hardwareInterface>
    </joint>
    <actuator name="motorr_R2">
      <hardwareInterface>hardware_interface/PositionJointInterface</hardwareInterface>
      <mechanicalReduction>1</mechanicalReduction>
    </actuator>
  </transmission>
  <link name="r_Rmiddle">
    <inertial>
      <origin rpy="0.00028099 0.00058278 0.03232242" xyz="-0.00009694 -0.01116046 0.00000050"/>
      <mass value="0.00475397"/>
      <inertia ixx="0.00000040" ixy="-0.00000001" ixz="0" iyy="0.00000016" iyz="0" izz="0.00000036"/>
    </inertial>
    <visual>
      <origin rpy="0 0 0" xyz="0 0 0"/>
      <geometry>
        <mesh filename="/export/home/strahl/dev/gaikpy/resources/urdf/nicol/meshes/RH8D/phalanx_refac.stl" scale="0.001 0.001 0.001"/>
      </geometry>
      <material name="rh8d_color"/>
    </visual>
    <collision>
      <origin rpy="0 0 0" xyz="0 0 0"/>
      <geometry>
        <mesh filename="/export/home/strahl/dev/gaikpy/resources/urdf/nicol/meshes/RH8D/phalanx_refac.stl" scale="0.001 0.001 0.001"/>
      </geometry>
    </collision>
  </link>
  <joint name="r_jointR3" type="revolute">
    <origin rpy="0 0 0.078" xyz="0 -0.0258749732 0"/>
    <parent link="r_Rmiddle"/>
    <child link="r_Rtip"/>
    <axis xyz="0 0 1"/>
    <limit effort="0.5" lower="0.0" upper="1.4835298642" velocity="1.0"/>
    <dynamics damping="0.0001"/>
  </joint>
  <transmission name="tranr_R3">
    <type>transmission_interface/SimpleTransmission</type>
    <joint name="r_jointR3">
      <hardwareInterface>hardware_interface/PositionJointInterface</hardwareInterface>
    </joint>
    <actuator name="motorr_R3">
      <hardwareInterface>hardware_interface/PositionJointInterface</hardwareInterface>
      <mechanicalReduction>1</mechanicalReduction>
    </actuator>
  </transmission>
  <link name="r_Rtip">
    <inertial>
      <origin rpy="0.00105402 -0.00291363 -0.08777144" xyz="0.00064228 -0.01044102 0.00000295"/>
      <mass value="0.00475224"/>
      <inertia ixx="0.00000031" ixy="0.00000001" ixz="0" iyy="0.00000014" iyz="0" izz="0.00000029"/>
    </inertial>
    <visual>
      <origin rpy="0 0 0" xyz="0 0 0"/>
      <geometry>
        <mesh filename="/export/home/strahl/dev/gaikpy/resources/urdf/nicol/meshes/RH8D/tip_refac.stl" scale="0.001 0.001 0.001"/>
      </geometry>
      <material name="rh8d_color"/>
    </visual>
    <collision>
      <origin rpy="0 0 0" xyz="0 0 0"/>
      <geometry>
        <mesh filename="/export/home/strahl/dev/gaikpy/resources/urdf/nicol/meshes/RH8D/tip_refac.stl" scale="0.001 0.001 0.001"/>
      </geometry>
    </collision>
  </link>
  <joint name="r_jointL1" type="revolute">
    <origin rpy="0.1572281 -0.19023965 -2.87172735" xyz="-0.0031705239 0.0731417977 -0.0376310382"/>
    <parent link="r_palm"/>
    <child link="r_Lproximal"/>
    <axis xyz="0 0 1"/>
    <limit effort="0.5" lower="0.0" upper="1.4835298642" velocity="1.0"/>
    <dynamics damping="0.0001"/>
  </joint>
  <transmission name="tranr_L1">
    <type>transmission_interface/SimpleTransmission</type>
    <joint name="r_jointL1">
      <hardwareInterface>hardware_interface/PositionJointInterface</hardwareInterface>
    </joint>
    <actuator name="motorr_L1">
      <hardwareInterface>hardware_interface/PositionJointInterface</hardwareInterface>
      <mechanicalReduction>1</mechanicalReduction>
    </actuator>
  </transmission>
  <link name="r_Lproximal">
    <inertial>
      <origin rpy="0.00028099 0.00058278 0.03232242" xyz="-0.00009694 -0.01116046 0.00000050"/>
      <mass value="0.00475397"/>
      <inertia ixx="0.00000040" ixy="-0.00000001" ixz="0" iyy="0.00000016" iyz="0" izz="0.00000036"/>
    </inertial>
    <visual>
      <origin rpy="0 0 0" xyz="0 0 0"/>
      <geometry>
        <mesh filename="/export/home/strahl/dev/gaikpy/resources/urdf/nicol/meshes/RH8D/phalanx_refac.stl" scale="0.001 0.001 0.001"/>
      </geometry>
      <material name="rh8d_color"/>
    </visual>
    <collision>
      <origin rpy="0 0 0" xyz="0 0 0"/>
      <geometry>
        <mesh filename="/export/home/strahl/dev/gaikpy/resources/urdf/nicol/meshes/RH8D/phalanx_refac.stl" scale="0.001 0.001 0.001"/>
      </geometry>
    </collision>
  </link>
  <joint name="r_jointL2" type="revolute">
    <origin rpy="0 0 0" xyz="0 -0.0258749732 0"/>
    <parent link="r_Lproximal"/>
    <child link="r_Lmiddle"/>
    <axis xyz="0 0 1"/>
    <limit effort="0.5" lower="0.0" upper="1.4835298642" velocity="1.0"/>
    <dynamics damping="0.0001"/>
  </joint>
  <transmission name="tranr_L2">
    <type>transmission_interface/SimpleTransmission</type>
    <joint name="r_jointL2">
      <hardwareInterface>hardware_interface/PositionJointInterface</hardwareInterface>
    </joint>
    <actuator name="motorr_L2">
      <hardwareInterface>hardware_interface/PositionJointInterface</hardwareInterface>
      <mechanicalReduction>1</mechanicalReduction>
    </actuator>
  </transmission>
  <link name="r_Lmiddle">
    <inertial>
      <origin rpy="0.00028099 0.00058278 0.03232242" xyz="-0.00009694 -0.01116046 0.00000050"/>
      <mass value="0.00475397"/>
      <inertia ixx="0.00000040" ixy="-0.00000001" ixz="0" iyy="0.00000016" iyz="0" izz="0.00000036"/>
    </inertial>
    <visual>
      <origin rpy="0 0 0" xyz="0 0 0"/>
      <geometry>
        <mesh filename="/export/home/strahl/dev/gaikpy/resources/urdf/nicol/meshes/RH8D/phalanx_refac.stl" scale="0.001 0.001 0.001"/>
      </geometry>
      <material name="rh8d_color"/>
    </visual>
    <collision>
      <origin rpy="0 0 0" xyz="0 0 0"/>
      <geometry>
        <mesh filename="/export/home/strahl/dev/gaikpy/resources/urdf/nicol/meshes/RH8D/phalanx_refac.stl" scale="0.001 0.001 0.001"/>
      </geometry>
    </collision>
  </link>
  <joint name="r_jointL3" type="revolute">
    <origin rpy="0 0 0.078" xyz="0 -0.0258749732 0"/>
    <parent link="r_Lmiddle"/>
    <child link="r_Ltip"/>
    <axis xyz="0 0 1"/>
    <limit effort="0.5" lower="0.0" upper="1.4835298642" velocity="1.0"/>
    <dynamics damping="0.0001"/>
  </joint>
  <transmission name="tranr_L3">
    <type>transmission_interface/SimpleTransmission</type>
    <joint name="r_jointL3">
      <hardwareInterface>hardware_interface/PositionJointInterface</hardwareInterface>
    </joint>
    <actuator name="motorr_L3">
      <hardwareInterface>hardware_interface/PositionJointInterface</hardwareInterface>
      <mechanicalReduction>1</mechanicalReduction>
    </actuator>
  </transmission>
  <link name="r_Ltip">
    <inertial>
      <origin rpy="0.00105402 -0.00291363 -0.08777144" xyz="0.00064228 -0.01044102 0.00000295"/>
      <mass value="0.00475224"/>
      <inertia ixx="0.00000031" ixy="0.00000001" ixz="0" iyy="0.00000014" iyz="0" izz="0.00000029"/>
    </inertial>
    <visual>
      <origin rpy="0 0 0" xyz="0 0 0"/>
      <geometry>
        <mesh filename="/export/home/strahl/dev/gaikpy/resources/urdf/nicol/meshes/RH8D/tip_refac.stl" scale="0.001 0.001 0.001"/>
      </geometry>
      <material name="rh8d_color"/>
    </visual>
    <collision>
      <origin rpy="0 0 0" xyz="0 0 0"/>
      <geometry>
        <mesh filename="/export/home/strahl/dev/gaikpy/resources/urdf/nicol/meshes/RH8D/tip_refac.stl" scale="0.001 0.001 0.001"/>
      </geometry>
    </collision>
  </link>
  <!-- link 1 -->
  <link name="r_link1">
    <collision>
      <!-- simplify collision to box -->
      <origin rpy="0 0 0" xyz="0 0 0.055"/>
      <geometry>
        <!-- <mesh filename="${omp_stl_path}link_1_reduced.stl" scale="0.001 0.001 0.001"/> -->
        <box size="0.055 0.055 0.13"/>
      </geometry>
    </collision>
    <visual>
      <origin rpy="0 0 0" xyz="0 0 0"/>
      <geometry>
        <mesh filename="/export/home/strahl/dev/gaikpy/resources/urdf/nicol/meshes/open_manipulator/link_1_reduced.stl" scale="0.001 0.001 0.001"/>
      </geometry>
      <material name="grey"/>
    </visual>
    <inertial>
      <origin rpy="0 0 0" xyz="0.000001 0 0.060920"/>
      <mass value="0.902296"/>
      <inertia ixx="0.001343" ixy="0" ixz="0" iyy="0.001345" iyz="0" izz="0.000397"/>
    </inertial>
  </link>
  <!-- Joint 1 -->
  <joint name="r_joint1" type="revolute">
    <parent link="r_link1"/>
    <child link="r_link2"/>
    <origin rpy="0 0 -1.5707963267948966" xyz="0.0 0.0 0.126"/>
    <axis xyz="0 0 1"/>
    <limit effort="1000" lower="0" upper="3.141592653589793" velocity="6.5"/>
    <dynamics damping="0.1" friction="0.0"/>
    <!-- <safety_controller k_velocity="10" k_position="15" soft_lower_limit="-2.0" soft_upper_limit="0.5" /> -->
  </joint>
  <transmission name="tranr_1">
    <type>transmission_interface/SimpleTransmission</type>
    <joint name="r_joint1">
      <hardwareInterface>hardware_interface/PositionJointInterface</hardwareInterface>
    </joint>
    <actuator name="motorr_1">
      <hardwareInterface>hardware_interface/PositionJointInterface</hardwareInterface>
      <mechanicalReduction>1</mechanicalReduction>
    </actuator>
  </transmission>
  <!-- link 2 -->
  <link name="r_link2">
    <collision>
      <!-- simplify collision to box -->
      <origin rpy="0 0 0" xyz="0 -0.002 0.033"/>
      <geometry>
        <!-- <mesh filename="${omp_stl_path}link_2_reduced.stl" scale="0.001 0.001 0.001"/> -->
        <box size="0.055 0.1325 0.055"/>
      </geometry>
    </collision>
    <visual>
      <origin rpy="0 0 0" xyz="0 0 0"/>
      <geometry>
        <mesh filename="/export/home/strahl/dev/gaikpy/resources/urdf/nicol/meshes/open_manipulator/link_2_reduced.stl" scale="0.001 0.001 0.001"/>
      </geometry>
      <material name="grey"/>
    </visual>
    <inertial>
      <origin rpy="0 0 0" xyz="0 0.000436 0.032021"/>
      <mass value="0.985121"/>
      <inertia ixx="0.001611" ixy="0" ixz="0" iyy="0.000473" iyz="0" izz="0.001599"/>
    </inertial>
  </link>
  <!-- Joint 2 -->
  <joint name="r_joint2" type="revolute">
    <parent link="r_link2"/>
    <child link="r_link3"/>
    <origin rpy="0 0 0" xyz="0.0 0.069 0.033"/>
    <axis xyz="0 1 0"/>
    <limit effort="1000" lower="-1.5707963267948966" upper="1.5707963267948966" velocity="6.5"/>
    <dynamics damping="0.1" friction="0.0"/>
  </joint>
  <transmission name="tranr_2">
    <type>transmission_interface/SimpleTransmission</type>
    <joint name="r_joint2">
      <hardwareInterface>hardware_interface/PositionJointInterface</hardwareInterface>
    </joint>
    <actuator name="motorr_2">
      <hardwareInterface>hardware_interface/PositionJointInterface</hardwareInterface>
      <mechanicalReduction>1</mechanicalReduction>
    </actuator>
  </transmission>
  <!-- link 3 -->
  <link name="r_link3">
    <collision>
      <origin rpy="0 0 0" xyz="0 0 0"/>
      <geometry>
        <mesh filename="/export/home/strahl/dev/gaikpy/resources/urdf/nicol/meshes/open_manipulator/link_3_reduced.stl" scale="0.001 0.001 0.001"/>
      </geometry>
    </collision>
    <visual>
      <origin rpy="0 0 0" xyz="0 0 0"/>
      <geometry>
        <mesh filename="/export/home/strahl/dev/gaikpy/resources/urdf/nicol/meshes/open_manipulator/link_3_reduced.stl" scale="0.001 0.001 0.001"/>
      </geometry>
      <material name="grey"/>
    </visual>
    <inertial>
      <origin rpy="-0.011848 -0.133044 0.017678" xyz="0.015706 -0.070340 0.199125"/>
      <mass value="1.501407"/>
      <inertia ixx="0.013723" ixy="-0.000001" ixz="-0.001527" iyy="0.012824" iyz="0.000125" izz="0.002524"/>
    </inertial>
  </link>
  <!-- Joint 3 -->
  <joint name="r_joint3" type="revolute">
    <parent link="r_link3"/>
    <child link="r_link4"/>
    <origin rpy="0 0 0" xyz="0.03000 -0.01150 0.26400"/>
    <axis xyz="0 1 0"/>
    <limit effort="1000" lower="-1.5707963267948966" upper="1.5707963267948966" velocity="6.5"/>
    <dynamics damping="0.1" friction="0.0"/>
  </joint>
  <transmission name="tranr_3">
    <type>transmission_interface/SimpleTransmission</type>
    <joint name="r_joint3">
      <hardwareInterface>hardware_interface/PositionJointInterface</hardwareInterface>
    </joint>
    <actuator name="motorr_3">
      <hardwareInterface>hardware_interface/PositionJointInterface</hardwareInterface>
      <mechanicalReduction>1</mechanicalReduction>
    </actuator>
  </transmission>
  <!-- link 4 -->
  <link name="r_link4">
    <collision>
      <origin rpy="0 0 0" xyz="0 0 0"/>
      <geometry>
        <mesh filename="/export/home/strahl/dev/gaikpy/resources/urdf/nicol/meshes/open_manipulator/link_4_reduced.stl" scale="0.001 0.001 0.001"/>
      </geometry>
    </collision>
    <visual>
      <origin rpy="0 0 0" xyz="0 0 0"/>
      <geometry>
        <mesh filename="/export/home/strahl/dev/gaikpy/resources/urdf/nicol/meshes/open_manipulator/link_4_reduced.stl" scale="0.001 0.001 0.001"/>
      </geometry>
      <material name="grey"/>
    </visual>
    <inertial>
      <origin rpy="0.002216 0.017493 0.001153" xyz="0.120352 -0.057519 0.029683"/>
      <mass value="1.330903"/>
      <inertia ixx="0.001287" ixy="0.000003" ixz="-0.000060" iyy="0.004298" iyz="0.000001" izz="0.004730"/>
    </inertial>
  </link>
  <!-- Joint 4 -->
  <joint name="r_joint4" type="revolute">
    <parent link="r_link4"/>
    <child link="r_link5"/>
    <origin rpy="0 0 0" xyz="0.19500 -0.05750 0.03000"/>
    <axis xyz="1 0 0"/>
    <limit effort="1000" lower="-1.5707963267948966" upper="1.5707963267948966" velocity="6.5"/>
    <dynamics damping="0.1" friction="0.0"/>
  </joint>
  <transmission name="tranr_4">
    <type>transmission_interface/SimpleTransmission</type>
    <joint name="r_joint4">
      <hardwareInterface>hardware_interface/PositionJointInterface</hardwareInterface>
    </joint>
    <actuator name="motorr_4">
      <hardwareInterface>hardware_interface/PositionJointInterface</hardwareInterface>
      <mechanicalReduction>1</mechanicalReduction>
    </actuator>
  </transmission>
  <!-- link 5 -->
  <link name="r_link5">
    <collision>
      <!-- simplify collision to box -->
      <origin rpy="0 0 0" xyz="0.061 0 0"/>
      <geometry>
        <!-- <mesh filename="${omp_stl_path}link_5_reduced.stl" scale="0.001 0.001 0.001"/> -->
        <box size="0.047 0.086 0.05"/>
      </geometry>
    </collision>
    <visual>
      <origin rpy="0 0 0" xyz="0 0 0"/>
      <geometry>
        <mesh filename="/export/home/strahl/dev/gaikpy/resources/urdf/nicol/meshes/open_manipulator/link_5_reduced.stl" scale="0.001 0.001 0.001"/>
      </geometry>
      <material name="grey"/>
    </visual>
    <inertial>
      <origin rpy="-0.000001 0 -0.002436" xyz="0.057143 -0.002069 0"/>
      <mass value="0.449696"/>
      <inertia ixx="0.000306" ixy="0" ixz="0" iyy="0.000212" iyz="0" izz="0.000390"/>
    </inertial>
  </link>
  <!-- Joint 5 -->
  <joint name="r_joint5" type="revolute">
    <parent link="r_link5"/>
    <child link="r_link6"/>
    <origin rpy="0 0 0" xyz="0.06300 0.04500 0.00000"/>
    <axis xyz="0 1 0"/>
    <limit effort="1000" lower="-1.5707963267948966" upper="1.5707963267948966" velocity="6.5"/>
    <dynamics damping="0.01" friction="0.0"/>
  </joint>
  <transmission name="tranr_5">
    <type>transmission_interface/SimpleTransmission</type>
    <joint name="r_joint5">
      <hardwareInterface>hardware_interface/PositionJointInterface</hardwareInterface>
    </joint>
    <actuator name="motorr_5">
      <hardwareInterface>hardware_interface/PositionJointInterface</hardwareInterface>
      <mechanicalReduction>1</mechanicalReduction>
    </actuator>
  </transmission>
  <!-- link 6 -->
  <link name="r_link6">
    <collision>
      <origin rpy="0 0 0" xyz="0 0 0"/>
      <geometry>
        <mesh filename="/export/home/strahl/dev/gaikpy/resources/urdf/nicol/meshes/open_manipulator/link_6_reduced.stl" scale="0.001 0.001 0.001"/>
      </geometry>
    </collision>
    <visual>
      <origin rpy="0 0 0" xyz="0 0 0"/>
      <geometry>
        <mesh filename="/export/home/strahl/dev/gaikpy/resources/urdf/nicol/meshes/open_manipulator/link_6_reduced.stl" scale="0.001 0.001 0.001"/>
      </geometry>
      <material name="grey"/>
    </visual>
    <inertial>
      <origin rpy="0 -0.000491 -0.002812" xyz="0.068686 -0.044988 -0.000034"/>
      <mass value="0.444892"/>
      <inertia ixx="0.000215" ixy="-0.000001" ixz="0" iyy="0.000443" iyz="0" izz="0.000529"/>
    </inertial>
  </link>
  <!-- Joint 6 connects to hand base-->
  <joint name="r_joint6" type="revolute">
    <parent link="r_link6"/>
    <!-- <child link="r_RH8D_base"/> -->
    <child link="r_forearm"/>
    <origin rpy="1.5707963267948966 0 1.5707963267948966" xyz="0.12300 -0.04500 0.00000"/>
    <axis xyz="0 0 1"/>
    <limit effort="1000" lower="-1.5707963267948966" upper="1.5707963267948966" velocity="6.5"/>
    <dynamics damping="0.01" friction="0.0"/>
  </joint>
  <transmission name="tranr_6">
    <type>transmission_interface/SimpleTransmission</type>
    <joint name="r_joint6">
      <hardwareInterface>hardware_interface/PositionJointInterface</hardwareInterface>
    </joint>
    <actuator name="motorr_6">
      <hardwareInterface>hardware_interface/PositionJointInterface</hardwareInterface>
      <mechanicalReduction>1</mechanicalReduction>
    </actuator>
  </transmission>
  <!-- condition args -->
  <!-- <xacro:property name="body_side" value="$(arg body_side)"/> -->
  <gazebo>
    <plugin filename="libgazebo_ros_control.so" name="gazebo_ros_control">
      <robotNamespace>right/open_manipulator_p</robotNamespace>
      <robotSimType>gazebo_ros_control/DefaultRobotHWSim</robotSimType>
    </plugin>
  </gazebo>
  <gazebo reference="r_link1">
    <kp>1000000.0</kp>
    <kd>100.0</kd>
    <mu1>30.0</mu1>
    <mu2>30.0</mu2>
    <maxVel>1.0</maxVel>
    <minDepth>0.001</minDepth>
    <material>Gazebo/DarkGrey</material>
  </gazebo>
  <gazebo reference="r_link2">
    <kp>1000000.0</kp>
    <kd>100.0</kd>
    <mu1>30.0</mu1>
    <mu2>30.0</mu2>
    <maxVel>1.0</maxVel>
    <minDepth>0.001</minDepth>
    <material>Gazebo/DarkGrey</material>
  </gazebo>
  <gazebo reference="r_link3">
    <kp>1000000.0</kp>
    <kd>100.0</kd>
    <mu1>30.0</mu1>
    <mu2>30.0</mu2>
    <maxVel>1.0</maxVel>
    <minDepth>0.001</minDepth>
    <material>Gazebo/DarkGrey</material>
  </gazebo>
  <gazebo reference="r_link4">
    <kp>1000000.0</kp>
    <kd>100.0</kd>
    <mu1>30.0</mu1>
    <mu2>30.0</mu2>
    <maxVel>1.0</maxVel>
    <minDepth>0.001</minDepth>
    <material>Gazebo/DarkGrey</material>
  </gazebo>
  <gazebo reference="r_link5">
    <kp>1000000.0</kp>
    <kd>100.0</kd>
    <mu1>30.0</mu1>
    <mu2>30.0</mu2>
    <maxVel>1.0</maxVel>
    <minDepth>0.001</minDepth>
    <material>Gazebo/DarkGrey</material>
  </gazebo>
  <gazebo reference="r_link6">
    <kp>1000000.0</kp>
    <kd>100.0</kd>
    <mu1>30.0</mu1>
    <mu2>30.0</mu2>
    <maxVel>1.0</maxVel>
    <minDepth>0.001</minDepth>
    <material>Gazebo/DarkGrey</material>
  </gazebo>
  <gazebo reference="r_forearm">
    <!-- <kp>1000000.0</kp>
      <kd>100.0</kd>
      <mu1>30.0</mu1>
      <mu2>30.0</mu2>
      <maxVel>1.0</maxVel>
      <minDepth>0.001</minDepth> -->
    <!-- <visual>
        <material>
          <ambient>0.74902 0.74902 0.74902 1.0</ambient>
          <diffuse>0.74902 0.74902 0.74902 1.0</diffuse>
          <specular>0.74902 0.74902 0.74902 1.0</specular>
        </material>
      </visual> -->
    <mu1>0.2</mu1>
    <mu2>0.2</mu2>
    <material>Gazebo/Grey</material>
  </gazebo>
  <gazebo reference="r_palm_axis">
    <!-- <kp>1000000.0</kp>
      <kd>100.0</kd>
      <mu1>30.0</mu1>
      <mu2>30.0</mu2>
      <maxVel>1.0</maxVel>
      <minDepth>0.001</minDepth> -->
    <!-- <visual>
        <material>
          <ambient>0.74902 0.74902 0.74902 1.0</ambient>
          <diffuse>0.74902 0.74902 0.74902 1.0</diffuse>
          <specular>0.74902 0.74902 0.74902 1.0</specular>
        </material>
      </visual> -->
    <mu1>0.2</mu1>
    <mu2>0.2</mu2>
    <material>Gazebo/Grey</material>
  </gazebo>
  <gazebo reference="r_palm">
    <!-- <kp>1000000.0</kp>
      <kd>100.0</kd>
      <mu1>30.0</mu1>
      <mu2>30.0</mu2>
      <maxVel>1.0</maxVel>
      <minDepth>0.001</minDepth> -->
    <!-- <visual>
        <material>
          <ambient>0.74902 0.74902 0.74902 1.0</ambient>
          <diffuse>0.74902 0.74902 0.74902 1.0</diffuse>
          <specular>0.74902 0.74902 0.74902 1.0</specular>
        </material>
      </visual> -->
    <mu1>0.2</mu1>
    <mu2>0.2</mu2>
    <material>Gazebo/Grey</material>
  </gazebo>
  <gazebo reference="r_Rproximal">
    <!-- <kp>1000000.0</kp>
      <kd>100.0</kd>
      <mu1>30.0</mu1>
      <mu2>30.0</mu2>
      <maxVel>1.0</maxVel>
      <minDepth>0.001</minDepth> -->
    <!-- <visual>
        <material>
          <ambient>0.74902 0.74902 0.74902 1.0</ambient>
          <diffuse>0.74902 0.74902 0.74902 1.0</diffuse>
          <specular>0.74902 0.74902 0.74902 1.0</specular>
        </material>
      </visual> -->
    <mu1>0.2</mu1>
    <mu2>0.2</mu2>
    <material>Gazebo/Grey</material>
  </gazebo>
  <gazebo reference="r_Rmiddle">
    <!-- <kp>1000000.0</kp>
      <kd>100.0</kd>
      <mu1>30.0</mu1>
      <mu2>30.0</mu2>
      <maxVel>1.0</maxVel>
      <minDepth>0.001</minDepth> -->
    <!-- <visual>
        <material>
          <ambient>0.74902 0.74902 0.74902 1.0</ambient>
          <diffuse>0.74902 0.74902 0.74902 1.0</diffuse>
          <specular>0.74902 0.74902 0.74902 1.0</specular>
        </material>
      </visual> -->
    <mu1>0.2</mu1>
    <mu2>0.2</mu2>
    <material>Gazebo/Grey</material>
  </gazebo>
  <gazebo reference="r_Rtip">
    <!-- <kp>1000000.0</kp>
      <kd>100.0</kd>
      <mu1>30.0</mu1>
      <mu2>30.0</mu2>
      <maxVel>1.0</maxVel>
      <minDepth>0.001</minDepth> -->
    <!-- <visual>
        <material>
          <ambient>0.74902 0.74902 0.74902 1.0</ambient>
          <diffuse>0.74902 0.74902 0.74902 1.0</diffuse>
          <specular>0.74902 0.74902 0.74902 1.0</specular>
        </material>
      </visual> -->
    <mu1>0.2</mu1>
    <mu2>0.2</mu2>
    <material>Gazebo/Grey</material>
  </gazebo>
  <gazebo reference="r_Mproximal">
    <!-- <kp>1000000.0</kp>
      <kd>100.0</kd>
      <mu1>30.0</mu1>
      <mu2>30.0</mu2>
      <maxVel>1.0</maxVel>
      <minDepth>0.001</minDepth> -->
    <!-- <visual>
        <material>
          <ambient>0.74902 0.74902 0.74902 1.0</ambient>
          <diffuse>0.74902 0.74902 0.74902 1.0</diffuse>
          <specular>0.74902 0.74902 0.74902 1.0</specular>
        </material>
      </visual> -->
    <mu1>0.2</mu1>
    <mu2>0.2</mu2>
    <material>Gazebo/Grey</material>
  </gazebo>
  <gazebo reference="r_Mmiddle">
    <!-- <kp>1000000.0</kp>
      <kd>100.0</kd>
      <mu1>30.0</mu1>
      <mu2>30.0</mu2>
      <maxVel>1.0</maxVel>
      <minDepth>0.001</minDepth> -->
    <!-- <visual>
        <material>
          <ambient>0.74902 0.74902 0.74902 1.0</ambient>
          <diffuse>0.74902 0.74902 0.74902 1.0</diffuse>
          <specular>0.74902 0.74902 0.74902 1.0</specular>
        </material>
      </visual> -->
    <mu1>0.2</mu1>
    <mu2>0.2</mu2>
    <material>Gazebo/Grey</material>
  </gazebo>
  <gazebo reference="r_Mtip">
    <!-- <kp>1000000.0</kp>
      <kd>100.0</kd>
      <mu1>30.0</mu1>
      <mu2>30.0</mu2>
      <maxVel>1.0</maxVel>
      <minDepth>0.001</minDepth> -->
    <!-- <visual>
        <material>
          <ambient>0.74902 0.74902 0.74902 1.0</ambient>
          <diffuse>0.74902 0.74902 0.74902 1.0</diffuse>
          <specular>0.74902 0.74902 0.74902 1.0</specular>
        </material>
      </visual> -->
    <mu1>0.2</mu1>
    <mu2>0.2</mu2>
    <material>Gazebo/Grey</material>
  </gazebo>
  <gazebo reference="r_Pproximal">
    <!-- <kp>1000000.0</kp>
      <kd>100.0</kd>
      <mu1>30.0</mu1>
      <mu2>30.0</mu2>
      <maxVel>1.0</maxVel>
      <minDepth>0.001</minDepth> -->
    <!-- <visual>
        <material>
          <ambient>0.74902 0.74902 0.74902 1.0</ambient>
          <diffuse>0.74902 0.74902 0.74902 1.0</diffuse>
          <specular>0.74902 0.74902 0.74902 1.0</specular>
        </material>
      </visual> -->
    <mu1>0.2</mu1>
    <mu2>0.2</mu2>
    <material>Gazebo/Grey</material>
  </gazebo>
  <gazebo reference="r_Pmiddle">
    <!-- <kp>1000000.0</kp>
      <kd>100.0</kd>
      <mu1>30.0</mu1>
      <mu2>30.0</mu2>
      <maxVel>1.0</maxVel>
      <minDepth>0.001</minDepth> -->
    <!-- <visual>
        <material>
          <ambient>0.74902 0.74902 0.74902 1.0</ambient>
          <diffuse>0.74902 0.74902 0.74902 1.0</diffuse>
          <specular>0.74902 0.74902 0.74902 1.0</specular>
        </material>
      </visual> -->
    <mu1>0.2</mu1>
    <mu2>0.2</mu2>
    <material>Gazebo/Grey</material>
  </gazebo>
  <gazebo reference="r_Ptip">
    <!-- <kp>1000000.0</kp>
      <kd>100.0</kd>
      <mu1>30.0</mu1>
      <mu2>30.0</mu2>
      <maxVel>1.0</maxVel>
      <minDepth>0.001</minDepth> -->
    <!-- <visual>
        <material>
          <ambient>0.74902 0.74902 0.74902 1.0</ambient>
          <diffuse>0.74902 0.74902 0.74902 1.0</diffuse>
          <specular>0.74902 0.74902 0.74902 1.0</specular>
        </material>
      </visual> -->
    <mu1>0.2</mu1>
    <mu2>0.2</mu2>
    <material>Gazebo/Grey</material>
  </gazebo>
  <gazebo reference="r_thumb_base">
    <!-- <kp>1000000.0</kp>
      <kd>100.0</kd>
      <mu1>30.0</mu1>
      <mu2>30.0</mu2>
      <maxVel>1.0</maxVel>
      <minDepth>0.001</minDepth> -->
    <!-- <visual>
        <material>
          <ambient>0.74902 0.74902 0.74902 1.0</ambient>
          <diffuse>0.74902 0.74902 0.74902 1.0</diffuse>
          <specular>0.74902 0.74902 0.74902 1.0</specular>
        </material>
      </visual> -->
    <mu1>0.2</mu1>
    <mu2>0.2</mu2>
    <material>Gazebo/Grey</material>
  </gazebo>
  <gazebo reference="r_Tproximal">
    <!-- <kp>1000000.0</kp>
      <kd>100.0</kd>
      <mu1>30.0</mu1>
      <mu2>30.0</mu2>
      <maxVel>1.0</maxVel>
      <minDepth>0.001</minDepth> -->
    <!-- <visual>
        <material>
          <ambient>0.74902 0.74902 0.74902 1.0</ambient>
          <diffuse>0.74902 0.74902 0.74902 1.0</diffuse>
          <specular>0.74902 0.74902 0.74902 1.0</specular>
        </material>
      </visual> -->
    <mu1>0.2</mu1>
    <mu2>0.2</mu2>
    <material>Gazebo/Grey</material>
  </gazebo>
  <gazebo reference="r_Tmiddle">
    <!-- <kp>1000000.0</kp>
      <kd>100.0</kd>
      <mu1>30.0</mu1>
      <mu2>30.0</mu2>
      <maxVel>1.0</maxVel>
      <minDepth>0.001</minDepth> -->
    <!-- <visual>
        <material>
          <ambient>0.74902 0.74902 0.74902 1.0</ambient>
          <diffuse>0.74902 0.74902 0.74902 1.0</diffuse>
          <specular>0.74902 0.74902 0.74902 1.0</specular>
        </material>
      </visual> -->
    <mu1>0.2</mu1>
    <mu2>0.2</mu2>
    <material>Gazebo/Grey</material>
  </gazebo>
  <gazebo reference="r_Ttip">
    <!-- <kp>1000000.0</kp>
      <kd>100.0</kd>
      <mu1>30.0</mu1>
      <mu2>30.0</mu2>
      <maxVel>1.0</maxVel>
      <minDepth>0.001</minDepth> -->
    <!-- <visual>
        <material>
          <ambient>0.74902 0.74902 0.74902 1.0</ambient>
          <diffuse>0.74902 0.74902 0.74902 1.0</diffuse>
          <specular>0.74902 0.74902 0.74902 1.0</specular>
        </material>
      </visual> -->
    <mu1>0.2</mu1>
    <mu2>0.2</mu2>
    <material>Gazebo/Grey</material>
  </gazebo>
  <gazebo reference="r_Iproximal">
    <!-- <kp>1000000.0</kp>
      <kd>100.0</kd>
      <mu1>30.0</mu1>
      <mu2>30.0</mu2>
      <maxVel>1.0</maxVel>
      <minDepth>0.001</minDepth> -->
    <!-- <visual>
        <material>
          <ambient>0.74902 0.74902 0.74902 1.0</ambient>
          <diffuse>0.74902 0.74902 0.74902 1.0</diffuse>
          <specular>0.74902 0.74902 0.74902 1.0</specular>
        </material>
      </visual> -->
    <mu1>0.2</mu1>
    <mu2>0.2</mu2>
    <material>Gazebo/Grey</material>
  </gazebo>
  <gazebo reference="r_Imiddle">
    <!-- <kp>1000000.0</kp>
      <kd>100.0</kd>
      <mu1>30.0</mu1>
      <mu2>30.0</mu2>
      <maxVel>1.0</maxVel>
      <minDepth>0.001</minDepth> -->
    <!-- <visual>
        <material>
          <ambient>0.74902 0.74902 0.74902 1.0</ambient>
          <diffuse>0.74902 0.74902 0.74902 1.0</diffuse>
          <specular>0.74902 0.74902 0.74902 1.0</specular>
        </material>
      </visual> -->
    <mu1>0.2</mu1>
    <mu2>0.2</mu2>
    <material>Gazebo/Grey</material>
  </gazebo>
  <gazebo reference="r_Itip">
    <!-- <kp>1000000.0</kp>
      <kd>100.0</kd>
      <mu1>30.0</mu1>
      <mu2>30.0</mu2>
      <maxVel>1.0</maxVel>
      <minDepth>0.001</minDepth> -->
    <!-- <visual>
        <material>
          <ambient>0.74902 0.74902 0.74902 1.0</ambient>
          <diffuse>0.74902 0.74902 0.74902 1.0</diffuse>
          <specular>0.74902 0.74902 0.74902 1.0</specular>
        </material>
      </visual> -->
    <mu1>0.2</mu1>
    <mu2>0.2</mu2>
    <material>Gazebo/Grey</material>
  </gazebo>
  <!-- <gazebo>
    <pose>0.0 0.0 0.0 0.0 0.0 0.0</pose>
  </gazebo> -->
  <link name="l_forearm">
    <inertial>
      <origin rpy="0.02118572 0.0001173 0.00029319" xyz="-0.0000047 0.00267674 0.0805699"/>
      <mass value="0.77750886"/>
      <inertia ixx="0.00152273" ixy="0.00000005" ixz="0.00000010" iyy="0.00167456" iyz="-0.00002091" izz="0.00068825"/>
    </inertial>
    <visual>
      <origin rpy="0 0 0" xyz="0 0 0"/>
      <geometry>
        <mesh filename="/export/home/strahl/dev/gaikpy/resources/urdf/nicol/meshes/RH8D/forearm_refac.stl" scale="0.001 0.001 0.001"/>
      </geometry>
      <material name="rh8d_color"/>
    </visual>
    <collision>
      <origin rpy="0 0 0" xyz="0 0 0"/>
      <geometry>
        <mesh filename="/export/home/strahl/dev/gaikpy/resources/urdf/nicol/meshes/RH8D/forearm_refac.stl" scale="0.001 0.001 0.001"/>
      </geometry>
    </collision>
  </link>
  <joint name="l_joint7" type="revolute">
    <origin rpy="1.5707963267948966 0 0" xyz="0 0.005 0.18399997"/>
    <parent link="l_forearm"/>
    <child link="l_palm_axis"/>
    <axis xyz="0 0 1"/>
    <limit effort="0.5" lower="-0.785398163397" upper="0.785398163397" velocity="1.0"/>
    <dynamics damping="0.001"/>
  </joint>
  <transmission name="tranl_7">
    <type>transmission_interface/SimpleTransmission</type>
    <joint name="l_joint7">
      <hardwareInterface>hardware_interface/PositionJointInterface</hardwareInterface>
    </joint>
    <actuator name="motorl_7">
      <hardwareInterface>hardware_interface/PositionJointInterface</hardwareInterface>
      <mechanicalReduction>1</mechanicalReduction>
    </actuator>
  </transmission>
  <link name="l_palm_axis">
    <inertial>
      <origin rpy="0.00003493 0.00015844 0.00001195" xyz="0.00000165 -0.00903164 0.00000046"/>
      <mass value="0.04827394"/>
      <inertia ixx="0.00000933" ixy="0.0" ixz="0.0" iyy="0.00001216" iyz="0.0" izz="0.00001695"/>
    </inertial>
    <visual>
      <origin rpy="0 0 0" xyz="0 0 0"/>
      <geometry>
        <mesh filename="/export/home/strahl/dev/gaikpy/resources/urdf/nicol/meshes/RH8D/palm_axis_refac.stl" scale="0.001 0.001 0.001"/>
      </geometry>
      <material name="rh8d_color"/>
    </visual>
    <collision>
      <origin rpy="0 0 0" xyz="0 0 0"/>
      <geometry>
        <mesh filename="/export/home/strahl/dev/gaikpy/resources/urdf/nicol/meshes/RH8D/palm_axis_refac.stl" scale="0.001 0.001 0.001"/>
      </geometry>
    </collision>
  </link>
  <joint name="l_joint8" type="revolute">
    <origin rpy="0 1.5707963267948966 0" xyz="0 0 0"/>
    <parent link="l_palm_axis"/>
    <child link="l_palm"/>
    <axis xyz="0 0 1"/>
    <limit effort="0.5" lower="-0.785398163397" upper="0.785398163397" velocity="1.0"/>
    <dynamics damping="0.001"/>
  </joint>
  <transmission name="tranl_8">
    <type>transmission_interface/SimpleTransmission</type>
    <joint name="l_joint8">
      <hardwareInterface>hardware_interface/PositionJointInterface</hardwareInterface>
    </joint>
    <actuator name="motorl_8">
      <hardwareInterface>hardware_interface/PositionJointInterface</hardwareInterface>
      <mechanicalReduction>1</mechanicalReduction>
    </actuator>
  </transmission>
  <link name="l_palm">
    <inertial>
      <origin rpy="-0.62411573 0.01906502 0.07874822" xyz="-0.00707208 0.03032733 -0.02905062"/>
      <mass value="0.08867160"/>
      <inertia ixx="0.00010922" ixy="-0.00000616" ixz="-0.00000410" iyy="0.00004316" iyz="-0.00003750" izz="0.00006793"/>
    </inertial>
    <visual>
      <origin rpy="0 0 0" xyz="0 0 0"/>
      <geometry>
        <mesh filename="/export/home/strahl/dev/gaikpy/resources/urdf/nicol/meshes/RH8D/left_palm_refac.stl" scale="0.001 0.001 0.001"/>
      </geometry>
      <material name="rh8d_color"/>
    </visual>
    <collision>
      <origin rpy="0 0 0" xyz="0 0 0"/>
      <geometry>
        <mesh filename="/export/home/strahl/dev/gaikpy/resources/urdf/nicol/meshes/RH8D/left_palm_refac.stl" scale="0.001 0.001 0.001"/>
      </geometry>
    </collision>
  </link>
  <!-- tool0 for detailed end effector positioning on eef link (palm) -->
  <joint name="l_palm_to_l_tool0" type="fixed">
    <parent link="l_Rproximal"/>
    <child link="l_tool0"/>
  </joint>
  <link name="l_tool0"/>
  <joint name="l_jointT0" type="revolute">
    <origin rpy="0.53083205 -0.65672327 -2.69880256" xyz="-0.00852244 0.01530788 -0.03843229"/>
    <parent link="l_palm"/>
    <child link="l_thumb_base"/>
    <axis xyz="0 0 1"/>
    <limit effort="0.5" lower="0.0" upper="1.57079632679" velocity="1.0"/>
    <dynamics damping="0.0001"/>
  </joint>
  <transmission name="tranl_T0">
    <type>transmission_interface/SimpleTransmission</type>
    <joint name="l_jointT0">
      <hardwareInterface>hardware_interface/PositionJointInterface</hardwareInterface>
    </joint>
    <actuator name="motorl_T0">
      <hardwareInterface>hardware_interface/PositionJointInterface</hardwareInterface>
      <mechanicalReduction>1</mechanicalReduction>
    </actuator>
  </transmission>
  <link name="l_thumb_base">
    <inertial>
      <origin rpy="-0.00000341 -0.00000343 0.03167803" xyz="-0.00000008 0.00000194 0.02800943"/>
      <mass value="0.00705621"/>
      <inertia ixx="0.00000058" ixy="0" ixz="0" iyy="0.00000058" iyz="0" izz="0.00000005"/>
    </inertial>
    <visual>
      <origin rpy="0 0 0" xyz="0 0 0"/>
      <geometry>
        <mesh filename="/export/home/strahl/dev/gaikpy/resources/urdf/nicol/meshes/RH8D/thumb_base_refac.stl" scale="0.001 0.001 0.001"/>
      </geometry>
      <material name="rh8d_color"/>
    </visual>
    <collision>
      <origin rpy="0 0 0" xyz="0 0 0"/>
      <geometry>
        <mesh filename="/export/home/strahl/dev/gaikpy/resources/urdf/nicol/meshes/RH8D/thumb_base_refac.stl" scale="0.001 0.001 0.001"/>
      </geometry>
    </collision>
  </link>
  <joint name="l_jointT1" type="revolute">
    <origin rpy="1.57079633 -1.01753528 -1.57079633" xyz="0 -0.0111644427 0.005490292"/>
    <parent link="l_thumb_base"/>
    <child link="l_Tproximal"/>
    <axis xyz="0 0 1"/>
    <limit effort="0.5" lower="0.0" upper="1.57079632679" velocity="1.0"/>
    <dynamics damping="0.0001"/>
  </joint>
  <transmission name="tranl_T1">
    <type>transmission_interface/SimpleTransmission</type>
    <joint name="l_jointT1">
      <hardwareInterface>hardware_interface/PositionJointInterface</hardwareInterface>
    </joint>
    <actuator name="motorl_T1">
      <hardwareInterface>hardware_interface/PositionJointInterface</hardwareInterface>
      <mechanicalReduction>1</mechanicalReduction>
    </actuator>
  </transmission>
  <link name="l_Tproximal">
    <inertial>
      <origin rpy="0.00064474 0.00155280 0.04587687" xyz="-0.00009888 -0.00895693 0.00000242"/>
      <mass value=" 0.00382508"/>
      <inertia ixx="0.00000026" ixy="-0.00000001" ixz="0" iyy="0.00000013" iyz="0" izz="0.00000023"/>
    </inertial>
    <visual>
      <origin rpy="0 0 0" xyz="0 0 0"/>
      <geometry>
        <mesh filename="/export/home/strahl/dev/gaikpy/resources/urdf/nicol/meshes/RH8D/thumb_phalanx_refac.stl" scale="0.001 0.001 0.001"/>
      </geometry>
      <material name="rh8d_color"/>
    </visual>
    <collision>
      <origin rpy="0 0 0" xyz="0 0 0"/>
      <geometry>
        <mesh filename="/export/home/strahl/dev/gaikpy/resources/urdf/nicol/meshes/RH8D/thumb_phalanx_refac.stl" scale="0.001 0.001 0.001"/>
      </geometry>
    </collision>
  </link>
  <joint name="l_jointT2" type="revolute">
    <origin rpy="0 0 0" xyz="0 -0.0215859928 0"/>
    <parent link="l_Tproximal"/>
    <child link="l_Tmiddle"/>
    <axis xyz="0 0 1"/>
    <limit effort="0.5" lower="0.0" upper="1.57079632679" velocity="1.0"/>
    <dynamics damping="0.0001"/>
  </joint>
  <transmission name="tranl_T2">
    <type>transmission_interface/SimpleTransmission</type>
    <joint name="l_jointT2">
      <hardwareInterface>hardware_interface/PositionJointInterface</hardwareInterface>
    </joint>
    <actuator name="motorl_T2">
      <hardwareInterface>hardware_interface/PositionJointInterface</hardwareInterface>
      <mechanicalReduction>1</mechanicalReduction>
    </actuator>
  </transmission>
  <link name="l_Tmiddle">
    <inertial>
      <origin rpy="0.00064474 0.00155280 0.04587687" xyz="-0.00009888 -0.00895693 0.00000242"/>
      <mass value=" 0.00382508"/>
      <inertia ixx="0.00000026" ixy="-0.00000001" ixz="0" iyy="0.00000013" iyz="0" izz="0.00000023"/>
    </inertial>
    <visual>
      <origin rpy="0 0 0" xyz="0 0 0"/>
      <geometry>
        <mesh filename="/export/home/strahl/dev/gaikpy/resources/urdf/nicol/meshes/RH8D/thumb_phalanx_refac.stl" scale="0.001 0.001 0.001"/>
      </geometry>
      <material name="rh8d_color"/>
    </visual>
    <collision>
      <origin rpy="0 0 0" xyz="0 0 0"/>
      <geometry>
        <mesh filename="/export/home/strahl/dev/gaikpy/resources/urdf/nicol/meshes/RH8D/thumb_phalanx_refac.stl" scale="0.001 0.001 0.001"/>
      </geometry>
    </collision>
  </link>
  <joint name="l_jointT3" type="revolute">
    <origin rpy="0 0 0.078" xyz="0 -0.0215859928 0"/>
    <parent link="l_Tmiddle"/>
    <child link="l_Ttip"/>
    <axis xyz="0 0 1"/>
    <limit effort="0.5" lower="0.0" upper="1.57079632679" velocity="1.0"/>
    <dynamics damping="0.0001"/>
  </joint>
  <transmission name="tranl_T3">
    <type>transmission_interface/SimpleTransmission</type>
    <joint name="l_jointT3">
      <hardwareInterface>hardware_interface/PositionJointInterface</hardwareInterface>
    </joint>
    <actuator name="motorl_T3">
      <hardwareInterface>hardware_interface/PositionJointInterface</hardwareInterface>
      <mechanicalReduction>1</mechanicalReduction>
    </actuator>
  </transmission>
  <link name="l_Ttip">
    <inertial>
      <origin rpy="0.00105402 -0.00291363 -0.08777144" xyz="0.00064228 -0.01044102 0.00000295"/>
      <mass value="0.00475224"/>
      <inertia ixx="0.00000031" ixy="0.00000001" ixz="0" iyy="0.00000014" iyz="0" izz="0.00000029"/>
    </inertial>
    <visual>
      <origin rpy="0 0 0" xyz="0 0 0"/>
      <geometry>
        <mesh filename="/export/home/strahl/dev/gaikpy/resources/urdf/nicol/meshes/RH8D/tip_refac.stl" scale="0.001 0.001 0.001"/>
      </geometry>
      <material name="rh8d_color"/>
    </visual>
    <collision>
      <origin rpy="0 0 0" xyz="0 0 0"/>
      <geometry>
        <mesh filename="/export/home/strahl/dev/gaikpy/resources/urdf/nicol/meshes/RH8D/tip_refac.stl" scale="0.001 0.001 0.001"/>
      </geometry>
    </collision>
  </link>
  <joint name="l_jointI1" type="revolute">
    <origin rpy="0.07160374 -0.18146378 -2.87864878" xyz="-0.0043044918 0.0812907302 -0.0367863551"/>
    <parent link="l_palm"/>
    <child link="l_Iproximal"/>
    <axis xyz="0 0 1"/>
    <limit effort="0.5" lower="0.0" upper="1.4835298642" velocity="1.0"/>
    <dynamics damping="0.0001"/>
  </joint>
  <transmission name="tranl_I1">
    <type>transmission_interface/SimpleTransmission</type>
    <joint name="l_jointI1">
      <hardwareInterface>hardware_interface/PositionJointInterface</hardwareInterface>
    </joint>
    <actuator name="motorl_I1">
      <hardwareInterface>hardware_interface/PositionJointInterface</hardwareInterface>
      <mechanicalReduction>1</mechanicalReduction>
    </actuator>
  </transmission>
  <link name="l_Iproximal">
    <inertial>
      <origin rpy="0.00028099 0.00058278 0.03232242" xyz="-0.00009694 -0.01116046 0.00000050"/>
      <mass value="0.00475397"/>
      <inertia ixx="0.00000040" ixy="-0.00000001" ixz="0" iyy="0.00000016" iyz="0" izz="0.00000036"/>
    </inertial>
    <visual>
      <origin rpy="0 0 0" xyz="0 0 0"/>
      <geometry>
        <mesh filename="/export/home/strahl/dev/gaikpy/resources/urdf/nicol/meshes/RH8D/phalanx_refac.stl" scale="0.001 0.001 0.001"/>
      </geometry>
      <material name="rh8d_color"/>
    </visual>
    <collision>
      <origin rpy="0 0 0" xyz="0 0 0"/>
      <geometry>
        <mesh filename="/export/home/strahl/dev/gaikpy/resources/urdf/nicol/meshes/RH8D/phalanx_refac.stl" scale="0.001 0.001 0.001"/>
      </geometry>
    </collision>
  </link>
  <joint name="l_jointI2" type="revolute">
    <origin rpy="0 0 0" xyz="0 -0.0258749732 0"/>
    <parent link="l_Iproximal"/>
    <child link="l_Imiddle"/>
    <axis xyz="0 0 1"/>
    <limit effort="0.5" lower="0.0" upper="1.4835298642" velocity="1.0"/>
    <dynamics damping="0.0001"/>
  </joint>
  <transmission name="tranl_I2">
    <type>transmission_interface/SimpleTransmission</type>
    <joint name="l_jointI2">
      <hardwareInterface>hardware_interface/PositionJointInterface</hardwareInterface>
    </joint>
    <actuator name="motorl_I2">
      <hardwareInterface>hardware_interface/PositionJointInterface</hardwareInterface>
      <mechanicalReduction>1</mechanicalReduction>
    </actuator>
  </transmission>
  <link name="l_Imiddle">
    <inertial>
      <origin rpy="0.00028099 0.00058278 0.03232242" xyz="-0.00009694 -0.01116046 0.00000050"/>
      <mass value="0.00475397"/>
      <inertia ixx="0.00000040" ixy="-0.00000001" ixz="0" iyy="0.00000016" iyz="0" izz="0.00000036"/>
    </inertial>
    <visual>
      <origin rpy="0 0 0" xyz="0 0 0"/>
      <geometry>
        <mesh filename="/export/home/strahl/dev/gaikpy/resources/urdf/nicol/meshes/RH8D/phalanx_refac.stl" scale="0.001 0.001 0.001"/>
      </geometry>
      <material name="rh8d_color"/>
    </visual>
    <collision>
      <origin rpy="0 0 0" xyz="0 0 0"/>
      <geometry>
        <mesh filename="/export/home/strahl/dev/gaikpy/resources/urdf/nicol/meshes/RH8D/phalanx_refac.stl" scale="0.001 0.001 0.001"/>
      </geometry>
    </collision>
  </link>
  <joint name="l_jointI3" type="revolute">
    <origin rpy="0 0 0.078" xyz="0 -0.0258749732 0"/>
    <parent link="l_Imiddle"/>
    <child link="l_Itip"/>
    <axis xyz="0 0 1"/>
    <limit effort="0.5" lower="0.0" upper="1.4835298642" velocity="1.0"/>
    <dynamics damping="0.0001"/>
  </joint>
  <transmission name="tranl_I3">
    <type>transmission_interface/SimpleTransmission</type>
    <joint name="l_jointI3">
      <hardwareInterface>hardware_interface/PositionJointInterface</hardwareInterface>
    </joint>
    <actuator name="motorl_I3">
      <hardwareInterface>hardware_interface/PositionJointInterface</hardwareInterface>
      <mechanicalReduction>1</mechanicalReduction>
    </actuator>
  </transmission>
  <link name="l_Itip">
    <inertial>
      <origin rpy="0.00105402 -0.00291363 -0.08777144" xyz="0.00064228 -0.01044102 0.00000295"/>
      <mass value="0.00475224"/>
      <inertia ixx="0.00000031" ixy="0.00000001" ixz="0" iyy="0.00000014" iyz="0" izz="0.00000029"/>
    </inertial>
    <visual>
      <origin rpy="0 0 0" xyz="0 0 0"/>
      <geometry>
        <mesh filename="/export/home/strahl/dev/gaikpy/resources/urdf/nicol/meshes/RH8D/tip_refac.stl" scale="0.001 0.001 0.001"/>
      </geometry>
      <material name="rh8d_color"/>
    </visual>
    <collision>
      <origin rpy="0 0 0" xyz="0 0 0"/>
      <geometry>
        <mesh filename="/export/home/strahl/dev/gaikpy/resources/urdf/nicol/meshes/RH8D/tip_refac.stl" scale="0.001 0.001 0.001"/>
      </geometry>
    </collision>
  </link>
  <joint name="l_jointM1" type="revolute">
    <origin rpy="-0.00745321 -0.08694845 -2.88142599" xyz="-0.0012008743 0.0828960623 -0.0118294206"/>
    <parent link="l_palm"/>
    <child link="l_Mproximal"/>
    <axis xyz="0 0 1"/>
    <limit effort="0.5" lower="0.0" upper="1.4835298642" velocity="1.0"/>
    <dynamics damping="0.0001"/>
  </joint>
  <transmission name="tranl_M1">
    <type>transmission_interface/SimpleTransmission</type>
    <joint name="l_jointM1">
      <hardwareInterface>hardware_interface/PositionJointInterface</hardwareInterface>
    </joint>
    <actuator name="motorl_M1">
      <hardwareInterface>hardware_interface/PositionJointInterface</hardwareInterface>
      <mechanicalReduction>1</mechanicalReduction>
    </actuator>
  </transmission>
  <link name="l_Mproximal">
    <inertial>
      <origin rpy="0.00028099 0.00058278 0.03232242" xyz="-0.00009694 -0.01116046 0.00000050"/>
      <mass value="0.00475397"/>
      <inertia ixx="0.00000040" ixy="-0.00000001" ixz="0" iyy="0.00000016" iyz="0" izz="0.00000036"/>
    </inertial>
    <visual>
      <origin rpy="0 0 0" xyz="0 0 0"/>
      <geometry>
        <mesh filename="/export/home/strahl/dev/gaikpy/resources/urdf/nicol/meshes/RH8D/phalanx_refac.stl" scale="0.001 0.001 0.001"/>
      </geometry>
      <material name="rh8d_color"/>
    </visual>
    <collision>
      <origin rpy="0 0 0" xyz="0 0 0"/>
      <geometry>
        <mesh filename="/export/home/strahl/dev/gaikpy/resources/urdf/nicol/meshes/RH8D/phalanx_refac.stl" scale="0.001 0.001 0.001"/>
      </geometry>
    </collision>
  </link>
  <joint name="l_jointM2" type="revolute">
    <origin rpy="0 0 0" xyz="0 -0.0258749732 0"/>
    <parent link="l_Mproximal"/>
    <child link="l_Mmiddle"/>
    <axis xyz="0 0 1"/>
    <limit effort="0.5" lower="0.0" upper="1.4835298642" velocity="1.0"/>
    <dynamics damping="0.0001"/>
  </joint>
  <transmission name="tranl_M2">
    <type>transmission_interface/SimpleTransmission</type>
    <joint name="l_jointM2">
      <hardwareInterface>hardware_interface/PositionJointInterface</hardwareInterface>
    </joint>
    <actuator name="motorl_M2">
      <hardwareInterface>hardware_interface/PositionJointInterface</hardwareInterface>
      <mechanicalReduction>1</mechanicalReduction>
    </actuator>
  </transmission>
  <link name="l_Mmiddle">
    <inertial>
      <origin rpy="0.00028099 0.00058278 0.03232242" xyz="-0.00009694 -0.01116046 0.00000050"/>
      <mass value="0.00475397"/>
      <inertia ixx="0.00000040" ixy="-0.00000001" ixz="0" iyy="0.00000016" iyz="0" izz="0.00000036"/>
    </inertial>
    <visual>
      <origin rpy="0 0 0" xyz="0 0 0"/>
      <geometry>
        <mesh filename="/export/home/strahl/dev/gaikpy/resources/urdf/nicol/meshes/RH8D/phalanx_refac.stl" scale="0.001 0.001 0.001"/>
      </geometry>
      <material name="rh8d_color"/>
    </visual>
    <collision>
      <origin rpy="0 0 0" xyz="0 0 0"/>
      <geometry>
        <mesh filename="/export/home/strahl/dev/gaikpy/resources/urdf/nicol/meshes/RH8D/phalanx_refac.stl" scale="0.001 0.001 0.001"/>
      </geometry>
    </collision>
  </link>
  <joint name="l_jointM3" type="revolute">
    <origin rpy="0 0 0.078" xyz="0 -0.0258749732 0"/>
    <parent link="l_Mmiddle"/>
    <child link="l_Mtip"/>
    <axis xyz="0 0 1"/>
    <limit effort="0.5" lower="0.0" upper="1.4835298642" velocity="1.0"/>
    <dynamics damping="0.0001"/>
  </joint>
  <transmission name="tranl_M3">
    <type>transmission_interface/SimpleTransmission</type>
    <joint name="l_jointM3">
      <hardwareInterface>hardware_interface/PositionJointInterface</hardwareInterface>
    </joint>
    <actuator name="motorl_M3">
      <hardwareInterface>hardware_interface/PositionJointInterface</hardwareInterface>
      <mechanicalReduction>1</mechanicalReduction>
    </actuator>
  </transmission>
  <link name="l_Mtip">
    <inertial>
      <origin rpy="-0.00040647 0.00277016 -0.02374342" xyz="0.00057513 -0.00890735 -0.00000417"/>
      <mass value="0.00325960"/>
      <inertia ixx="0.00000021" ixy="0" ixz="0" iyy="0.00000009" iyz="0" izz="0.00000019"/>
    </inertial>
    <visual>
      <origin rpy="0 0 0" xyz="0 0 0"/>
      <geometry>
        <mesh filename="/export/home/strahl/dev/gaikpy/resources/urdf/nicol/meshes/RH8D/optoforce_refac.stl" scale="0.001 0.001 0.001"/>
      </geometry>
      <material name="rh8d_color"/>
    </visual>
    <collision>
      <origin rpy="0 0 0" xyz="0 0 0"/>
      <geometry>
        <mesh filename="/export/home/strahl/dev/gaikpy/resources/urdf/nicol/meshes/RH8D/optoforce_refac.stl" scale="0.001 0.001 0.001"/>
      </geometry>
    </collision>
  </link>
  <joint name="l_jointR1" type="revolute">
    <origin rpy="-0.0798369 0.09241357 -2.88345893" xyz="-0.0011171786 0.0818708881 0.0130285291"/>
    <parent link="l_palm"/>
    <child link="l_Rproximal"/>
    <axis xyz="0 0 1"/>
    <limit effort="0.5" lower="0.0" upper="1.4835298642" velocity="1.0"/>
    <dynamics damping="0.0001"/>
  </joint>
  <transmission name="tranl_R1">
    <type>transmission_interface/SimpleTransmission</type>
    <joint name="l_jointR1">
      <hardwareInterface>hardware_interface/PositionJointInterface</hardwareInterface>
    </joint>
    <actuator name="motorl_R1">
      <hardwareInterface>hardware_interface/PositionJointInterface</hardwareInterface>
      <mechanicalReduction>1</mechanicalReduction>
    </actuator>
  </transmission>
  <link name="l_Rproximal">
    <inertial>
      <origin rpy="0.00028099 0.00058278 0.03232242" xyz="-0.00009694 -0.01116046 0.00000050"/>
      <mass value="0.00475397"/>
      <inertia ixx="0.00000040" ixy="-0.00000001" ixz="0" iyy="0.00000016" iyz="0" izz="0.00000036"/>
    </inertial>
    <visual>
      <origin rpy="0 0 0" xyz="0 0 0"/>
      <geometry>
        <mesh filename="/export/home/strahl/dev/gaikpy/resources/urdf/nicol/meshes/RH8D/phalanx_refac.stl" scale="0.001 0.001 0.001"/>
      </geometry>
      <material name="rh8d_color"/>
    </visual>
    <collision>
      <origin rpy="0 0 0" xyz="0 0 0"/>
      <geometry>
        <mesh filename="/export/home/strahl/dev/gaikpy/resources/urdf/nicol/meshes/RH8D/phalanx_refac.stl" scale="0.001 0.001 0.001"/>
      </geometry>
    </collision>
  </link>
  <joint name="l_jointR2" type="revolute">
    <origin rpy="0 0 0" xyz="0 -0.0258749732 0"/>
    <parent link="l_Rproximal"/>
    <child link="l_Rmiddle"/>
    <axis xyz="0 0 1"/>
    <limit effort="0.5" lower="0.0" upper="1.4835298642" velocity="1.0"/>
    <dynamics damping="0.0001"/>
  </joint>
  <transmission name="tranl_R2">
    <type>transmission_interface/SimpleTransmission</type>
    <joint name="l_jointR2">
      <hardwareInterface>hardware_interface/PositionJointInterface</hardwareInterface>
    </joint>
    <actuator name="motorl_R2">
      <hardwareInterface>hardware_interface/PositionJointInterface</hardwareInterface>
      <mechanicalReduction>1</mechanicalReduction>
    </actuator>
  </transmission>
  <link name="l_Rmiddle">
    <inertial>
      <origin rpy="0.00028099 0.00058278 0.03232242" xyz="-0.00009694 -0.01116046 0.00000050"/>
      <mass value="0.00475397"/>
      <inertia ixx="0.00000040" ixy="-0.00000001" ixz="0" iyy="0.00000016" iyz="0" izz="0.00000036"/>
    </inertial>
    <visual>
      <origin rpy="0 0 0" xyz="0 0 0"/>
      <geometry>
        <mesh filename="/export/home/strahl/dev/gaikpy/resources/urdf/nicol/meshes/RH8D/phalanx_refac.stl" scale="0.001 0.001 0.001"/>
      </geometry>
      <material name="rh8d_color"/>
    </visual>
    <collision>
      <origin rpy="0 0 0" xyz="0 0 0"/>
      <geometry>
        <mesh filename="/export/home/strahl/dev/gaikpy/resources/urdf/nicol/meshes/RH8D/phalanx_refac.stl" scale="0.001 0.001 0.001"/>
      </geometry>
    </collision>
  </link>
  <joint name="l_jointR3" type="revolute">
    <origin rpy="0 0 0.078" xyz="0 -0.0258749732 0"/>
    <parent link="l_Rmiddle"/>
    <child link="l_Rtip"/>
    <axis xyz="0 0 1"/>
    <limit effort="0.5" lower="0.0" upper="1.4835298642" velocity="1.0"/>
    <dynamics damping="0.0001"/>
  </joint>
  <transmission name="tranl_R3">
    <type>transmission_interface/SimpleTransmission</type>
    <joint name="l_jointR3">
      <hardwareInterface>hardware_interface/PositionJointInterface</hardwareInterface>
    </joint>
    <actuator name="motorl_R3">
      <hardwareInterface>hardware_interface/PositionJointInterface</hardwareInterface>
      <mechanicalReduction>1</mechanicalReduction>
    </actuator>
  </transmission>
  <link name="l_Rtip">
    <inertial>
      <origin rpy="0.00105402 -0.00291363 -0.08777144" xyz="0.00064228 -0.01044102 0.00000295"/>
      <mass value="0.00475224"/>
      <inertia ixx="0.00000031" ixy="0.00000001" ixz="0" iyy="0.00000014" iyz="0" izz="0.00000029"/>
    </inertial>
    <visual>
      <origin rpy="0 0 0" xyz="0 0 0"/>
      <geometry>
        <mesh filename="/export/home/strahl/dev/gaikpy/resources/urdf/nicol/meshes/RH8D/tip_refac.stl" scale="0.001 0.001 0.001"/>
      </geometry>
      <material name="rh8d_color"/>
    </visual>
    <collision>
      <origin rpy="0 0 0" xyz="0 0 0"/>
      <geometry>
        <mesh filename="/export/home/strahl/dev/gaikpy/resources/urdf/nicol/meshes/RH8D/tip_refac.stl" scale="0.001 0.001 0.001"/>
      </geometry>
    </collision>
  </link>
  <joint name="l_jointL1" type="revolute">
    <origin rpy="-0.1572281 0.19023965 -2.87172735" xyz="-0.0031705239 0.0731417977 0.0376310382"/>
    <parent link="l_palm"/>
    <child link="l_Lproximal"/>
    <axis xyz="0 0 1"/>
    <limit effort="0.5" lower="0.0" upper="1.4835298642" velocity="1.0"/>
    <dynamics damping="0.0001"/>
  </joint>
  <transmission name="tranl_L1">
    <type>transmission_interface/SimpleTransmission</type>
    <joint name="l_jointL1">
      <hardwareInterface>hardware_interface/PositionJointInterface</hardwareInterface>
    </joint>
    <actuator name="motorl_L1">
      <hardwareInterface>hardware_interface/PositionJointInterface</hardwareInterface>
      <mechanicalReduction>1</mechanicalReduction>
    </actuator>
  </transmission>
  <link name="l_Lproximal">
    <inertial>
      <origin rpy="0.00028099 0.00058278 0.03232242" xyz="-0.00009694 -0.01116046 0.00000050"/>
      <mass value="0.00475397"/>
      <inertia ixx="0.00000040" ixy="-0.00000001" ixz="0" iyy="0.00000016" iyz="0" izz="0.00000036"/>
    </inertial>
    <visual>
      <origin rpy="0 0 0" xyz="0 0 0"/>
      <geometry>
        <mesh filename="/export/home/strahl/dev/gaikpy/resources/urdf/nicol/meshes/RH8D/phalanx_refac.stl" scale="0.001 0.001 0.001"/>
      </geometry>
      <material name="rh8d_color"/>
    </visual>
    <collision>
      <origin rpy="0 0 0" xyz="0 0 0"/>
      <geometry>
        <mesh filename="/export/home/strahl/dev/gaikpy/resources/urdf/nicol/meshes/RH8D/phalanx_refac.stl" scale="0.001 0.001 0.001"/>
      </geometry>
    </collision>
  </link>
  <joint name="l_jointL2" type="revolute">
    <origin rpy="0 0 0" xyz="0 -0.0258749732 0"/>
    <parent link="l_Lproximal"/>
    <child link="l_Lmiddle"/>
    <axis xyz="0 0 1"/>
    <limit effort="0.5" lower="0.0" upper="1.4835298642" velocity="1.0"/>
    <dynamics damping="0.0001"/>
  </joint>
  <transmission name="tranl_L2">
    <type>transmission_interface/SimpleTransmission</type>
    <joint name="l_jointL2">
      <hardwareInterface>hardware_interface/PositionJointInterface</hardwareInterface>
    </joint>
    <actuator name="motorl_L2">
      <hardwareInterface>hardware_interface/PositionJointInterface</hardwareInterface>
      <mechanicalReduction>1</mechanicalReduction>
    </actuator>
  </transmission>
  <link name="l_Lmiddle">
    <inertial>
      <origin rpy="0.00028099 0.00058278 0.03232242" xyz="-0.00009694 -0.01116046 0.00000050"/>
      <mass value="0.00475397"/>
      <inertia ixx="0.00000040" ixy="-0.00000001" ixz="0" iyy="0.00000016" iyz="0" izz="0.00000036"/>
    </inertial>
    <visual>
      <origin rpy="0 0 0" xyz="0 0 0"/>
      <geometry>
        <mesh filename="/export/home/strahl/dev/gaikpy/resources/urdf/nicol/meshes/RH8D/phalanx_refac.stl" scale="0.001 0.001 0.001"/>
      </geometry>
      <material name="rh8d_color"/>
    </visual>
    <collision>
      <origin rpy="0 0 0" xyz="0 0 0"/>
      <geometry>
        <mesh filename="/export/home/strahl/dev/gaikpy/resources/urdf/nicol/meshes/RH8D/phalanx_refac.stl" scale="0.001 0.001 0.001"/>
      </geometry>
    </collision>
  </link>
  <joint name="l_jointL3" type="revolute">
    <origin rpy="0 0 0.078" xyz="0 -0.0258749732 0"/>
    <parent link="l_Lmiddle"/>
    <child link="l_Ltip"/>
    <axis xyz="0 0 1"/>
    <limit effort="0.5" lower="0.0" upper="1.4835298642" velocity="1.0"/>
    <dynamics damping="0.0001"/>
  </joint>
  <transmission name="tranl_L3">
    <type>transmission_interface/SimpleTransmission</type>
    <joint name="l_jointL3">
      <hardwareInterface>hardware_interface/PositionJointInterface</hardwareInterface>
    </joint>
    <actuator name="motorl_L3">
      <hardwareInterface>hardware_interface/PositionJointInterface</hardwareInterface>
      <mechanicalReduction>1</mechanicalReduction>
    </actuator>
  </transmission>
  <link name="l_Ltip">
    <inertial>
      <origin rpy="0.00105402 -0.00291363 -0.08777144" xyz="0.00064228 -0.01044102 0.00000295"/>
      <mass value="0.00475224"/>
      <inertia ixx="0.00000031" ixy="0.00000001" ixz="0" iyy="0.00000014" iyz="0" izz="0.00000029"/>
    </inertial>
    <visual>
      <origin rpy="0 0 0" xyz="0 0 0"/>
      <geometry>
        <mesh filename="/export/home/strahl/dev/gaikpy/resources/urdf/nicol/meshes/RH8D/tip_refac.stl" scale="0.001 0.001 0.001"/>
      </geometry>
      <material name="rh8d_color"/>
    </visual>
    <collision>
      <origin rpy="0 0 0" xyz="0 0 0"/>
      <geometry>
        <mesh filename="/export/home/strahl/dev/gaikpy/resources/urdf/nicol/meshes/RH8D/tip_refac.stl" scale="0.001 0.001 0.001"/>
      </geometry>
    </collision>
  </link>
  <!-- link 1 -->
  <link name="l_link1">
    <collision>
      <!-- simplify collision to box -->
      <origin rpy="0 0 0" xyz="0 0 0.055"/>
      <geometry>
        <!-- <mesh filename="${omp_stl_path}link_1_reduced.stl" scale="0.001 0.001 0.001"/> -->
        <box size="0.055 0.055 0.13"/>
      </geometry>
    </collision>
    <visual>
      <origin rpy="0 0 0" xyz="0 0 0"/>
      <geometry>
        <mesh filename="/export/home/strahl/dev/gaikpy/resources/urdf/nicol/meshes/open_manipulator/link_1_reduced.stl" scale="0.001 0.001 0.001"/>
      </geometry>
      <material name="grey"/>
    </visual>
    <inertial>
      <origin rpy="0 0 0" xyz="0.000001 0 0.060920"/>
      <mass value="0.902296"/>
      <inertia ixx="0.001343" ixy="0" ixz="0" iyy="0.001345" iyz="0" izz="0.000397"/>
    </inertial>
  </link>
  <!-- Joint 1 -->
  <joint name="l_joint1" type="revolute">
    <parent link="l_link1"/>
    <child link="l_link2"/>
    <origin rpy="0 0 1.5707963267948966" xyz="0.0 0.0 0.126"/>
    <axis xyz="0 0 1"/>
    <limit effort="1000" lower="-3.141592653589793" upper="0.0" velocity="6.5"/>
    <dynamics damping="0.1" friction="0.0"/>
    <!-- <safety_controller k_velocity="10" k_position="15" soft_lower_limit="-2.0" soft_upper_limit="0.5" /> -->
  </joint>
  <transmission name="tranl_1">
    <type>transmission_interface/SimpleTransmission</type>
    <joint name="l_joint1">
      <hardwareInterface>hardware_interface/PositionJointInterface</hardwareInterface>
    </joint>
    <actuator name="motorl_1">
      <hardwareInterface>hardware_interface/PositionJointInterface</hardwareInterface>
      <mechanicalReduction>1</mechanicalReduction>
    </actuator>
  </transmission>
  <!-- link 2 -->
  <link name="l_link2">
    <collision>
      <!-- simplify collision to box -->
      <origin rpy="0 0 0" xyz="0 -0.002 0.033"/>
      <geometry>
        <!-- <mesh filename="${omp_stl_path}link_2_reduced.stl" scale="0.001 0.001 0.001"/> -->
        <box size="0.055 0.1325 0.055"/>
      </geometry>
    </collision>
    <visual>
      <origin rpy="0 0 0" xyz="0 0 0"/>
      <geometry>
        <mesh filename="/export/home/strahl/dev/gaikpy/resources/urdf/nicol/meshes/open_manipulator/link_2_reduced.stl" scale="0.001 0.001 0.001"/>
      </geometry>
      <material name="grey"/>
    </visual>
    <inertial>
      <origin rpy="0 0 0" xyz="0 0.000436 0.032021"/>
      <mass value="0.985121"/>
      <inertia ixx="0.001611" ixy="0" ixz="0" iyy="0.000473" iyz="0" izz="0.001599"/>
    </inertial>
  </link>
  <!-- Joint 2 -->
  <joint name="l_joint2" type="revolute">
    <parent link="l_link2"/>
    <child link="l_link3"/>
    <origin rpy="0 0 0" xyz="0.0 0.069 0.033"/>
    <axis xyz="0 1 0"/>
    <limit effort="1000" lower="-1.5707963267948966" upper="1.5707963267948966" velocity="6.5"/>
    <dynamics damping="0.1" friction="0.0"/>
  </joint>
  <transmission name="tranl_2">
    <type>transmission_interface/SimpleTransmission</type>
    <joint name="l_joint2">
      <hardwareInterface>hardware_interface/PositionJointInterface</hardwareInterface>
    </joint>
    <actuator name="motorl_2">
      <hardwareInterface>hardware_interface/PositionJointInterface</hardwareInterface>
      <mechanicalReduction>1</mechanicalReduction>
    </actuator>
  </transmission>
  <!-- link 3 -->
  <link name="l_link3">
    <collision>
      <origin rpy="0 0 0" xyz="0 0 0"/>
      <geometry>
        <mesh filename="/export/home/strahl/dev/gaikpy/resources/urdf/nicol/meshes/open_manipulator/link_3_reduced.stl" scale="0.001 0.001 0.001"/>
      </geometry>
    </collision>
    <visual>
      <origin rpy="0 0 0" xyz="0 0 0"/>
      <geometry>
        <mesh filename="/export/home/strahl/dev/gaikpy/resources/urdf/nicol/meshes/open_manipulator/link_3_reduced.stl" scale="0.001 0.001 0.001"/>
      </geometry>
      <material name="grey"/>
    </visual>
    <inertial>
      <origin rpy="-0.011848 -0.133044 0.017678" xyz="0.015706 -0.070340 0.199125"/>
      <mass value="1.501407"/>
      <inertia ixx="0.013723" ixy="-0.000001" ixz="-0.001527" iyy="0.012824" iyz="0.000125" izz="0.002524"/>
    </inertial>
  </link>
  <!-- Joint 3 -->
  <joint name="l_joint3" type="revolute">
    <parent link="l_link3"/>
    <child link="l_link4"/>
    <origin rpy="0 0 0" xyz="0.03000 -0.01150 0.26400"/>
    <axis xyz="0 1 0"/>
    <limit effort="1000" lower="-1.5707963267948966" upper="1.5707963267948966" velocity="6.5"/>
    <dynamics damping="0.1" friction="0.0"/>
  </joint>
  <transmission name="tranl_3">
    <type>transmission_interface/SimpleTransmission</type>
    <joint name="l_joint3">
      <hardwareInterface>hardware_interface/PositionJointInterface</hardwareInterface>
    </joint>
    <actuator name="motorl_3">
      <hardwareInterface>hardware_interface/PositionJointInterface</hardwareInterface>
      <mechanicalReduction>1</mechanicalReduction>
    </actuator>
  </transmission>
  <!-- link 4 -->
  <link name="l_link4">
    <collision>
      <origin rpy="0 0 0" xyz="0 0 0"/>
      <geometry>
        <mesh filename="/export/home/strahl/dev/gaikpy/resources/urdf/nicol/meshes/open_manipulator/link_4_reduced.stl" scale="0.001 0.001 0.001"/>
      </geometry>
    </collision>
    <visual>
      <origin rpy="0 0 0" xyz="0 0 0"/>
      <geometry>
        <mesh filename="/export/home/strahl/dev/gaikpy/resources/urdf/nicol/meshes/open_manipulator/link_4_reduced.stl" scale="0.001 0.001 0.001"/>
      </geometry>
      <material name="grey"/>
    </visual>
    <inertial>
      <origin rpy="0.002216 0.017493 0.001153" xyz="0.120352 -0.057519 0.029683"/>
      <mass value="1.330903"/>
      <inertia ixx="0.001287" ixy="0.000003" ixz="-0.000060" iyy="0.004298" iyz="0.000001" izz="0.004730"/>
    </inertial>
  </link>
  <!-- Joint 4 -->
  <joint name="l_joint4" type="revolute">
    <parent link="l_link4"/>
    <child link="l_link5"/>
    <origin rpy="0 0 0" xyz="0.19500 -0.05750 0.03000"/>
    <axis xyz="1 0 0"/>
    <limit effort="1000" lower="-1.5707963267948966" upper="1.5707963267948966" velocity="6.5"/>
    <dynamics damping="0.1" friction="0.0"/>
  </joint>
  <transmission name="tranl_4">
    <type>transmission_interface/SimpleTransmission</type>
    <joint name="l_joint4">
      <hardwareInterface>hardware_interface/PositionJointInterface</hardwareInterface>
    </joint>
    <actuator name="motorl_4">
      <hardwareInterface>hardware_interface/PositionJointInterface</hardwareInterface>
      <mechanicalReduction>1</mechanicalReduction>
    </actuator>
  </transmission>
  <!-- link 5 -->
  <link name="l_link5">
    <collision>
      <!-- simplify collision to box -->
      <origin rpy="0 0 0" xyz="0.061 0 0"/>
      <geometry>
        <!-- <mesh filename="${omp_stl_path}link_5_reduced.stl" scale="0.001 0.001 0.001"/> -->
        <box size="0.047 0.086 0.05"/>
      </geometry>
    </collision>
    <visual>
      <origin rpy="0 0 0" xyz="0 0 0"/>
      <geometry>
        <mesh filename="/export/home/strahl/dev/gaikpy/resources/urdf/nicol/meshes/open_manipulator/link_5_reduced.stl" scale="0.001 0.001 0.001"/>
      </geometry>
      <material name="grey"/>
    </visual>
    <inertial>
      <origin rpy="-0.000001 0 -0.002436" xyz="0.057143 -0.002069 0"/>
      <mass value="0.449696"/>
      <inertia ixx="0.000306" ixy="0" ixz="0" iyy="0.000212" iyz="0" izz="0.000390"/>
    </inertial>
  </link>
  <!-- Joint 5 -->
  <joint name="l_joint5" type="revolute">
    <parent link="l_link5"/>
    <child link="l_link6"/>
    <origin rpy="0 0 0" xyz="0.06300 0.04500 0.00000"/>
    <axis xyz="0 1 0"/>
    <limit effort="1000" lower="-1.5707963267948966" upper="1.5707963267948966" velocity="6.5"/>
    <dynamics damping="0.01" friction="0.0"/>
  </joint>
  <transmission name="tranl_5">
    <type>transmission_interface/SimpleTransmission</type>
    <joint name="l_joint5">
      <hardwareInterface>hardware_interface/PositionJointInterface</hardwareInterface>
    </joint>
    <actuator name="motorl_5">
      <hardwareInterface>hardware_interface/PositionJointInterface</hardwareInterface>
      <mechanicalReduction>1</mechanicalReduction>
    </actuator>
  </transmission>
  <!-- link 6 -->
  <link name="l_link6">
    <collision>
      <origin rpy="0 0 0" xyz="0 0 0"/>
      <geometry>
        <mesh filename="/export/home/strahl/dev/gaikpy/resources/urdf/nicol/meshes/open_manipulator/link_6_reduced.stl" scale="0.001 0.001 0.001"/>
      </geometry>
    </collision>
    <visual>
      <origin rpy="0 0 0" xyz="0 0 0"/>
      <geometry>
        <mesh filename="/export/home/strahl/dev/gaikpy/resources/urdf/nicol/meshes/open_manipulator/link_6_reduced.stl" scale="0.001 0.001 0.001"/>
      </geometry>
      <material name="grey"/>
    </visual>
    <inertial>
      <origin rpy="0 -0.000491 -0.002812" xyz="0.068686 -0.044988 -0.000034"/>
      <mass value="0.444892"/>
      <inertia ixx="0.000215" ixy="-0.000001" ixz="0" iyy="0.000443" iyz="0" izz="0.000529"/>
    </inertial>
  </link>
  <!-- Joint 6 connects to hand base-->
  <joint name="l_joint6" type="revolute">
    <parent link="l_link6"/>
    <child link="l_forearm"/>
    <origin rpy="1.5707963267948966 0 1.5707963267948966" xyz="0.12300 -0.04500 0.00000"/>
    <axis xyz="0 0 1"/>
    <limit effort="1000" lower="-1.5707963267948966" upper="1.5707963267948966" velocity="6.5"/>
    <dynamics damping="0.01" friction="0.0"/>
  </joint>
  <transmission name="tranl_6">
    <type>transmission_interface/SimpleTransmission</type>
    <joint name="l_joint6">
      <hardwareInterface>hardware_interface/PositionJointInterface</hardwareInterface>
    </joint>
    <actuator name="motorl_6">
      <hardwareInterface>hardware_interface/PositionJointInterface</hardwareInterface>
      <mechanicalReduction>1</mechanicalReduction>
    </actuator>
  </transmission>
  <!-- Append right open_manipulator_p to robot_frame -->
  <joint name="r_base_joint" type="fixed">
    <origin rpy="1.5707963267948966 0 0" xyz="-0.027 -0.0605 1.173"/>
    <parent link="world"/>
    <child link="r_link1"/>
  </joint>
  <!-- Append left open_manipulator_p to robot_frame -->
  <joint name="l_base_joint" type="fixed">
    <origin rpy="-1.5707963267948966 0 0" xyz="-0.027 0.0605 1.173"/>
    <parent link="world"/>
    <child link="l_link1"/>
  </joint>
</robot>

