<?xml version="1.0" encoding="utf-8"?>
<!-- =================================================================================== -->
<!-- |    This document was autogenerated by xacro from export_NICOL_to_urdf.xacro     | -->
<!-- |    EDITING THIS FILE BY HAND IS NOT RECOMMENDED                                 | -->
<!-- =================================================================================== -->
<!-- ############################################## -->
<!-- Use only to export NICOL to a single urdf file -->
<!-- ############################################## -->
<robot name="NICOL">
  <!-- ################################ NOT IN USE ############################################ -->
  <!-- ############################ macro for the long horizontal sections ############################### -->
  <!-- ############################ macro for the short horizontal sections ############################### -->
  <!-- Frame materials -->
  <material name="profile">
    <color rgba="0.5 0.5 0.5 2.0"/>
  </material>
  <material name="plate">
    <color rgba="0.5 0.5 0.5 1.8"/>
  </material>
  <material name="grey">
    <color rgba="0.2 0.2 0.2 2.0"/>
  </material>
  <material name="silver">
    <color rgba="0.8 0.8 0.8 1.0"/>
  </material>
  <material name="dark_white">
    <color rgba="0.9 0.9 0.9 1.0"/>
  </material>
  <!-- Gazebo -->
  <material name="black">
    <color rgba="0.0 0.0 0.0 1.0"/>
  </material>
  <material name="blue">
    <color rgba="0.0 0.0 0.8 1.0"/>
  </material>
  <material name="green">
    <color rgba="0.0 0.8 0.0 1.0"/>
  </material>
  <material name="deep_grey">
    <color rgba="0.5 0.5 0.5 1.0"/>
  </material>
  <material name="orange">
    <color rgba="1.0 0.423529411765 0.0392156862745 1.0"/>
  </material>
  <material name="brown">
    <color rgba="0.870588235294 0.811764705882 0.764705882353 1.0"/>
  </material>
  <material name="red">
    <color rgba="0.8 0.0 0.0 1.0"/>
  </material>
  <material name="white">
    <color rgba="1.0 1.0 1.0 1.0"/>
  </material>
  <!-- World, center of global coordinate system-->
  <link name="world">
  </link>
  <!-- origin at center of manipulator socket -->
  <joint name="base_joint" type="fixed">
    <parent link="world"/>
    <child link="base_link"/>
    <origin xyz="0 0 0.8"/>
  </joint>
  <!-- robot frame origin at back upper center of plate -->
  <joint name="frame_joint" type="fixed">
    <parent link="world"/>
    <child link="frame_link"/>
    <origin xyz="0 0 0.8"/>
  </joint>
  <!-- visual robot frame working plate -->
  <joint name="plate_joint" type="fixed">
    <parent link="frame_link"/>
    <child link="plate_link"/>
    <origin xyz="0.5 0 0.0001"/>
  </joint>
  <!-- camera holder joint -->
  <joint name="camera_holder_joint" type="fixed">
    <parent link="world"/>
    <child link="camera_holder_link"/>
    <origin rpy="0 3.14159265359 0" xyz="0.36 0 1.955"/>
  </joint>
  <!-- camera joint -->
  <joint name="camera_joint" type="fixed">
    <parent link="world"/>
    <child link="camera_link"/>
    <origin rpy="0 3.14159265359 1.57079632679" xyz="0.33 0 1.91"/>
  </joint>
  <!-- the camera (simulated in Gazebo config) -->
  <link name="camera_link">
    <visual>
      <origin rpy="0 0 0" xyz="0 0 0"/>
      <geometry>
        <mesh filename="/export/home/strahl/dev/gaikpy/resources/urdf/nicol/meshes/camera/Intel_RealSense_Depth_Camera_D435.stl" scale="0.01 0.01 0.01"/>
      </geometry>
      <material name="profile"/>
    </visual>
    <collision>
      <origin rpy="0 0 0" xyz="0 0 0"/>
      <geometry>
        <mesh filename="/export/home/strahl/dev/gaikpy/resources/urdf/nicol/meshes/camera/Intel_RealSense_Depth_Camera_D435.stl" scale="0.01 0.01 0.01"/>
      </geometry>
    </collision>
    <inertial>
      <origin rpy="-0.07609636 -0.007504916 0.00122173" xyz="0.002 0 -0.013"/>
      <mass value="0.054"/>
      <inertia ixx="5.226e-06" ixy="1.9e-08" ixz="2.29e-07" iyy="3.5428e-05" iyz="1.9e-08" izz="3.5183e-05"/>
    </inertial>
  </link>
  <!-- the camera holder -->
  <link name="camera_holder_link">
    <visual>
      <origin rpy="0 0 0" xyz="0 0 0"/>
      <geometry>
        <mesh filename="/export/home/strahl/dev/gaikpy/resources/urdf/nicol/meshes/robot_frame/camera_holder_centered.stl" scale="0.01 0.01 0.01"/>
      </geometry>
      <material name="silver"/>
    </visual>
    <collision>
      <origin rpy="0 0 0" xyz="0 0 0"/>
      <geometry>
        <mesh filename="/export/home/strahl/dev/gaikpy/resources/urdf/nicol/meshes/robot_frame/camera_holder_centered.stl" scale="0.01 0.01 0.01"/>
      </geometry>
    </collision>
    <inertial>
      <origin rpy="0 0.7824311 0" xyz="0.01 0 0.01"/>
      <mass value="0.360"/>
      <inertia ixx="7.521032e-03" ixy="0.0" ixz="-4.2999999999999995e-08" iyy="2.5991e-05" iyz="0.0" izz="7.521032e-03"/>
    </inertial>
  </link>
  <!-- the robot frame -->
  <link name="frame_link">
    <visual>
      <origin rpy="0 0 0" xyz="0 0 0"/>
      <geometry>
        <mesh filename="/export/home/strahl/dev/gaikpy/resources/urdf/nicol/meshes/robot_frame/robot_frame_without_holder_centered.stl" scale="0.01 0.01 0.01"/>
      </geometry>
      <material name="silver"/>
    </visual>
    <collision>
      <origin rpy="0 0 0" xyz="0 0 0"/>
      <geometry>
        <mesh filename="/export/home/strahl/dev/gaikpy/resources/urdf/nicol/meshes/robot_frame/robot_frame_without_holder_centered_collision_geom.stl" scale="0.01 0.01 0.01"/>
      </geometry>
    </collision>
    <inertial>
      <origin rpy="0.16 -0.00034906585 0.0" xyz="0.5 0.0 0.122"/>
      <mass value="192.828"/>
      <inertia ixx="1.80424173437e02" ixy="-3.670789e-03" ixz="-2.197721e-02" iyy="1.14244360904e02" iyz="7.8251517e-02" izz="1.22561195992e02"/>
    </inertial>
  </link>
  <!-- the visual working plate -->
  <link name="plate_link">
    <visual>
      <origin rpy="0 0 0" xyz="0 0 0"/>
      <geometry>
        <box size="1 2 0.0002"/>
      </geometry>
      <material name="white"/>
    </visual>
    <collision>
      <origin rpy="0 0 0" xyz="0 0 0"/>
      <geometry>
        <box size="1 2 0.0002"/>
      </geometry>
    </collision>
    <inertial>
      <origin rpy="0 0 0" xyz="0 0 0"/>
      <mass value="0"/>
      <inertia ixx="1.0" ixy="0.0" ixz="0.0" iyy="1.0" iyz="0.0" izz="1.0"/>
    </inertial>
  </link>
  <!-- the holder  -->
  <link name="base_link">
    <visual>
      <origin rpy="0 0 0" xyz="0 0 0"/>
      <geometry>
        <mesh filename="/export/home/strahl/dev/gaikpy/resources/urdf/nicol/meshes/robot_frame/single_profile_45mm_holder_with_socket_centered.stl" scale="0.01 0.01 0.01"/>
      </geometry>
      <material name="silver"/>
    </visual>
    <collision>
      <origin rpy="0 0 0" xyz="0 0 0"/>
      <geometry>
        <mesh filename="/export/home/strahl/dev/gaikpy/resources/urdf/nicol/meshes/robot_frame/single_profile_45mm_holder_with_socket_centered.stl" scale="0.01 0.01 0.01"/>
      </geometry>
    </collision>
    <inertial>
      <origin rpy="0 -0.0005235988 0" xyz="-0.022 0.0 -0.720"/>
      <mass value="515.106"/>
      <inertia ixx="2.4662489606e01" ixy="4.29e-07" ixz="-8.927336e-03" iyy=" 2.4652408384e01" iyz="1.401e-05" izz="7.601222788"/>
    </inertial>
  </link>
  <!-- ################### Gazebo ####################### -->
  <!-- World -->
  <gazebo reference="world">
  </gazebo>
  <!-- holder -->
  <gazebo reference="base_link">
    <visual>
      <material>
        <ambient>0.7 0.7 0.7 1.0</ambient>
        <diffuse>0.6 0.6 0.6 1.0</diffuse>
        <specular>0.7 0.7 0.7 1.0</specular>
      </material>
    </visual>
  </gazebo>
  <!-- frame  -->
  <gazebo reference="frame_link">
    <visual>
      <material>
        <ambient>0.7 0.7 0.7 1.0</ambient>
        <diffuse>0.6 0.6 0.6 1.0</diffuse>
        <specular>0.7 0.7 0.7 1.0</specular>
      </material>
    </visual>
  </gazebo>
  <!-- camera -->
  <gazebo reference="camera_link">
    <material>Gazebo/Grey</material>
  </gazebo>
  <!-- camera holder -->
  <gazebo reference="camera_holder_link">
    <visual>
      <material>
        <ambient>0.7 0.7 0.7 1.0</ambient>
        <diffuse>0.6 0.6 0.6 1.0</diffuse>
        <specular>0.7 0.7 0.7 1.0</specular>
      </material>
    </visual>
  </gazebo>
  <!-- working plate -->
  <gazebo reference="plate_link">
    <material>Gazebo/White</material>
  </gazebo>
  <gazebo>
    <plugin filename="libgazebo_ros_control.so" name="gazebo_ros_control">
      <robotNamespace>right/open_manipulator_p</robotNamespace>
      <robotSimType>gazebo_ros_control/DefaultRobotHWSim</robotSimType>
    </plugin>
  </gazebo>
  <gazebo reference="r_link1">
    <!-- <kp>1000000.0</kp>
      <kd>100.0</kd> 
      <mu1>30.0</mu1>
      <mu2>30.0</mu2>
      <maxVel>1.0</maxVel>
      <minDepth>0.001</minDepth> -->
    <mu1>0.20</mu1>
    <mu2>0.20</mu2>
    <material>Gazebo/DarkGrey</material>
  </gazebo>
  <gazebo reference="r_link2">
    <!-- <kp>1000000.0</kp>
      <kd>100.0</kd> 
      <mu1>30.0</mu1>
      <mu2>30.0</mu2>
      <maxVel>1.0</maxVel>
      <minDepth>0.001</minDepth> -->
    <mu1>0.20</mu1>
    <mu2>0.20</mu2>
    <material>Gazebo/DarkGrey</material>
  </gazebo>
  <gazebo reference="r_link3">
    <!-- <kp>1000000.0</kp>
      <kd>100.0</kd> 
      <mu1>30.0</mu1>
      <mu2>30.0</mu2>
      <maxVel>1.0</maxVel>
      <minDepth>0.001</minDepth> -->
    <mu1>0.20</mu1>
    <mu2>0.20</mu2>
    <material>Gazebo/DarkGrey</material>
  </gazebo>
  <gazebo reference="r_link4">
    <!-- <kp>1000000.0</kp>
      <kd>100.0</kd> 
      <mu1>30.0</mu1>
      <mu2>30.0</mu2>
      <maxVel>1.0</maxVel>
      <minDepth>0.001</minDepth> -->
    <mu1>0.20</mu1>
    <mu2>0.20</mu2>
    <material>Gazebo/DarkGrey</material>
  </gazebo>
  <gazebo reference="r_link5">
    <!-- <kp>1000000.0</kp>
      <kd>100.0</kd> 
      <mu1>30.0</mu1>
      <mu2>30.0</mu2>
      <maxVel>1.0</maxVel>
      <minDepth>0.001</minDepth> -->
    <mu1>0.20</mu1>
    <mu2>0.20</mu2>
    <material>Gazebo/DarkGrey</material>
  </gazebo>
  <gazebo reference="r_link6">
    <!-- <kp>1000000.0</kp>
      <kd>100.0</kd> 
      <mu1>30.0</mu1>
      <mu2>30.0</mu2>
      <maxVel>1.0</maxVel>
      <minDepth>0.001</minDepth> -->
    <mu1>0.20</mu1>
    <mu2>0.20</mu2>
    <material>Gazebo/DarkGrey</material>
  </gazebo>
  <gazebo reference="r_RH8D_base">
    <!-- <kp>1000000.0</kp>
      <kd>100.0</kd>
      <mu1>30.0</mu1>
      <mu2>30.0</mu2>
      <maxVel>1.0</maxVel>
      <minDepth>0.001</minDepth> -->
    <!-- <visual>
        <material>
          <ambient>0.74902 0.74902 0.74902 1.0</ambient>
          <diffuse>0.74902 0.74902 0.74902 1.0</diffuse>
          <specular>0.74902 0.74902 0.74902 1.0</specular>
        </material>
      </visual> -->
    <mu1>0.2</mu1>
    <mu2>0.2</mu2>
    <material>Gazebo/Grey</material>
  </gazebo>
  <gazebo reference="r_forearm">
    <!-- <kp>1000000.0</kp>
      <kd>100.0</kd>
      <mu1>30.0</mu1>
      <mu2>30.0</mu2>
      <maxVel>1.0</maxVel>
      <minDepth>0.001</minDepth> -->
    <!-- <visual>
        <material>
          <ambient>0.74902 0.74902 0.74902 1.0</ambient>
          <diffuse>0.74902 0.74902 0.74902 1.0</diffuse>
          <specular>0.74902 0.74902 0.74902 1.0</specular>
        </material>
      </visual> -->
    <mu1>0.2</mu1>
    <mu2>0.2</mu2>
    <material>Gazebo/Grey</material>
  </gazebo>
  <gazebo reference="r_palm axis">
    <!-- <kp>1000000.0</kp>
      <kd>100.0</kd>
      <mu1>30.0</mu1>
      <mu2>30.0</mu2>
      <maxVel>1.0</maxVel>
      <minDepth>0.001</minDepth> -->
    <!-- <visual>
        <material>
          <ambient>0.74902 0.74902 0.74902 1.0</ambient>
          <diffuse>0.74902 0.74902 0.74902 1.0</diffuse>
          <specular>0.74902 0.74902 0.74902 1.0</specular>
        </material>
      </visual> -->
    <mu1>0.2</mu1>
    <mu2>0.2</mu2>
    <material>Gazebo/Grey</material>
  </gazebo>
  <gazebo reference="r_palm">
    <!-- <kp>1000000.0</kp>
      <kd>100.0</kd>
      <mu1>30.0</mu1>
      <mu2>30.0</mu2>
      <maxVel>1.0</maxVel>
      <minDepth>0.001</minDepth> -->
    <!-- <visual>
        <material>
          <ambient>0.74902 0.74902 0.74902 1.0</ambient>
          <diffuse>0.74902 0.74902 0.74902 1.0</diffuse>
          <specular>0.74902 0.74902 0.74902 1.0</specular>
        </material>
      </visual> -->
    <mu1>0.2</mu1>
    <mu2>0.2</mu2>
    <material>Gazebo/Grey</material>
  </gazebo>
  <gazebo reference="r_Rproximal">
    <!-- <kp>1000000.0</kp>
      <kd>100.0</kd>
      <mu1>30.0</mu1>
      <mu2>30.0</mu2>
      <maxVel>1.0</maxVel>
      <minDepth>0.001</minDepth> -->
    <!-- <visual>
        <material>
          <ambient>0.74902 0.74902 0.74902 1.0</ambient>
          <diffuse>0.74902 0.74902 0.74902 1.0</diffuse>
          <specular>0.74902 0.74902 0.74902 1.0</specular>
        </material>
      </visual> -->
    <mu1>0.2</mu1>
    <mu2>0.2</mu2>
    <material>Gazebo/Grey</material>
  </gazebo>
  <gazebo reference="r_Rmiddle">
    <!-- <kp>1000000.0</kp>
      <kd>100.0</kd>
      <mu1>30.0</mu1>
      <mu2>30.0</mu2>
      <maxVel>1.0</maxVel>
      <minDepth>0.001</minDepth> -->
    <!-- <visual>
        <material>
          <ambient>0.74902 0.74902 0.74902 1.0</ambient>
          <diffuse>0.74902 0.74902 0.74902 1.0</diffuse>
          <specular>0.74902 0.74902 0.74902 1.0</specular>
        </material>
      </visual> -->
    <mu1>0.2</mu1>
    <mu2>0.2</mu2>
    <material>Gazebo/Grey</material>
  </gazebo>
  <gazebo reference="r_Rtip">
    <!-- <kp>1000000.0</kp>
      <kd>100.0</kd>
      <mu1>30.0</mu1>
      <mu2>30.0</mu2>
      <maxVel>1.0</maxVel>
      <minDepth>0.001</minDepth> -->
    <!-- <visual>
        <material>
          <ambient>0.74902 0.74902 0.74902 1.0</ambient>
          <diffuse>0.74902 0.74902 0.74902 1.0</diffuse>
          <specular>0.74902 0.74902 0.74902 1.0</specular>
        </material>
      </visual> -->
    <mu1>0.2</mu1>
    <mu2>0.2</mu2>
    <material>Gazebo/Grey</material>
  </gazebo>
  <gazebo reference="r_Mproximal">
    <!-- <kp>1000000.0</kp>
      <kd>100.0</kd>
      <mu1>30.0</mu1>
      <mu2>30.0</mu2>
      <maxVel>1.0</maxVel>
      <minDepth>0.001</minDepth> -->
    <!-- <visual>
        <material>
          <ambient>0.74902 0.74902 0.74902 1.0</ambient>
          <diffuse>0.74902 0.74902 0.74902 1.0</diffuse>
          <specular>0.74902 0.74902 0.74902 1.0</specular>
        </material>
      </visual> -->
    <mu1>0.2</mu1>
    <mu2>0.2</mu2>
    <material>Gazebo/Grey</material>
  </gazebo>
  <gazebo reference="r_Mmiddle">
    <!-- <kp>1000000.0</kp>
      <kd>100.0</kd>
      <mu1>30.0</mu1>
      <mu2>30.0</mu2>
      <maxVel>1.0</maxVel>
      <minDepth>0.001</minDepth> -->
    <!-- <visual>
        <material>
          <ambient>0.74902 0.74902 0.74902 1.0</ambient>
          <diffuse>0.74902 0.74902 0.74902 1.0</diffuse>
          <specular>0.74902 0.74902 0.74902 1.0</specular>
        </material>
      </visual> -->
    <mu1>0.2</mu1>
    <mu2>0.2</mu2>
    <material>Gazebo/Grey</material>
  </gazebo>
  <gazebo reference="r_Mtip">
    <!-- <kp>1000000.0</kp>
      <kd>100.0</kd>
      <mu1>30.0</mu1>
      <mu2>30.0</mu2>
      <maxVel>1.0</maxVel>
      <minDepth>0.001</minDepth> -->
    <!-- <visual>
        <material>
          <ambient>0.74902 0.74902 0.74902 1.0</ambient>
          <diffuse>0.74902 0.74902 0.74902 1.0</diffuse>
          <specular>0.74902 0.74902 0.74902 1.0</specular>
        </material>
      </visual> -->
    <mu1>0.2</mu1>
    <mu2>0.2</mu2>
    <material>Gazebo/Grey</material>
  </gazebo>
  <gazebo reference="r_Pproximal">
    <!-- <kp>1000000.0</kp>
      <kd>100.0</kd>
      <mu1>30.0</mu1>
      <mu2>30.0</mu2>
      <maxVel>1.0</maxVel>
      <minDepth>0.001</minDepth> -->
    <!-- <visual>
        <material>
          <ambient>0.74902 0.74902 0.74902 1.0</ambient>
          <diffuse>0.74902 0.74902 0.74902 1.0</diffuse>
          <specular>0.74902 0.74902 0.74902 1.0</specular>
        </material>
      </visual> -->
    <mu1>0.2</mu1>
    <mu2>0.2</mu2>
    <material>Gazebo/Grey</material>
  </gazebo>
  <gazebo reference="r_Pmiddle">
    <!-- <kp>1000000.0</kp>
      <kd>100.0</kd>
      <mu1>30.0</mu1>
      <mu2>30.0</mu2>
      <maxVel>1.0</maxVel>
      <minDepth>0.001</minDepth> -->
    <!-- <visual>
        <material>
          <ambient>0.74902 0.74902 0.74902 1.0</ambient>
          <diffuse>0.74902 0.74902 0.74902 1.0</diffuse>
          <specular>0.74902 0.74902 0.74902 1.0</specular>
        </material>
      </visual> -->
    <mu1>0.2</mu1>
    <mu2>0.2</mu2>
    <material>Gazebo/Grey</material>
  </gazebo>
  <gazebo reference="r_Ptip">
    <!-- <kp>1000000.0</kp>
      <kd>100.0</kd>
      <mu1>30.0</mu1>
      <mu2>30.0</mu2>
      <maxVel>1.0</maxVel>
      <minDepth>0.001</minDepth> -->
    <!-- <visual>
        <material>
          <ambient>0.74902 0.74902 0.74902 1.0</ambient>
          <diffuse>0.74902 0.74902 0.74902 1.0</diffuse>
          <specular>0.74902 0.74902 0.74902 1.0</specular>
        </material>
      </visual> -->
    <mu1>0.2</mu1>
    <mu2>0.2</mu2>
    <material>Gazebo/Grey</material>
  </gazebo>
  <gazebo reference="r_thumb base">
    <!-- <kp>1000000.0</kp>
      <kd>100.0</kd>
      <mu1>30.0</mu1>
      <mu2>30.0</mu2>
      <maxVel>1.0</maxVel>
      <minDepth>0.001</minDepth> -->
    <!-- <visual>
        <material>
          <ambient>0.74902 0.74902 0.74902 1.0</ambient>
          <diffuse>0.74902 0.74902 0.74902 1.0</diffuse>
          <specular>0.74902 0.74902 0.74902 1.0</specular>
        </material>
      </visual> -->
    <mu1>0.2</mu1>
    <mu2>0.2</mu2>
    <material>Gazebo/Grey</material>
  </gazebo>
  <gazebo reference="r_Tproximal">
    <!-- <kp>1000000.0</kp>
      <kd>100.0</kd>
      <mu1>30.0</mu1>
      <mu2>30.0</mu2>
      <maxVel>1.0</maxVel>
      <minDepth>0.001</minDepth> -->
    <!-- <visual>
        <material>
          <ambient>0.74902 0.74902 0.74902 1.0</ambient>
          <diffuse>0.74902 0.74902 0.74902 1.0</diffuse>
          <specular>0.74902 0.74902 0.74902 1.0</specular>
        </material>
      </visual> -->
    <mu1>0.2</mu1>
    <mu2>0.2</mu2>
    <material>Gazebo/Grey</material>
  </gazebo>
  <gazebo reference="r_Tmiddle">
    <!-- <kp>1000000.0</kp>
      <kd>100.0</kd>
      <mu1>30.0</mu1>
      <mu2>30.0</mu2>
      <maxVel>1.0</maxVel>
      <minDepth>0.001</minDepth> -->
    <!-- <visual>
        <material>
          <ambient>0.74902 0.74902 0.74902 1.0</ambient>
          <diffuse>0.74902 0.74902 0.74902 1.0</diffuse>
          <specular>0.74902 0.74902 0.74902 1.0</specular>
        </material>
      </visual> -->
    <mu1>0.2</mu1>
    <mu2>0.2</mu2>
    <material>Gazebo/Grey</material>
  </gazebo>
  <gazebo reference="r_Ttip">
    <!-- <kp>1000000.0</kp>
      <kd>100.0</kd>
      <mu1>30.0</mu1>
      <mu2>30.0</mu2>
      <maxVel>1.0</maxVel>
      <minDepth>0.001</minDepth> -->
    <!-- <visual>
        <material>
          <ambient>0.74902 0.74902 0.74902 1.0</ambient>
          <diffuse>0.74902 0.74902 0.74902 1.0</diffuse>
          <specular>0.74902 0.74902 0.74902 1.0</specular>
        </material>
      </visual> -->
    <mu1>0.2</mu1>
    <mu2>0.2</mu2>
    <material>Gazebo/Grey</material>
  </gazebo>
  <gazebo reference="r_Iproximal">
    <!-- <kp>1000000.0</kp>
      <kd>100.0</kd>
      <mu1>30.0</mu1>
      <mu2>30.0</mu2>
      <maxVel>1.0</maxVel>
      <minDepth>0.001</minDepth> -->
    <!-- <visual>
        <material>
          <ambient>0.74902 0.74902 0.74902 1.0</ambient>
          <diffuse>0.74902 0.74902 0.74902 1.0</diffuse>
          <specular>0.74902 0.74902 0.74902 1.0</specular>
        </material>
      </visual> -->
    <mu1>0.2</mu1>
    <mu2>0.2</mu2>
    <material>Gazebo/Grey</material>
  </gazebo>
  <gazebo reference="r_Imiddle">
    <!-- <kp>1000000.0</kp>
      <kd>100.0</kd>
      <mu1>30.0</mu1>
      <mu2>30.0</mu2>
      <maxVel>1.0</maxVel>
      <minDepth>0.001</minDepth> -->
    <!-- <visual>
        <material>
          <ambient>0.74902 0.74902 0.74902 1.0</ambient>
          <diffuse>0.74902 0.74902 0.74902 1.0</diffuse>
          <specular>0.74902 0.74902 0.74902 1.0</specular>
        </material>
      </visual> -->
    <mu1>0.2</mu1>
    <mu2>0.2</mu2>
    <material>Gazebo/Grey</material>
  </gazebo>
  <gazebo reference="r_Itip">
    <!-- <kp>1000000.0</kp>
      <kd>100.0</kd>
      <mu1>30.0</mu1>
      <mu2>30.0</mu2>
      <maxVel>1.0</maxVel>
      <minDepth>0.001</minDepth> -->
    <!-- <visual>
        <material>
          <ambient>0.74902 0.74902 0.74902 1.0</ambient>
          <diffuse>0.74902 0.74902 0.74902 1.0</diffuse>
          <specular>0.74902 0.74902 0.74902 1.0</specular>
        </material>
      </visual> -->
    <mu1>0.2</mu1>
    <mu2>0.2</mu2>
    <material>Gazebo/Grey</material>
  </gazebo>
  <!-- <gazebo>
    <pose>0.0 0.0 0.0 0.0 0.0 0.0</pose>
  </gazebo> -->
  <gazebo reference="camera_link">
    <sensor name="intel_realsense_d435" type="camera">
      <update_rate>30.0</update_rate>
      <camera name="head">
        <horizontal_fov>1.02974</horizontal_fov>
        <image>
          <width>1920</width>
          <height>1080</height>
          <format>R8G8B8</format>
        </image>
        <clip>
          <near>0.02</near>
          <far>300</far>
        </clip>
        <noise>
          <type>gaussian</type>
          <!-- Noise is sampled independently per pixel on each frame.
                That pixel's noise value is added to each of its color
                channels, which at that point lie in the range [0,1]. -->
          <mean>0.0</mean>
          <stddev>0.007</stddev>
        </noise>
      </camera>
      <plugin filename="libgazebo_ros_camera.so" name="camera_controller">
        <alwaysOn>true</alwaysOn>
        <updateRate>0.0</updateRate>
        <cameraName>camera/color</cameraName>
        <imageTopicName>image_raw</imageTopicName>
        <cameraInfoTopicName>camera_info</cameraInfoTopicName>
        <frameName>camera_link</frameName>
        <hackBaseline>0.07</hackBaseline>
        <distortionK1>0.0</distortionK1>
        <distortionK2>0.0</distortionK2>
        <distortionK3>0.0</distortionK3>
        <distortionT1>0.0</distortionT1>
        <distortionT2>0.0</distortionT2>
      </plugin>
    </sensor>
  </gazebo>
  <!-- Conditional on urdf export, append prefix when merged to one urdf -->
  <!-- <xacro:if value="$(arg export_arg)">
    <xacro:property name="r_joint_export_prefix" value="r_"/>
  </xacro:if>
  <xacro:unless value="$(arg export_arg)"> 
    <xacro:property name="r_joint_export_prefix" value=""/>
  </xacro:unless>
   -->
  <!-- custom base -->
  <link name="r_RH8D_base">
    <inertial>
      <origin rpy="0 -0.485027 0" xyz="0 -0.0102 0"/>
      <mass value="0.035"/>
      <inertia ixx="7.813e-06" ixy="0" ixz="0" iyy="1.3286e-5" iyz="0" izz="7.813e-06"/>
    </inertial>
    <visual>
      <origin rpy="0 0 0" xyz="0 0 0"/>
      <geometry>
        <mesh filename="/export/home/strahl/dev/gaikpy/resources/urdf/nicol/meshes/RH8D/hand_adapter_base.stl" scale="0.01 0.01 0.01"/>
      </geometry>
      <material name="base_color">
        <color rgba="0.74902 0.74902 0.74902 1.0"/>
      </material>
    </visual>
    <collision>
      <origin rpy="0 0 0" xyz="0 0 0"/>
      <geometry>
        <mesh filename="/export/home/strahl/dev/gaikpy/resources/urdf/nicol/meshes/RH8D/hand_adapter_base.stl" scale="0.01 0.01 0.01"/>
      </geometry>
    </collision>
  </link>
  <!-- r_forearm -->
  <link name="r_forearm">
    <inertial>
      <origin rpy="0 0 0" xyz="2.30433000001e-07 -0.0655374 -0.00282708"/>
      <mass value="0.737868"/>
      <inertia ixx="0.0013021" ixy="1.01472e-07" ixz="5.87405e-09" iyy="0.000679239" iyz="-1.22301e-05" izz="0.00145511"/>
    </inertial>
    <visual>
      <origin rpy="0 0 0" xyz="0.0241628 -0.122588 -0.0023045"/>
      <geometry>
        <mesh filename="/export/home/strahl/dev/gaikpy/resources/urdf/nicol/meshes/RH8D/right/forearm.stl" scale="0.001 0.001 0.001"/>
      </geometry>
      <material name="forearm_color">
        <color rgba="0.74902 0.74902 0.74902 1.0"/>
      </material>
    </visual>
    <collision>
      <origin rpy="0 0 0" xyz="0.0241628 -0.122588 -0.0023045"/>
      <geometry>
        <mesh filename="/export/home/strahl/dev/gaikpy/resources/urdf/nicol/meshes/RH8D/right/forearm.stl" scale="0.001 0.001 0.001"/>
      </geometry>
    </collision>
  </link>
  <!-- r_forearm_base joint is fixed in nias version : manipulator joint4 and 6 are used for wrist -->
  <joint name="r_forearm__base" type="fixed">
    <origin rpy="0 -1.57079632679 0" xyz="0 -0.019 0"/>
    <parent link="r_RH8D_base"/>
    <child link="r_forearm"/>
  </joint>
  <!-- r_palm axis -->
  <link name="r_palm axis">
    <inertial>
      <origin rpy="0 0 0" xyz="0 0.009025 -0.01025"/>
      <mass value="0.0484983"/>
      <inertia ixx="9.46434e-06" ixy="0.0" ixz="0.0" iyy="1.22209e-05" iyz="-2.49433e-17" izz="1.71183e-05"/>
    </inertial>
    <visual>
      <origin rpy="0 0 0" xyz="0 0 -0.01025"/>
      <geometry>
        <mesh filename="/export/home/strahl/dev/gaikpy/resources/urdf/nicol/meshes/RH8D/right/palm axis.stl" scale="0.001 0.001 0.001"/>
      </geometry>
      <material name="palm axis_color">
        <color rgba="0.74902 0.74902 0.74902 1.0"/>
      </material>
    </visual>
    <collision>
      <origin rpy="0 0 0" xyz="0 0 -0.01025"/>
      <geometry>
        <mesh filename="/export/home/strahl/dev/gaikpy/resources/urdf/nicol/meshes/RH8D/right/palm axis.stl" scale="0.001 0.001 0.001"/>
      </geometry>
    </collision>
  </link>
  <!--  joint palm_forearm  -->
  <joint name="r_joint7" type="revolute">
    <origin rpy="-3.14159265359 0 -3.14159265359" xyz="0 -0.165 -0.01525"/>
    <axis xyz="-2.22044604925e-16 0.0 -1.0"/>
    <parent link="r_forearm"/>
    <child link="r_palm axis"/>
    <limit effort="0.5" lower="-0.785398163397" upper="0.785398163397" velocity="1.0"/>
    <dynamics damping="0.01"/>
  </joint>
  <transmission name="tranr_7">
    <type>transmission_interface/SimpleTransmission</type>
    <joint name="r_joint7">
      <hardwareInterface>hardware_interface/PositionJointInterface</hardwareInterface>
    </joint>
    <actuator name="motorr_7">
      <hardwareInterface>hardware_interface/PositionJointInterface</hardwareInterface>
      <mechanicalReduction>1</mechanicalReduction>
    </actuator>
  </transmission>
  <!-- palm -->
  <link name="r_palm">
    <inertial>
      <origin rpy="0 0 0" xyz="0.02226623 -0.04266 -0.00107953"/>
      <mass value="0.0886716"/>
      <inertia ixx="3.49499e-05" ixy="1.90978e-06" ixz="3.02331e-06" iyy="5.90827e-05" iyz="-2.26784e-07" izz="8.80157e-05"/>
    </inertial>
    <visual>
      <origin rpy="0 0 0" xyz="16.7603 17.427 0.713666"/>
      <geometry>
        <mesh filename="/export/home/strahl/dev/gaikpy/resources/urdf/nicol/meshes/RH8D/right/palm.stl" scale="0.001 0.001 0.001"/>
      </geometry>
      <material name="palm_color">
        <color rgba="0.74902 0.74902 0.74902 1.0"/>
      </material>
    </visual>
    <collision>
      <origin rpy="0 0 0" xyz="16.7603 17.427 0.713666"/>
      <geometry>
        <mesh filename="/export/home/strahl/dev/gaikpy/resources/urdf/nicol/meshes/RH8D/right/palm.stl" scale="0.001 0.001 0.001"/>
      </geometry>
    </collision>
  </link>
  <!-- joint palm_palm_axis -->
  <joint name="r_joint8" type="revolute">
    <origin rpy="0 0 0" xyz="-0.0265 0 -0.01025"/>
    <axis xyz="-1.0 2.22044604925e-16 0.0"/>
    <parent link="r_palm axis"/>
    <child link="r_palm"/>
    <limit effort="0.5" lower="-0.785398163397" upper="0.785398163397" velocity="1.0"/>
    <dynamics damping="0.01"/>
  </joint>
  <transmission name="tranr_8">
    <type>transmission_interface/SimpleTransmission</type>
    <joint name="r_joint8">
      <hardwareInterface>hardware_interface/PositionJointInterface</hardwareInterface>
    </joint>
    <actuator name="motorr_8">
      <hardwareInterface>hardware_interface/PositionJointInterface</hardwareInterface>
      <mechanicalReduction>1</mechanicalReduction>
    </actuator>
  </transmission>
  <!-- Ringfinger -->
  <link name="r_Rproximal">
    <inertial>
      <origin rpy="0 0 0" xyz="-0.00506265498327 0.000178411167835 -0.0113952992502"/>
      <mass value="0.0046468"/>
      <inertia ixx="3.60659e-07" ixy="2.95375e-10" ixz="3.96643e-12" iyy="4.02251e-07" iyz="7.4602e-09" izz="1.59669e-07"/>
    </inertial>
    <visual>
      <origin rpy="0 0 0" xyz="0.00532660458173 -0.00134315858259 -0.0128298354943"/>
      <geometry>
        <mesh filename="/export/home/strahl/dev/gaikpy/resources/urdf/nicol/meshes/RH8D/right/seg_L.stl" scale="0.001 0.001 0.001"/>
      </geometry>
      <material name="Rproximal_color">
        <color rgba="0.74902 0.74902 0.74902 1.0"/>
      </material>
    </visual>
    <collision>
      <origin rpy="0 0 0" xyz="0.00532660458173 -0.00134315858259 -0.0128298354943"/>
      <geometry>
        <mesh filename="/export/home/strahl/dev/gaikpy/resources/urdf/nicol/meshes/RH8D/right/seg_L.stl" scale="0.001 0.001 0.001"/>
      </geometry>
    </collision>
  </link>
  <!-- joint r_Rproximal__palm  -->
  <joint name="r_jointR1" type="revolute">
    <origin rpy="-1.83998062112 -0.070428847363 0.101332262919" xyz="0.044463 -0.081365 0.00148931"/>
    <axis xyz="-1.00000007251 -8.46220030541e-08 1.44225053858e-07"/>
    <parent link="r_palm"/>
    <child link="r_Rproximal"/>
    <limit effort="0.5" lower="0.0" upper="1.4835298642" velocity="1.0"/>
    <dynamics damping="0.01"/>
  </joint>
  <transmission name="tranr_R1">
    <type>transmission_interface/SimpleTransmission</type>
    <joint name="r_jointR1">
      <hardwareInterface>hardware_interface/PositionJointInterface</hardwareInterface>
    </joint>
    <actuator name="motorr_R1">
      <hardwareInterface>hardware_interface/PositionJointInterface</hardwareInterface>
      <mechanicalReduction>1</mechanicalReduction>
    </actuator>
  </transmission>
  <link name="r_Rmiddle">
    <inertial>
      <origin rpy="0 0 0" xyz="-0.0050627375168 0.000178703837342 -0.0113961050151"/>
      <mass value="0.0046468"/>
      <inertia ixx="3.60659e-07" ixy="2.95375e-10" ixz="3.96643e-12" iyy="4.02251e-07" iyz="7.4602e-09" izz="1.59669e-07"/>
    </inertial>
    <visual>
      <origin rpy="0 0 0" xyz="0.00532662722179 -0.00134303584663 -0.0128300831679"/>
      <geometry>
        <mesh filename="/export/home/strahl/dev/gaikpy/resources/urdf/nicol/meshes/RH8D/right/seg_L.stl" scale="0.001 0.001 0.001"/>
      </geometry>
      <material name="Rmiddle_color">
        <color rgba="0.74902 0.74902 0.74902 1.0"/>
      </material>
    </visual>
    <collision>
      <origin rpy="0 0 0" xyz="0.00532662722179 -0.00134303584663 -0.0128300831679"/>
      <geometry>
        <mesh filename="/export/home/strahl/dev/gaikpy/resources/urdf/nicol/meshes/RH8D/right/seg_L.stl" scale="0.001 0.001 0.001"/>
      </geometry>
    </collision>
  </link>
  <!-- joint r_Rmiddle__r_Rproximal -->
  <joint name="r_jointR2" type="revolute">
    <origin rpy="-0.0872670609142 0 2.76912342671e-07" xyz="0 0 -0.0258747809103"/>
    <axis xyz="-1.00000007251 1.72767385245e-07 2.31542720386e-07"/>
    <parent link="r_Rproximal"/>
    <child link="r_Rmiddle"/>
    <limit effort="0.5" lower="0.0" upper="1.4835298642" velocity="1.0"/>
    <dynamics damping="0.001"/>
  </joint>
  <transmission name="tranr_R2">
    <type>transmission_interface/SimpleTransmission</type>
    <joint name="r_jointR2">
      <hardwareInterface>hardware_interface/PositionJointInterface</hardwareInterface>
    </joint>
    <actuator name="motorr_R2">
      <hardwareInterface>hardware_interface/PositionJointInterface</hardwareInterface>
      <mechanicalReduction>1</mechanicalReduction>
    </actuator>
  </transmission>
  <link name="r_Rtip">
    <inertial>
      <origin rpy="0 0 0" xyz="-0.00506262889447 0.000158864121429 -0.00949029810479"/>
      <mass value="0.00398141"/>
      <inertia ixx="2.27393e-07" ixy="-4.487e-12" ixz="-6.19169e-12" iyy="2.50732e-07" iyz="3.7689e-09" izz="1.09262e-07"/>
    </inertial>
    <visual>
      <origin rpy="0 0 0" xyz="-0.00506246565687 -4.09118144695e-07 7.45384128198e-07"/>
      <geometry>
        <mesh filename="/export/home/strahl/dev/gaikpy/resources/urdf/nicol/meshes/RH8D/right/tip.stl" scale="0.001 0.001 0.001"/>
      </geometry>
      <material name="Rtip_color">
        <color rgba="0.74902 0.74902 0.74902 1.0"/>
      </material>
    </visual>
    <collision>
      <origin rpy="0 0 0" xyz="-0.00506246565687 -4.09118144695e-07 7.45384128198e-07"/>
      <geometry>
        <mesh filename="/export/home/strahl/dev/gaikpy/resources/urdf/nicol/meshes/RH8D/right/tip.stl" scale="0.001 0.001 0.001"/>
      </geometry>
    </collision>
  </link>
  <!-- joint r_Rtip__r_Rmiddle -->
  <joint name="r_jointR3" type="revolute">
    <origin rpy="-0.0872662816218 1.12264697248e-07 -3.5745305372e-07" xyz="0 2.25940697457e-07 -0.0258755491275"/>
    <axis xyz="-1.00000007251 -1.94378654964e-07 1.02727742424e-07"/>
    <parent link="r_Rmiddle"/>
    <child link="r_Rtip"/>
    <limit effort="0.5" lower="0.0" upper="1.4835298642" velocity="1.0"/>
    <dynamics damping="0.001"/>
  </joint>
  <transmission name="tranr_R3">
    <type>transmission_interface/SimpleTransmission</type>
    <joint name="r_jointR3">
      <hardwareInterface>hardware_interface/PositionJointInterface</hardwareInterface>
    </joint>
    <actuator name="motorr_R3">
      <hardwareInterface>hardware_interface/PositionJointInterface</hardwareInterface>
      <mechanicalReduction>1</mechanicalReduction>
    </actuator>
  </transmission>
  <!-- Middlefinger -->
  <link name="r_Mproximal">
    <inertial>
      <origin rpy="0 0 0" xyz="-0.00506268032219 0.000178369758776 -0.0113951959251"/>
      <mass value="0.0046468"/>
      <inertia ixx="3.60659e-07" ixy="2.95375e-10" ixz="3.96643e-12" iyy="4.02251e-07" iyz="7.4602e-09" izz="1.59669e-07"/>
    </inertial>
    <visual>
      <origin rpy="0 0 0" xyz="0.00532660055243 -0.00134318776557 -0.0128295627043"/>
      <geometry>
        <mesh filename="/export/home/strahl/dev/gaikpy/resources/urdf/nicol/meshes/RH8D/right/seg_L.stl" scale="0.001 0.001 0.001"/>
      </geometry>
      <material name="Mproximal_color">
        <color rgba="0.74902 0.74902 0.74902 1.0"/>
      </material>
    </visual>
    <collision>
      <origin rpy="0 0 0" xyz="0.00532660055243 -0.00134318776557 -0.0128295627043"/>
      <geometry>
        <mesh filename="/export/home/strahl/dev/gaikpy/resources/urdf/nicol/meshes/RH8D/right/seg_L.stl" scale="0.001 0.001 0.001"/>
      </geometry>
    </collision>
  </link>
  <!-- joint r_Mtip__M2 -->
  <joint name="r_jointM1" type="revolute">
    <origin rpy="-1.83324870939 0.0859369188285 -0.0151906736407" xyz="0.01971414 -0.082973 0.00076618"/>
    <axis xyz="-1.00000030441 -5.71235363176e-07 2.22119205119e-07"/>
    <parent link="r_palm"/>
    <child link="r_Mproximal"/>
    <limit effort="0.5" lower="0.0" upper="1.4835298642" velocity="1.0"/>
    <dynamics damping="0.01"/>
  </joint>
  <transmission name="tranr_M1">
    <type>transmission_interface/SimpleTransmission</type>
    <joint name="r_jointM1">
      <hardwareInterface>hardware_interface/PositionJointInterface</hardwareInterface>
    </joint>
    <actuator name="motorr_M1">
      <hardwareInterface>hardware_interface/PositionJointInterface</hardwareInterface>
      <mechanicalReduction>1</mechanicalReduction>
    </actuator>
  </transmission>
  <link name="r_Mmiddle">
    <inertial>
      <origin rpy="0 0 0" xyz="-0.00506269201108 0.000178473714736 -0.0113956264739"/>
      <mass value="0.0046468"/>
      <inertia ixx="3.60659e-07" ixy="2.95375e-10" ixz="3.96643e-12" iyy="4.02251e-07" iyz="7.4602e-09" izz="1.59669e-07"/>
    </inertial>
    <visual>
      <origin rpy="0 0 0" xyz="0.00532662940519 -0.001342939287 -0.012830098266"/>
      <geometry>
        <mesh filename="/export/home/strahl/dev/gaikpy/resources/urdf/nicol/meshes/RH8D/right/seg_L.stl" scale="0.001 0.001 0.001"/>
      </geometry>
      <material name="Mmiddle_color">
        <color rgba="0.74902 0.74902 0.74902 1.0"/>
      </material>
    </visual>
    <collision>
      <origin rpy="0 0 0" xyz="0.00532662940519 -0.001342939287 -0.012830098266"/>
      <geometry>
        <mesh filename="/export/home/strahl/dev/gaikpy/resources/urdf/nicol/meshes/RH8D/right/seg_L.stl" scale="0.001 0.001 0.001"/>
      </geometry>
    </collision>
  </link>
  <!-- joint  r_Mmiddle__Mproxima -->
  <joint name="r_jointM2" type="revolute">
    <origin rpy="-0.0872661749543 2.70259221066e-07 3.1679265362e-07" xyz="0 -2.41651877793e-07 -0.0258742142625"/>
    <axis xyz="-1.00000030441 -2.49278715942e-07 -7.0132973715e-08"/>
    <parent link="r_Mproximal"/>
    <child link="r_Mmiddle"/>
    <limit effort="0.5" lower="0.0" upper="1.4835298642" velocity="1.0"/>
    <dynamics damping="0.001"/>
  </joint>
  <transmission name="tranr_M2">
    <type>transmission_interface/SimpleTransmission</type>
    <joint name="r_jointM2">
      <hardwareInterface>hardware_interface/PositionJointInterface</hardwareInterface>
    </joint>
    <actuator name="motorr_M2">
      <hardwareInterface>hardware_interface/PositionJointInterface</hardwareInterface>
      <mechanicalReduction>1</mechanicalReduction>
    </actuator>
  </transmission>
  <link name="r_Mtip">
    <inertial>
      <origin rpy="0 0 0" xyz="-0.0050627478165 0.00015921993426 -0.00949104619276"/>
      <mass value="0.00398141"/>
      <inertia ixx="2.27393e-07" ixy="-4.487e-12" ixz="-6.19169e-12" iyy="2.50732e-07" iyz="3.7689e-09" izz="1.09262e-07"/>
    </inertial>
    <visual>
      <origin rpy="0 0 0" xyz="-0.00506245834339 -1.4490970493e-07 3.55767050764e-07"/>
      <geometry>
        <mesh filename="/export/home/strahl/dev/gaikpy/resources/urdf/nicol/meshes/RH8D/right/tip.stl" scale="0.001 0.001 0.001"/>
      </geometry>
      <material name="Mtip_color">
        <color rgba="0.74902 0.74902 0.74902 1.0"/>
      </material>
    </visual>
    <collision>
      <origin rpy="0 0 0" xyz="-0.00506245834339 -1.4490970493e-07 3.55767050764e-07"/>
      <geometry>
        <mesh filename="/export/home/strahl/dev/gaikpy/resources/urdf/nicol/meshes/RH8D/right/tip.stl" scale="0.001 0.001 0.001"/>
      </geometry>
    </collision>
  </link>
  <!-- joint r_Mtip_r_Mmiddle -->
  <joint name="r_jointM3" type="revolute">
    <origin rpy="-0.0872666641639 -2.30451794024e-07 1.75345278157e-07" xyz="0 1.85177410031e-07 -0.0258754440497"/>
    <axis xyz="-1.00000030441 -8.76247884616e-08 1.53265091958e-07"/>
    <parent link="r_Mmiddle"/>
    <child link="r_Mtip"/>
    <limit effort="0.5" lower="0.0" upper="1.4835298642" velocity="1.0"/>
    <dynamics damping="0.001"/>
  </joint>
  <transmission name="tranr_M3">
    <type>transmission_interface/SimpleTransmission</type>
    <joint name="r_jointM3">
      <hardwareInterface>hardware_interface/PositionJointInterface</hardwareInterface>
    </joint>
    <actuator name="motorr_M3">
      <hardwareInterface>hardware_interface/PositionJointInterface</hardwareInterface>
      <mechanicalReduction>1</mechanicalReduction>
    </actuator>
  </transmission>
  <!-- Little finger -->
  <link name="r_Pproximal">
    <inertial>
      <origin rpy="0 0 0" xyz="-0.00506265004772 0.000178471691603 -0.0113954440839"/>
      <mass value="0.0046468"/>
      <inertia ixx="3.60659e-07" ixy="2.95375e-10" ixz="3.96643e-12" iyy="4.02251e-07" iyz="7.4602e-09" izz="1.59669e-07"/>
    </inertial>
    <visual>
      <origin rpy="0 0 0" xyz="0.00532669695333 -0.00134327559708 -0.0128292006118"/>
      <geometry>
        <mesh filename="/export/home/strahl/dev/gaikpy/resources/urdf/nicol/meshes/RH8D/right/seg_L.stl" scale="0.001 0.001 0.001"/>
      </geometry>
      <material name="Pproximal_color">
        <color rgba="0.74902 0.74902 0.74902 1.0"/>
      </material>
    </visual>
    <collision>
      <origin rpy="0 0 0" xyz="0.00532669695333 -0.00134327559708 -0.0128292006118"/>
      <geometry>
        <mesh filename="/export/home/strahl/dev/gaikpy/resources/urdf/nicol/meshes/RH8D/right/seg_L.stl" scale="0.001 0.001 0.001"/>
      </geometry>
    </collision>
  </link>
  <!-- joint r_Pproximal__palm -->
  <joint name="r_jointL1" type="revolute">
    <origin rpy="-1.86212856709 -0.138702648968 0.204065548896" xyz="0.0691264 -0.072128 0.0038631"/>
    <axis xyz="-0.999999718358 -2.63813422101e-07 -1.77932631934e-07"/>
    <parent link="r_palm"/>
    <child link="r_Pproximal"/>
    <limit effort="0.5" lower="0.0" upper="1.4835298642" velocity="1.0"/>
    <dynamics damping="0.01"/>
  </joint>
  <transmission name="tranr_L1">
    <type>transmission_interface/SimpleTransmission</type>
    <joint name="r_jointL1">
      <hardwareInterface>hardware_interface/PositionJointInterface</hardwareInterface>
    </joint>
    <actuator name="motorr_L1">
      <hardwareInterface>hardware_interface/PositionJointInterface</hardwareInterface>
      <mechanicalReduction>1</mechanicalReduction>
    </actuator>
  </transmission>
  <link name="r_Pmiddle">
    <inertial>
      <origin rpy="0 0 0" xyz="-0.00506271792241 0.000178454269957 -0.0113956275282"/>
      <mass value="0.0046468"/>
      <inertia ixx="3.60659e-07" ixy="2.95375e-10" ixz="3.96643e-12" iyy="4.02251e-07" iyz="7.4602e-09" izz="1.59669e-07"/>
    </inertial>
    <visual>
      <origin rpy="0 0 0" xyz="0.00532646642137 -0.00134299429342 -0.0128302748856"/>
      <geometry>
        <mesh filename="/export/home/strahl/dev/gaikpy/resources/urdf/nicol/meshes/RH8D/right/seg_L.stl" scale="0.001 0.001 0.001"/>
      </geometry>
      <material name="Pmiddle_color">
        <color rgba="0.74902 0.74902 0.74902 1.0"/>
      </material>
    </visual>
    <collision>
      <origin rpy="0 0 0" xyz="0.00532646642137 -0.00134299429342 -0.0128302748856"/>
      <geometry>
        <mesh filename="/export/home/strahl/dev/gaikpy/resources/urdf/nicol/meshes/RH8D/right/seg_L.stl" scale="0.001 0.001 0.001"/>
      </geometry>
    </collision>
  </link>
  <!-- joint r_Pmiddle__r_Pproximal -->
  <joint name="r_jointL2" type="revolute">
    <origin rpy="-0.0872666026479 1.06320174575e-07 0" xyz="1.71429768873e-07 0 -0.0258743732015"/>
    <axis xyz="-0.999999718358 -2.69819360882e-07 -3.08944752836e-07"/>
    <parent link="r_Pproximal"/>
    <child link="r_Pmiddle"/>
    <limit effort="0.5" lower="0.0" upper="1.4835298642" velocity="1.0"/>
    <dynamics damping="0.001"/>
  </joint>
  <transmission name="tranr_L2">
    <type>transmission_interface/SimpleTransmission</type>
    <joint name="r_jointL2">
      <hardwareInterface>hardware_interface/PositionJointInterface</hardwareInterface>
    </joint>
    <actuator name="motorr_L2">
      <hardwareInterface>hardware_interface/PositionJointInterface</hardwareInterface>
      <mechanicalReduction>1</mechanicalReduction>
    </actuator>
  </transmission>
  <link name="r_Ptip">
    <inertial>
      <origin rpy="0 0 0" xyz="-0.00506265913629 0.000159136938405 -0.00949076905022"/>
      <mass value="0.00398141"/>
      <inertia ixx="2.27393e-07" ixy="-4.487e-12" ixz="-6.19169e-12" iyy="2.50732e-07" iyz="3.7689e-09" izz="1.09262e-07"/>
    </inertial>
    <visual>
      <origin rpy="0 0 0" xyz="-0.00506254619728 0 1.00217221743e-07"/>
      <geometry>
        <mesh filename="/export/home/strahl/dev/gaikpy/resources/urdf/nicol/meshes/RH8D/right/tip.stl" scale="0.001 0.001 0.001"/>
      </geometry>
      <material name="Ptip_color">
        <color rgba="0.74902 0.74902 0.74902 1.0"/>
      </material>
    </visual>
    <collision>
      <origin rpy="0 0 0" xyz="-0.00506254619728 0 1.00217221743e-07"/>
      <geometry>
        <mesh filename="/export/home/strahl/dev/gaikpy/resources/urdf/nicol/meshes/RH8D/right/tip.stl" scale="0.001 0.001 0.001"/>
      </geometry>
    </collision>
  </link>
  <!-- joint r_Ptip__Pmiddle -->
  <joint name="r_jointL3" type="revolute">
    <origin rpy="-0.0872659042327 2.27460324884e-07 1.07985789158e-07" xyz="0 0 -0.0258752741659"/>
    <axis xyz="-0.999999718358 -1.14467305121e-07 -5.48468494399e-07"/>
    <parent link="r_Pmiddle"/>
    <child link="r_Ptip"/>
    <limit effort="0.5" lower="0.0" upper="1.4835298642" velocity="1.0"/>
    <dynamics damping="0.001"/>
  </joint>
  <transmission name="tranr_L3">
    <type>transmission_interface/SimpleTransmission</type>
    <joint name="r_jointL3">
      <hardwareInterface>hardware_interface/PositionJointInterface</hardwareInterface>
    </joint>
    <actuator name="motorr_L3">
      <hardwareInterface>hardware_interface/PositionJointInterface</hardwareInterface>
      <mechanicalReduction>1</mechanicalReduction>
    </actuator>
  </transmission>
  <!-- Thumb -->
  <link name="r_thumb base">
    <inertial>
      <origin rpy="0 0 0" xyz="5.41241550495e-07 0.0139591752938 0.00025370998152"/>
      <mass value="0.00705621"/>
      <inertia ixx="5.42596e-07" ixy="4.46196e-11" ixz="-1.43331e-11" iyy="3.55499e-07" iyz="4.00664e-08" izz="5.38335e-07"/>
    </inertial>
    <visual>
      <origin rpy="0 0 0" xyz="0 0.0145002326896 2.12529551097e-07"/>
      <geometry>
        <mesh filename="/export/home/strahl/dev/gaikpy/resources/urdf/nicol/meshes/RH8D/right/thumb.stl" scale="0.001 0.001 0.001"/>
      </geometry>
      <material name="thumb base_color">
        <color rgba="0.74902 0.74902 0.74902 1.0"/>
      </material>
    </visual>
    <collision>
      <origin rpy="0 0 0" xyz="0 0.0145002326896 2.12529551097e-07"/>
      <geometry>
        <mesh filename="/export/home/strahl/dev/gaikpy/resources/urdf/nicol/meshes/RH8D/right/thumb.stl" scale="0.001 0.001 0.001"/>
      </geometry>
    </collision>
  </link>
  <!-- joint palm_thumb_base -->
  <joint name="r_jointT0" type="revolute">
    <origin rpy="-1.75712148701 1.30427457179 2.16321531663" xyz="-0.0132983 -0.013942 0.0090401"/>
    <axis xyz="7.47739294649e-08 -1.00000039555 -1.69572095365e-07"/>
    <parent link="r_palm"/>
    <child link="r_thumb base"/>
    <limit effort="0.5" lower="0.0" upper="1.57079632679" velocity="1.0"/>
    <dynamics damping="0.01"/>
  </joint>
  <transmission name="tranr_T0">
    <type>transmission_interface/SimpleTransmission</type>
    <joint name="r_jointT0">
      <hardwareInterface>hardware_interface/PositionJointInterface</hardwareInterface>
    </joint>
    <actuator name="motorr_T0">
      <hardwareInterface>hardware_interface/PositionJointInterface</hardwareInterface>
      <mechanicalReduction>1</mechanicalReduction>
    </actuator>
  </transmission>
  <link name="r_Tproximal">
    <inertial>
      <origin rpy="0 0 0" xyz="-0.00509118037371 -0.000108367330619 -0.00917567646424"/>
      <mass value="0.00379261"/>
      <inertia ixx="3.44891e-07" ixy="-5.85841e-09" ixz="-1.40349e-09" iyy="2.90581e-07" iyz="-9.57879e-09" izz="2.1814e-07"/>
    </inertial>
    <visual>
      <origin rpy="0 0 0" xyz="-0.00506247937312 1.51098425411e-07 -0.00864845498031"/>
      <geometry>
        <mesh filename="/export/home/strahl/dev/gaikpy/resources/urdf/nicol/meshes/RH8D/right/seg_M.stl" scale="0.001 0.001 0.001"/>
      </geometry>
      <material name="Tproximal_color">
        <color rgba="0.74902 0.74902 0.74902 1.0"/>
      </material>
    </visual>
    <collision>
      <origin rpy="0 0 0" xyz="-0.00506247937312 1.51098425411e-07 -0.00864845498031"/>
      <geometry>
        <mesh filename="/export/home/strahl/dev/gaikpy/resources/urdf/nicol/meshes/RH8D/right/seg_M.stl" scale="0.001 0.001 0.001"/>
      </geometry>
    </collision>
  </link>
  <!-- joint r_Tproximal_thumb_base -->
  <joint name="r_jointT1" type="revolute">
    <origin rpy="-2.69572490984 0 -3.23524184915e-07" xyz="0.00506271141921 0.00574726795841 0.0111638055054"/>
    <axis xyz="-1.00000015905 4.04301755325e-07 -1.03967894405e-07"/>
    <parent link="r_thumb base"/>
    <child link="r_Tproximal"/>
    <limit effort="0.5" lower="0.0" upper="1.57079632679" velocity="1.0"/>
    <dynamics damping="0.01"/>
  </joint>
  <transmission name="tranr_T1">
    <type>transmission_interface/SimpleTransmission</type>
    <joint name="r_jointT1">
      <hardwareInterface>hardware_interface/PositionJointInterface</hardwareInterface>
    </joint>
    <actuator name="motorr_T1">
      <hardwareInterface>hardware_interface/PositionJointInterface</hardwareInterface>
      <mechanicalReduction>1</mechanicalReduction>
    </actuator>
  </transmission>
  <link name="r_Tmiddle">
    <inertial>
      <origin rpy="0 0 0" xyz="-0.00509145714593 -0.000109508075581 -0.00917619264503"/>
      <mass value="0.00379261"/>
      <inertia ixx="3.44891e-07" ixy="-5.85841e-09" ixz="-1.40349e-09" iyy="2.90581e-07" iyz="-9.57879e-09" izz="2.1814e-07"/>
    </inertial>
    <visual>
      <origin rpy="0 0 0" xyz="-0.00506255005155 -3.30490933204e-07 -0.00864867274502"/>
      <geometry>
        <mesh filename="/export/home/strahl/dev/gaikpy/resources/urdf/nicol/meshes/RH8D/right/seg_M.stl" scale="0.001 0.001 0.001"/>
      </geometry>
      <material name="Tmiddle_color">
        <color rgba="0.74902 0.74902 0.74902 1.0"/>
      </material>
    </visual>
    <collision>
      <origin rpy="0 0 0" xyz="-0.00506255005155 -3.30490933204e-07 -0.00864867274502"/>
      <geometry>
        <mesh filename="/export/home/strahl/dev/gaikpy/resources/urdf/nicol/meshes/RH8D/right/seg_M.stl" scale="0.001 0.001 0.001"/>
      </geometry>
    </collision>
  </link>
  <!-- joint Tmiddle__r_Tproximal -->
  <joint name="r_jointT2" type="revolute">
    <origin rpy="-0.00953533375442 -2.2361018211e-07 -5.28725690007e-07" xyz="1.61327491782e-07 6.88063125837e-07 -0.0215856949813"/>
    <axis xyz="-1.00000015905 -1.25559174474e-07 1.18450477621e-07"/>
    <parent link="r_Tproximal"/>
    <child link="r_Tmiddle"/>
    <limit effort="0.5" lower="0.0" upper="1.57079632679" velocity="1.0"/>
    <dynamics damping="0.001"/>
  </joint>
  <transmission name="tranr_T2">
    <type>transmission_interface/SimpleTransmission</type>
    <joint name="r_jointT2">
      <hardwareInterface>hardware_interface/PositionJointInterface</hardwareInterface>
    </joint>
    <actuator name="motorr_T2">
      <hardwareInterface>hardware_interface/PositionJointInterface</hardwareInterface>
      <mechanicalReduction>1</mechanicalReduction>
    </actuator>
  </transmission>
  <link name="r_Ttip">
    <inertial>
      <origin rpy="0 0 0" xyz="-0.00506285640086 0.000158437874597 -0.00949116013742"/>
      <mass value="0.00398141"/>
      <inertia ixx="2.27393e-07" ixy="-4.487e-12" ixz="-6.19169e-12" iyy="2.50732e-07" iyz="3.7689e-09" izz="1.09262e-07"/>
    </inertial>
    <visual>
      <origin rpy="0 0 0" xyz="-0.00506272959909 -7.78884574837e-07 -2.9976296162e-07"/>
      <geometry>
        <mesh filename="/export/home/strahl/dev/gaikpy/resources/urdf/nicol/meshes/RH8D/right/tip.stl" scale="0.001 0.001 0.001"/>
      </geometry>
      <material name="Ttip_color">
        <color rgba="0.74902 0.74902 0.74902 1.0"/>
      </material>
    </visual>
    <collision>
      <origin rpy="0 0 0" xyz="-0.00506272959909 -7.78884574837e-07 -2.9976296162e-07"/>
      <geometry>
        <mesh filename="/export/home/strahl/dev/gaikpy/resources/urdf/nicol/meshes/RH8D/right/tip.stl" scale="0.001 0.001 0.001"/>
      </geometry>
    </collision>
  </link>
  <!-- joint r_Ttip__T2 -->
  <joint name="r_jointT3" type="revolute">
    <origin rpy="0 0 0" xyz="0 1.28178098219e-07 -0.0215859563877"/>
    <axis xyz="-1.00000015905 -1.25559174474e-07 1.18450477621e-07"/>
    <parent link="r_Tmiddle"/>
    <child link="r_Ttip"/>
    <limit effort="0.5" lower="0.0" upper="1.57079632679" velocity="1.0"/>
    <dynamics damping="0.001"/>
  </joint>
  <transmission name="tranr_T3">
    <type>transmission_interface/SimpleTransmission</type>
    <joint name="r_jointT3">
      <hardwareInterface>hardware_interface/PositionJointInterface</hardwareInterface>
    </joint>
    <actuator name="motorr_T3">
      <hardwareInterface>hardware_interface/PositionJointInterface</hardwareInterface>
      <mechanicalReduction>1</mechanicalReduction>
    </actuator>
  </transmission>
  <!-- Index finger -->
  <link name="r_Iproximal">
    <inertial>
      <origin rpy="0 0 0" xyz="-0.00506269303095 0.000178661194879 -0.0113960183486"/>
      <mass value="0.0046468"/>
      <inertia ixx="3.60659e-07" ixy="2.95375e-10" ixz="3.96643e-12" iyy="4.02251e-07" iyz="7.4602e-09" izz="1.59669e-07"/>
    </inertial>
    <visual>
      <origin rpy="0 0 0" xyz="0.00532665437356 -0.00134306865084 -0.0128298343462"/>
      <geometry>
        <mesh filename="/export/home/strahl/dev/gaikpy/resources/urdf/nicol/meshes/RH8D/right/seg_L.stl" scale="0.001 0.001 0.001"/>
      </geometry>
      <material name="Iproximal_color">
        <color rgba="0.74902 0.74902 0.74902 1.0"/>
      </material>
    </visual>
    <collision>
      <origin rpy="0 0 0" xyz="0.00532665437356 -0.00134306865084 -0.0128298343462"/>
      <geometry>
        <mesh filename="/export/home/strahl/dev/gaikpy/resources/urdf/nicol/meshes/RH8D/right/seg_L.stl" scale="0.001 0.001 0.001"/>
      </geometry>
    </collision>
  </link>
  <!-- joint r_Iproximal__palm -->
  <joint name="r_jointI1" type="revolute">
    <origin rpy="-1.84942615384 0.155854888307 -0.117563434836" xyz="-0.0053425 -0.081883 0.00351788"/>
    <axis xyz="-0.999999806433 -3.11064646163e-07 -1.92575397934e-07"/>
    <parent link="r_palm"/>
    <child link="r_Iproximal"/>
    <limit effort="0.5" lower="0.0" upper="1.4835298642" velocity="1.0"/>
    <dynamics damping="0.01"/>
  </joint>
  <transmission name="tranr_I1">
    <type>transmission_interface/SimpleTransmission</type>
    <joint name="r_jointI1">
      <hardwareInterface>hardware_interface/PositionJointInterface</hardwareInterface>
    </joint>
    <actuator name="motorr_I1">
      <hardwareInterface>hardware_interface/PositionJointInterface</hardwareInterface>
      <mechanicalReduction>1</mechanicalReduction>
    </actuator>
  </transmission>
  <link name="r_Imiddle">
    <inertial>
      <origin rpy="0 0 0" xyz="-0.00506266070615 0.000178528721729 -0.0113957955067"/>
      <mass value="0.0046468"/>
      <inertia ixx="3.60659e-07" ixy="2.95375e-10" ixz="3.96643e-12" iyy="4.02251e-07" iyz="7.4602e-09" izz="1.59669e-07"/>
    </inertial>
    <visual>
      <origin rpy="0 0 0" xyz="0.00532665674393 -0.00134322760034 -0.012829627881"/>
      <geometry>
        <mesh filename="/export/home/strahl/dev/gaikpy/resources/urdf/nicol/meshes/RH8D/right/seg_L.stl" scale="0.001 0.001 0.001"/>
      </geometry>
      <material name="Imiddle_color">
        <color rgba="0.74902 0.74902 0.74902 1.0"/>
      </material>
    </visual>
    <collision>
      <origin rpy="0 0 0" xyz="0.00532665674393 -0.00134322760034 -0.012829627881"/>
      <geometry>
        <mesh filename="/export/home/strahl/dev/gaikpy/resources/urdf/nicol/meshes/RH8D/right/seg_L.stl" scale="0.001 0.001 0.001"/>
      </geometry>
    </collision>
  </link>
  <!-- joint Imiddle__L1imal -->
  <joint name="r_jointI2" type="revolute">
    <origin rpy="-0.0872662181335 -6.1944905734e-07 4.44119679405e-07" xyz="0 0 -0.0258750517122"/>
    <axis xyz="-0.999999806433 9.5344259203e-08 4.3684563622e-07"/>
    <parent link="r_Iproximal"/>
    <child link="r_Imiddle"/>
    <limit effort="0.5" lower="0.0" upper="1.4835298642" velocity="1.0"/>
    <dynamics damping="0.001"/>
  </joint>
  <transmission name="tranr_I2">
    <type>transmission_interface/SimpleTransmission</type>
    <joint name="r_jointI2">
      <hardwareInterface>hardware_interface/PositionJointInterface</hardwareInterface>
    </joint>
    <actuator name="motorr_I2">
      <hardwareInterface>hardware_interface/PositionJointInterface</hardwareInterface>
      <mechanicalReduction>1</mechanicalReduction>
    </actuator>
  </transmission>
  <link name="r_Itip">
    <inertial>
      <origin rpy="0 0 0" xyz="-0.00506271582253 0.000159256228073 -0.00949120545948"/>
      <mass value="0.00398141"/>
      <inertia ixx="2.27393e-07" ixy="-4.487e-12" ixz="-6.19169e-12" iyy="2.50732e-07" iyz="3.7689e-09" izz="1.09262e-07"/>
    </inertial>
    <visual>
      <origin rpy="0 0 0" xyz="-0.00506242530965 1.78928126315e-07 -5.67587439049e-07"/>
      <geometry>
        <mesh filename="/export/home/strahl/dev/gaikpy/resources/urdf/nicol/meshes/RH8D/right/tip.stl" scale="0.001 0.001 0.001"/>
      </geometry>
      <material name="Itip_color">
        <color rgba="0.74902 0.74902 0.74902 1.0"/>
      </material>
    </visual>
    <collision>
      <origin rpy="0 0 0" xyz="-0.00506242530965 1.78928126315e-07 -5.67587439049e-07"/>
      <geometry>
        <mesh filename="/export/home/strahl/dev/gaikpy/resources/urdf/nicol/meshes/RH8D/right/tip.stl" scale="0.001 0.001 0.001"/>
      </geometry>
    </collision>
  </link>
  <!-- joint Itip__L2 -->
  <joint name="r_jointI3" type="revolute">
    <origin rpy="-0.0872665348444 1.37808199802e-07 -5.71018688354e-07" xyz="0 0 -0.0258750542774"/>
    <axis xyz="-0.999999806433 -4.99927084681e-07 2.56441750668e-07"/>
    <parent link="r_Imiddle"/>
    <child link="r_Itip"/>
    <limit effort="0.5" lower="0.0" upper="1.4835298642" velocity="1.0"/>
    <dynamics damping="0.001"/>
  </joint>
  <transmission name="tranr_I3">
    <type>transmission_interface/SimpleTransmission</type>
    <joint name="r_jointI3">
      <hardwareInterface>hardware_interface/PositionJointInterface</hardwareInterface>
    </joint>
    <actuator name="motorr_I3">
      <hardwareInterface>hardware_interface/PositionJointInterface</hardwareInterface>
      <mechanicalReduction>1</mechanicalReduction>
    </actuator>
  </transmission>
  <!-- link 1 -->
  <link name="r_link1">
    <collision>
      <origin rpy="0 0 0" xyz="0 0 0"/>
      <geometry>
        <mesh filename="/export/home/strahl/dev/gaikpy/resources/urdf/nicol/meshes/open_manipulator/link_1.stl" scale="0.001 0.001 0.001"/>
      </geometry>
    </collision>
    <visual>
      <origin rpy="0 0 0" xyz="0 0 0"/>
      <geometry>
        <mesh filename="/export/home/strahl/dev/gaikpy/resources/urdf/nicol/meshes/open_manipulator/link_1.stl" scale="0.001 0.001 0.001"/>
      </geometry>
      <material name="grey"/>
    </visual>
    <inertial>
      <origin rpy="0 0 0" xyz="0.00023 0.00000 0.06223"/>
      <mass value="0.85644"/>
      <inertia ixx="1.0" ixy="0.0" ixz="0.0" iyy="1.0" iyz="0.0" izz="1.0"/>
      <!--<inertia ixx="0.00121064" ixy="0.0" ixz="0.00001100" iyy="0.00120886" iyz="0.0" izz="0.00038103" />-->
    </inertial>
  </link>
  <!-- Joint 1 -->
  <joint name="r_joint1" type="revolute">
    <parent link="r_link1"/>
    <child link="r_link2"/>
    <origin rpy="0 0 3.14159265359" xyz="0.0 0.0 0.126"/>
    <axis xyz="0 0 1"/>
    <limit effort="1000" lower="-1.57079632679" upper="1.57079632679" velocity="6.5"/>
    <dynamics damping="0.7"/>
    <!-- <safety_controller k_velocity="10" k_position="15" soft_lower_limit="-2.0" soft_upper_limit="0.5" /> -->
  </joint>
  <transmission name="tranr_1">
    <type>transmission_interface/SimpleTransmission</type>
    <joint name="r_joint1">
      <hardwareInterface>hardware_interface/PositionJointInterface</hardwareInterface>
    </joint>
    <actuator name="motorr_1">
      <hardwareInterface>hardware_interface/PositionJointInterface</hardwareInterface>
      <mechanicalReduction>1</mechanicalReduction>
    </actuator>
  </transmission>
  <!-- link 2 -->
  <link name="r_link2">
    <collision>
      <origin rpy="0 0 0" xyz="0 0 0"/>
      <geometry>
        <mesh filename="/export/home/strahl/dev/gaikpy/resources/urdf/nicol/meshes/open_manipulator/link_2.stl" scale="0.001 0.001 0.001"/>
      </geometry>
    </collision>
    <visual>
      <origin rpy="0 0 0" xyz="0 0 0"/>
      <geometry>
        <mesh filename="/export/home/strahl/dev/gaikpy/resources/urdf/nicol/meshes/open_manipulator/link_2.stl" scale="0.001 0.001 0.001"/>
      </geometry>
      <material name="grey"/>
    </visual>
    <inertial>
      <origin rpy="0 0 0" xyz="0.00000 0.00080 0.03183"/>
      <!--<origin xyz="0.00000 -0.06820 -0.00117" rpy="0 0 0"/>-->
      <mass value="0.94658"/>
      <inertia ixx="1.0" ixy="0.0" ixz="0.0" iyy="1.0" iyz="0.0" izz="1.0"/>
      <!--<inertia ixx="0.00152547" ixy="0.0" ixz="0.0" iyy="0.00045954" iyz="-0.00001086" izz="0.00151740" />-->
    </inertial>
  </link>
  <!-- Joint 2 -->
  <joint name="r_joint2" type="revolute">
    <parent link="r_link2"/>
    <child link="r_link3"/>
    <origin rpy="0 0 0" xyz="0.0 0.069 0.033"/>
    <axis xyz="0 1 0"/>
    <limit effort="1000" lower="-1.57079632679" upper="1.57079632679" velocity="6.5"/>
    <dynamics damping="0.7"/>
  </joint>
  <transmission name="tranr_2">
    <type>transmission_interface/SimpleTransmission</type>
    <joint name="r_joint2">
      <hardwareInterface>hardware_interface/PositionJointInterface</hardwareInterface>
    </joint>
    <actuator name="motorr_2">
      <hardwareInterface>hardware_interface/PositionJointInterface</hardwareInterface>
      <mechanicalReduction>1</mechanicalReduction>
    </actuator>
  </transmission>
  <!-- link 3 -->
  <link name="r_link3">
    <collision>
      <origin rpy="0 0 0" xyz="0 0 0"/>
      <geometry>
        <mesh filename="/export/home/strahl/dev/gaikpy/resources/urdf/nicol/meshes/open_manipulator/link_3.stl" scale="0.001 0.001 0.001"/>
      </geometry>
    </collision>
    <visual>
      <origin rpy="0 0 0" xyz="0 0 0"/>
      <geometry>
        <mesh filename="/export/home/strahl/dev/gaikpy/resources/urdf/nicol/meshes/open_manipulator/link_3.stl" scale="0.001 0.001 0.001"/>
      </geometry>
      <material name="grey"/>
    </visual>
    <inertial>
      <origin rpy="0 0 0" xyz="0.01768 -0.06881 0.20524"/>
      <!--<origin xyz="-0.01232 -0.05731 -0.05876" rpy="0 0 0"/>-->
      <mass value="1.30260"/>
      <inertia ixx="1.0" ixy="0.0" ixz="0.0" iyy="1.0" iyz="0.0" izz="1.0"/>
      <!--<inertia ixx="0.01111021" ixy="0.00001331" ixz="-0.00134208" iyy="0.01046642" iyz="0.00016235" izz="0.00202081" />-->
    </inertial>
  </link>
  <!-- Joint 3 -->
  <joint name="r_joint3" type="revolute">
    <parent link="r_link3"/>
    <child link="r_link4"/>
    <origin rpy="0 0 0" xyz="0.03000 -0.01150 0.26400"/>
    <axis xyz="0 1 0"/>
    <limit effort="1000" lower="-1.57079632679" upper="1.57079632679" velocity="6.5"/>
    <dynamics damping="0.7"/>
  </joint>
  <transmission name="tranr_3">
    <type>transmission_interface/SimpleTransmission</type>
    <joint name="r_joint3">
      <hardwareInterface>hardware_interface/PositionJointInterface</hardwareInterface>
    </joint>
    <actuator name="motorr_3">
      <hardwareInterface>hardware_interface/PositionJointInterface</hardwareInterface>
      <mechanicalReduction>1</mechanicalReduction>
    </actuator>
  </transmission>
  <!-- link 4 -->
  <link name="r_link4">
    <collision>
      <origin rpy="0 0 0" xyz="0 0 0"/>
      <geometry>
        <mesh filename="/export/home/strahl/dev/gaikpy/resources/urdf/nicol/meshes/open_manipulator/link_4.stl" scale="0.001 0.001 0.001"/>
      </geometry>
    </collision>
    <visual>
      <origin rpy="0 0 0" xyz="0 0 0"/>
      <geometry>
        <mesh filename="/export/home/strahl/dev/gaikpy/resources/urdf/nicol/meshes/open_manipulator/link_4.stl" scale="0.001 0.001 0.001"/>
      </geometry>
      <material name="grey"/>
    </visual>
    <inertial>
      <origin rpy="0 0 0" xyz="0.12475 -0.05716 0.02979"/>
      <!--<origin xyz="-0.07025 0.00034 -0.00021" rpy="0 0 0"/>-->
      <mass value="1.15977"/>
      <inertia ixx="1.0" ixy="0.0" ixz="0.0" iyy="1.0" iyz="0.0" izz="1.0"/>
      <!--<inertia ixx="0.00096726" ixy="0.00004383" ixz="-0.00002771" iyy="0.00318801" iyz="0.00000627" izz="0.00341484" />-->
    </inertial>
  </link>
  <!-- Joint 4 -->
  <joint name="r_joint4" type="revolute">
    <parent link="r_link4"/>
    <child link="r_link5"/>
    <origin rpy="0 0 0" xyz="0.19500 -0.05750 0.03000"/>
    <axis xyz="1 0 0"/>
    <limit effort="1000" lower="-1.57079632679" upper="1.57079632679" velocity="6.5"/>
    <dynamics damping="0.1"/>
  </joint>
  <transmission name="tranr_4">
    <type>transmission_interface/SimpleTransmission</type>
    <joint name="r_joint4">
      <hardwareInterface>hardware_interface/PositionJointInterface</hardwareInterface>
    </joint>
    <actuator name="motorr_4">
      <hardwareInterface>hardware_interface/PositionJointInterface</hardwareInterface>
      <mechanicalReduction>1</mechanicalReduction>
    </actuator>
  </transmission>
  <!-- link 5 -->
  <link name="r_link5">
    <collision>
      <origin rpy="0 0 0" xyz="0 0 0"/>
      <geometry>
        <mesh filename="/export/home/strahl/dev/gaikpy/resources/urdf/nicol/meshes/open_manipulator/link_5.stl" scale="0.001 0.001 0.001"/>
      </geometry>
    </collision>
    <visual>
      <origin rpy="0 0 0" xyz="0 0 0"/>
      <geometry>
        <mesh filename="/export/home/strahl/dev/gaikpy/resources/urdf/nicol/meshes/open_manipulator/link_5.stl" scale="0.001 0.001 0.001"/>
      </geometry>
      <material name="grey"/>
    </visual>
    <inertial>
      <origin rpy="0 0 0" xyz="0.05642 -0.00217 0.00002"/>
      <!--<origin xyz="-0.00658 -0.04717 0.00002" rpy="0 0 0"/>-->
      <mass value="0.44688"/>
      <inertia ixx="1.0" ixy="0.0" ixz="0.0" iyy="1.0" iyz="0.0" izz="1.0"/>
      <!--<inertia ixx="0.00030285" ixy="0.00000761" ixz="0.00000031" iyy="0.00022339" iyz="-0.00000001" izz="0.00039766" />-->
    </inertial>
  </link>
  <!-- Joint 5 -->
  <joint name="r_joint5" type="revolute">
    <parent link="r_link5"/>
    <child link="r_link6"/>
    <origin rpy="0 0 0" xyz="0.06300 0.04500 0.00000"/>
    <axis xyz="0 1 0"/>
    <limit effort="1000" lower="-1.57079632679" upper="1.57079632679" velocity="6.5"/>
    <dynamics damping="0.1"/>
  </joint>
  <transmission name="tranr_5">
    <type>transmission_interface/SimpleTransmission</type>
    <joint name="r_joint5">
      <hardwareInterface>hardware_interface/PositionJointInterface</hardwareInterface>
    </joint>
    <actuator name="motorr_5">
      <hardwareInterface>hardware_interface/PositionJointInterface</hardwareInterface>
      <mechanicalReduction>1</mechanicalReduction>
    </actuator>
  </transmission>
  <!-- link 6 -->
  <link name="r_link6">
    <collision>
      <origin rpy="0 0 0" xyz="0 0 0"/>
      <geometry>
        <mesh filename="/export/home/strahl/dev/gaikpy/resources/urdf/nicol/meshes/open_manipulator/link_6.stl" scale="0.001 0.001 0.001"/>
      </geometry>
    </collision>
    <visual>
      <origin rpy="0 0 0" xyz="0 0 0"/>
      <geometry>
        <mesh filename="/export/home/strahl/dev/gaikpy/resources/urdf/nicol/meshes/open_manipulator/link_6.stl" scale="0.001 0.001 0.001"/>
      </geometry>
      <material name="grey"/>
    </visual>
    <inertial>
      <origin rpy="0 0 0" xyz="0.06831 -0.04457 0.00000"/>
      <!--<origin xyz="-0.05469 0.00043 0.00000" rpy="0 0 0"/>-->
      <mass value="0.43273"/>
      <inertia ixx="1.0" ixy="0.0" ixz="0.0" iyy="1.0" iyz="0.0" izz="1.0"/>
      <!--<inertia ixx="0.00021512" ixy="0.00001009" ixz="0.00000000" iyy="0.00042827" iyz="0.00000000" izz="0.00051436" />-->
    </inertial>
  </link>
  <!-- Joint 6 connects to hand base-->
  <joint name="r_joint6" type="revolute">
    <parent link="r_link6"/>
    <child link="r_RH8D_base"/>
    <origin rpy="0 1.57079632679 1.57079632679" xyz="0.12300 -0.04500 0.00000"/>
    <axis xyz="0 1 0"/>
    <limit effort="1000" lower="-1.57079632679" upper="1.57079632679" velocity="6.5"/>
    <dynamics damping="0.1"/>
  </joint>
  <transmission name="tranr_6">
    <type>transmission_interface/SimpleTransmission</type>
    <joint name="r_joint6">
      <hardwareInterface>hardware_interface/PositionJointInterface</hardwareInterface>
    </joint>
    <actuator name="motorr_6">
      <hardwareInterface>hardware_interface/PositionJointInterface</hardwareInterface>
      <mechanicalReduction>1</mechanicalReduction>
    </actuator>
  </transmission>
  <gazebo>
    <plugin filename="libgazebo_ros_control.so" name="gazebo_ros_control">
      <robotNamespace>right/open_manipulator_p</robotNamespace>
      <robotSimType>gazebo_ros_control/DefaultRobotHWSim</robotSimType>
    </plugin>
  </gazebo>
  <gazebo reference="r_link1">
    <!-- <kp>1000000.0</kp>
      <kd>100.0</kd> 
      <mu1>30.0</mu1>
      <mu2>30.0</mu2>
      <maxVel>1.0</maxVel>
      <minDepth>0.001</minDepth> -->
    <mu1>0.20</mu1>
    <mu2>0.20</mu2>
    <material>Gazebo/DarkGrey</material>
  </gazebo>
  <gazebo reference="r_link2">
    <!-- <kp>1000000.0</kp>
      <kd>100.0</kd> 
      <mu1>30.0</mu1>
      <mu2>30.0</mu2>
      <maxVel>1.0</maxVel>
      <minDepth>0.001</minDepth> -->
    <mu1>0.20</mu1>
    <mu2>0.20</mu2>
    <material>Gazebo/DarkGrey</material>
  </gazebo>
  <gazebo reference="r_link3">
    <!-- <kp>1000000.0</kp>
      <kd>100.0</kd> 
      <mu1>30.0</mu1>
      <mu2>30.0</mu2>
      <maxVel>1.0</maxVel>
      <minDepth>0.001</minDepth> -->
    <mu1>0.20</mu1>
    <mu2>0.20</mu2>
    <material>Gazebo/DarkGrey</material>
  </gazebo>
  <gazebo reference="r_link4">
    <!-- <kp>1000000.0</kp>
      <kd>100.0</kd> 
      <mu1>30.0</mu1>
      <mu2>30.0</mu2>
      <maxVel>1.0</maxVel>
      <minDepth>0.001</minDepth> -->
    <mu1>0.20</mu1>
    <mu2>0.20</mu2>
    <material>Gazebo/DarkGrey</material>
  </gazebo>
  <gazebo reference="r_link5">
    <!-- <kp>1000000.0</kp>
      <kd>100.0</kd> 
      <mu1>30.0</mu1>
      <mu2>30.0</mu2>
      <maxVel>1.0</maxVel>
      <minDepth>0.001</minDepth> -->
    <mu1>0.20</mu1>
    <mu2>0.20</mu2>
    <material>Gazebo/DarkGrey</material>
  </gazebo>
  <gazebo reference="r_link6">
    <!-- <kp>1000000.0</kp>
      <kd>100.0</kd> 
      <mu1>30.0</mu1>
      <mu2>30.0</mu2>
      <maxVel>1.0</maxVel>
      <minDepth>0.001</minDepth> -->
    <mu1>0.20</mu1>
    <mu2>0.20</mu2>
    <material>Gazebo/DarkGrey</material>
  </gazebo>
  <gazebo reference="r_RH8D_base">
    <!-- <kp>1000000.0</kp>
      <kd>100.0</kd>
      <mu1>30.0</mu1>
      <mu2>30.0</mu2>
      <maxVel>1.0</maxVel>
      <minDepth>0.001</minDepth> -->
    <!-- <visual>
        <material>
          <ambient>0.74902 0.74902 0.74902 1.0</ambient>
          <diffuse>0.74902 0.74902 0.74902 1.0</diffuse>
          <specular>0.74902 0.74902 0.74902 1.0</specular>
        </material>
      </visual> -->
    <mu1>0.2</mu1>
    <mu2>0.2</mu2>
    <material>Gazebo/Grey</material>
  </gazebo>
  <gazebo reference="r_forearm">
    <!-- <kp>1000000.0</kp>
      <kd>100.0</kd>
      <mu1>30.0</mu1>
      <mu2>30.0</mu2>
      <maxVel>1.0</maxVel>
      <minDepth>0.001</minDepth> -->
    <!-- <visual>
        <material>
          <ambient>0.74902 0.74902 0.74902 1.0</ambient>
          <diffuse>0.74902 0.74902 0.74902 1.0</diffuse>
          <specular>0.74902 0.74902 0.74902 1.0</specular>
        </material>
      </visual> -->
    <mu1>0.2</mu1>
    <mu2>0.2</mu2>
    <material>Gazebo/Grey</material>
  </gazebo>
  <gazebo reference="r_palm axis">
    <!-- <kp>1000000.0</kp>
      <kd>100.0</kd>
      <mu1>30.0</mu1>
      <mu2>30.0</mu2>
      <maxVel>1.0</maxVel>
      <minDepth>0.001</minDepth> -->
    <!-- <visual>
        <material>
          <ambient>0.74902 0.74902 0.74902 1.0</ambient>
          <diffuse>0.74902 0.74902 0.74902 1.0</diffuse>
          <specular>0.74902 0.74902 0.74902 1.0</specular>
        </material>
      </visual> -->
    <mu1>0.2</mu1>
    <mu2>0.2</mu2>
    <material>Gazebo/Grey</material>
  </gazebo>
  <gazebo reference="r_palm">
    <!-- <kp>1000000.0</kp>
      <kd>100.0</kd>
      <mu1>30.0</mu1>
      <mu2>30.0</mu2>
      <maxVel>1.0</maxVel>
      <minDepth>0.001</minDepth> -->
    <!-- <visual>
        <material>
          <ambient>0.74902 0.74902 0.74902 1.0</ambient>
          <diffuse>0.74902 0.74902 0.74902 1.0</diffuse>
          <specular>0.74902 0.74902 0.74902 1.0</specular>
        </material>
      </visual> -->
    <mu1>0.2</mu1>
    <mu2>0.2</mu2>
    <material>Gazebo/Grey</material>
  </gazebo>
  <gazebo reference="r_Rproximal">
    <!-- <kp>1000000.0</kp>
      <kd>100.0</kd>
      <mu1>30.0</mu1>
      <mu2>30.0</mu2>
      <maxVel>1.0</maxVel>
      <minDepth>0.001</minDepth> -->
    <!-- <visual>
        <material>
          <ambient>0.74902 0.74902 0.74902 1.0</ambient>
          <diffuse>0.74902 0.74902 0.74902 1.0</diffuse>
          <specular>0.74902 0.74902 0.74902 1.0</specular>
        </material>
      </visual> -->
    <mu1>0.2</mu1>
    <mu2>0.2</mu2>
    <material>Gazebo/Grey</material>
  </gazebo>
  <gazebo reference="r_Rmiddle">
    <!-- <kp>1000000.0</kp>
      <kd>100.0</kd>
      <mu1>30.0</mu1>
      <mu2>30.0</mu2>
      <maxVel>1.0</maxVel>
      <minDepth>0.001</minDepth> -->
    <!-- <visual>
        <material>
          <ambient>0.74902 0.74902 0.74902 1.0</ambient>
          <diffuse>0.74902 0.74902 0.74902 1.0</diffuse>
          <specular>0.74902 0.74902 0.74902 1.0</specular>
        </material>
      </visual> -->
    <mu1>0.2</mu1>
    <mu2>0.2</mu2>
    <material>Gazebo/Grey</material>
  </gazebo>
  <gazebo reference="r_Rtip">
    <!-- <kp>1000000.0</kp>
      <kd>100.0</kd>
      <mu1>30.0</mu1>
      <mu2>30.0</mu2>
      <maxVel>1.0</maxVel>
      <minDepth>0.001</minDepth> -->
    <!-- <visual>
        <material>
          <ambient>0.74902 0.74902 0.74902 1.0</ambient>
          <diffuse>0.74902 0.74902 0.74902 1.0</diffuse>
          <specular>0.74902 0.74902 0.74902 1.0</specular>
        </material>
      </visual> -->
    <mu1>0.2</mu1>
    <mu2>0.2</mu2>
    <material>Gazebo/Grey</material>
  </gazebo>
  <gazebo reference="r_Mproximal">
    <!-- <kp>1000000.0</kp>
      <kd>100.0</kd>
      <mu1>30.0</mu1>
      <mu2>30.0</mu2>
      <maxVel>1.0</maxVel>
      <minDepth>0.001</minDepth> -->
    <!-- <visual>
        <material>
          <ambient>0.74902 0.74902 0.74902 1.0</ambient>
          <diffuse>0.74902 0.74902 0.74902 1.0</diffuse>
          <specular>0.74902 0.74902 0.74902 1.0</specular>
        </material>
      </visual> -->
    <mu1>0.2</mu1>
    <mu2>0.2</mu2>
    <material>Gazebo/Grey</material>
  </gazebo>
  <gazebo reference="r_Mmiddle">
    <!-- <kp>1000000.0</kp>
      <kd>100.0</kd>
      <mu1>30.0</mu1>
      <mu2>30.0</mu2>
      <maxVel>1.0</maxVel>
      <minDepth>0.001</minDepth> -->
    <!-- <visual>
        <material>
          <ambient>0.74902 0.74902 0.74902 1.0</ambient>
          <diffuse>0.74902 0.74902 0.74902 1.0</diffuse>
          <specular>0.74902 0.74902 0.74902 1.0</specular>
        </material>
      </visual> -->
    <mu1>0.2</mu1>
    <mu2>0.2</mu2>
    <material>Gazebo/Grey</material>
  </gazebo>
  <gazebo reference="r_Mtip">
    <!-- <kp>1000000.0</kp>
      <kd>100.0</kd>
      <mu1>30.0</mu1>
      <mu2>30.0</mu2>
      <maxVel>1.0</maxVel>
      <minDepth>0.001</minDepth> -->
    <!-- <visual>
        <material>
          <ambient>0.74902 0.74902 0.74902 1.0</ambient>
          <diffuse>0.74902 0.74902 0.74902 1.0</diffuse>
          <specular>0.74902 0.74902 0.74902 1.0</specular>
        </material>
      </visual> -->
    <mu1>0.2</mu1>
    <mu2>0.2</mu2>
    <material>Gazebo/Grey</material>
  </gazebo>
  <gazebo reference="r_Pproximal">
    <!-- <kp>1000000.0</kp>
      <kd>100.0</kd>
      <mu1>30.0</mu1>
      <mu2>30.0</mu2>
      <maxVel>1.0</maxVel>
      <minDepth>0.001</minDepth> -->
    <!-- <visual>
        <material>
          <ambient>0.74902 0.74902 0.74902 1.0</ambient>
          <diffuse>0.74902 0.74902 0.74902 1.0</diffuse>
          <specular>0.74902 0.74902 0.74902 1.0</specular>
        </material>
      </visual> -->
    <mu1>0.2</mu1>
    <mu2>0.2</mu2>
    <material>Gazebo/Grey</material>
  </gazebo>
  <gazebo reference="r_Pmiddle">
    <!-- <kp>1000000.0</kp>
      <kd>100.0</kd>
      <mu1>30.0</mu1>
      <mu2>30.0</mu2>
      <maxVel>1.0</maxVel>
      <minDepth>0.001</minDepth> -->
    <!-- <visual>
        <material>
          <ambient>0.74902 0.74902 0.74902 1.0</ambient>
          <diffuse>0.74902 0.74902 0.74902 1.0</diffuse>
          <specular>0.74902 0.74902 0.74902 1.0</specular>
        </material>
      </visual> -->
    <mu1>0.2</mu1>
    <mu2>0.2</mu2>
    <material>Gazebo/Grey</material>
  </gazebo>
  <gazebo reference="r_Ptip">
    <!-- <kp>1000000.0</kp>
      <kd>100.0</kd>
      <mu1>30.0</mu1>
      <mu2>30.0</mu2>
      <maxVel>1.0</maxVel>
      <minDepth>0.001</minDepth> -->
    <!-- <visual>
        <material>
          <ambient>0.74902 0.74902 0.74902 1.0</ambient>
          <diffuse>0.74902 0.74902 0.74902 1.0</diffuse>
          <specular>0.74902 0.74902 0.74902 1.0</specular>
        </material>
      </visual> -->
    <mu1>0.2</mu1>
    <mu2>0.2</mu2>
    <material>Gazebo/Grey</material>
  </gazebo>
  <gazebo reference="r_thumb base">
    <!-- <kp>1000000.0</kp>
      <kd>100.0</kd>
      <mu1>30.0</mu1>
      <mu2>30.0</mu2>
      <maxVel>1.0</maxVel>
      <minDepth>0.001</minDepth> -->
    <!-- <visual>
        <material>
          <ambient>0.74902 0.74902 0.74902 1.0</ambient>
          <diffuse>0.74902 0.74902 0.74902 1.0</diffuse>
          <specular>0.74902 0.74902 0.74902 1.0</specular>
        </material>
      </visual> -->
    <mu1>0.2</mu1>
    <mu2>0.2</mu2>
    <material>Gazebo/Grey</material>
  </gazebo>
  <gazebo reference="r_Tproximal">
    <!-- <kp>1000000.0</kp>
      <kd>100.0</kd>
      <mu1>30.0</mu1>
      <mu2>30.0</mu2>
      <maxVel>1.0</maxVel>
      <minDepth>0.001</minDepth> -->
    <!-- <visual>
        <material>
          <ambient>0.74902 0.74902 0.74902 1.0</ambient>
          <diffuse>0.74902 0.74902 0.74902 1.0</diffuse>
          <specular>0.74902 0.74902 0.74902 1.0</specular>
        </material>
      </visual> -->
    <mu1>0.2</mu1>
    <mu2>0.2</mu2>
    <material>Gazebo/Grey</material>
  </gazebo>
  <gazebo reference="r_Tmiddle">
    <!-- <kp>1000000.0</kp>
      <kd>100.0</kd>
      <mu1>30.0</mu1>
      <mu2>30.0</mu2>
      <maxVel>1.0</maxVel>
      <minDepth>0.001</minDepth> -->
    <!-- <visual>
        <material>
          <ambient>0.74902 0.74902 0.74902 1.0</ambient>
          <diffuse>0.74902 0.74902 0.74902 1.0</diffuse>
          <specular>0.74902 0.74902 0.74902 1.0</specular>
        </material>
      </visual> -->
    <mu1>0.2</mu1>
    <mu2>0.2</mu2>
    <material>Gazebo/Grey</material>
  </gazebo>
  <gazebo reference="r_Ttip">
    <!-- <kp>1000000.0</kp>
      <kd>100.0</kd>
      <mu1>30.0</mu1>
      <mu2>30.0</mu2>
      <maxVel>1.0</maxVel>
      <minDepth>0.001</minDepth> -->
    <!-- <visual>
        <material>
          <ambient>0.74902 0.74902 0.74902 1.0</ambient>
          <diffuse>0.74902 0.74902 0.74902 1.0</diffuse>
          <specular>0.74902 0.74902 0.74902 1.0</specular>
        </material>
      </visual> -->
    <mu1>0.2</mu1>
    <mu2>0.2</mu2>
    <material>Gazebo/Grey</material>
  </gazebo>
  <gazebo reference="r_Iproximal">
    <!-- <kp>1000000.0</kp>
      <kd>100.0</kd>
      <mu1>30.0</mu1>
      <mu2>30.0</mu2>
      <maxVel>1.0</maxVel>
      <minDepth>0.001</minDepth> -->
    <!-- <visual>
        <material>
          <ambient>0.74902 0.74902 0.74902 1.0</ambient>
          <diffuse>0.74902 0.74902 0.74902 1.0</diffuse>
          <specular>0.74902 0.74902 0.74902 1.0</specular>
        </material>
      </visual> -->
    <mu1>0.2</mu1>
    <mu2>0.2</mu2>
    <material>Gazebo/Grey</material>
  </gazebo>
  <gazebo reference="r_Imiddle">
    <!-- <kp>1000000.0</kp>
      <kd>100.0</kd>
      <mu1>30.0</mu1>
      <mu2>30.0</mu2>
      <maxVel>1.0</maxVel>
      <minDepth>0.001</minDepth> -->
    <!-- <visual>
        <material>
          <ambient>0.74902 0.74902 0.74902 1.0</ambient>
          <diffuse>0.74902 0.74902 0.74902 1.0</diffuse>
          <specular>0.74902 0.74902 0.74902 1.0</specular>
        </material>
      </visual> -->
    <mu1>0.2</mu1>
    <mu2>0.2</mu2>
    <material>Gazebo/Grey</material>
  </gazebo>
  <gazebo reference="r_Itip">
    <!-- <kp>1000000.0</kp>
      <kd>100.0</kd>
      <mu1>30.0</mu1>
      <mu2>30.0</mu2>
      <maxVel>1.0</maxVel>
      <minDepth>0.001</minDepth> -->
    <!-- <visual>
        <material>
          <ambient>0.74902 0.74902 0.74902 1.0</ambient>
          <diffuse>0.74902 0.74902 0.74902 1.0</diffuse>
          <specular>0.74902 0.74902 0.74902 1.0</specular>
        </material>
      </visual> -->
    <mu1>0.2</mu1>
    <mu2>0.2</mu2>
    <material>Gazebo/Grey</material>
  </gazebo>
  <!-- <gazebo>
    <pose>0.0 0.0 0.0 0.0 0.0 0.0</pose>
  </gazebo> -->
  <gazebo reference="camera_link">
    <sensor name="intel_realsense_d435" type="camera">
      <update_rate>30.0</update_rate>
      <camera name="head">
        <horizontal_fov>1.02974</horizontal_fov>
        <image>
          <width>1920</width>
          <height>1080</height>
          <format>R8G8B8</format>
        </image>
        <clip>
          <near>0.02</near>
          <far>300</far>
        </clip>
        <noise>
          <type>gaussian</type>
          <!-- Noise is sampled independently per pixel on each frame.
                That pixel's noise value is added to each of its color
                channels, which at that point lie in the range [0,1]. -->
          <mean>0.0</mean>
          <stddev>0.007</stddev>
        </noise>
      </camera>
      <plugin filename="libgazebo_ros_camera.so" name="camera_controller">
        <alwaysOn>true</alwaysOn>
        <updateRate>0.0</updateRate>
        <cameraName>camera/color</cameraName>
        <imageTopicName>image_raw</imageTopicName>
        <cameraInfoTopicName>camera_info</cameraInfoTopicName>
        <frameName>camera_link</frameName>
        <hackBaseline>0.07</hackBaseline>
        <distortionK1>0.0</distortionK1>
        <distortionK2>0.0</distortionK2>
        <distortionK3>0.0</distortionK3>
        <distortionT1>0.0</distortionT1>
        <distortionT2>0.0</distortionT2>
      </plugin>
    </sensor>
  </gazebo>
  <!-- Conditional on urdf export, append prefix when merged to one urdf -->
  <!-- <xacro:if value="$(arg export_arg)">
    <xacro:property name="l_joint_export_prefix" value="l_"/>
  </xacro:if>
  <xacro:unless value="$(arg export_arg)"> 
    <xacro:property name="l_joint_export_prefix" value=""/>
  </xacro:unless> -->
  <!-- custom base -->
  <link name="l_RH8D_base">
    <inertial>
      <origin rpy="0 -0.485027 0" xyz="0 -0.0102 0"/>
      <mass value="0.035"/>
      <inertia ixx="7.813e-06" ixy="0" ixz="0" iyy="1.3286e-5" iyz="0" izz="7.813e-06"/>
    </inertial>
    <visual>
      <origin rpy="0 0 0" xyz="0 0 0"/>
      <geometry>
        <mesh filename="/export/home/strahl/dev/gaikpy/resources/urdf/nicol/meshes/RH8D/hand_adapter_base.stl" scale="0.01 0.01 0.01"/>
      </geometry>
      <material name="base_color">
        <color rgba="0.74902 0.74902 0.74902 1.0"/>
      </material>
    </visual>
    <collision>
      <origin rpy="0 0 0" xyz="0 0 0"/>
      <geometry>
        <mesh filename="/export/home/strahl/dev/gaikpy/resources/urdf/nicol/meshes/RH8D/hand_adapter_base.stl" scale="0.01 0.01 0.01"/>
      </geometry>
    </collision>
  </link>
  <link name="l_forearm">
    <inertial>
      <origin rpy="0 0 0" xyz="2.30433000001e-07 -0.0655374 -0.00282708"/>
      <mass value="0.737868"/>
      <inertia ixx="0.0013021" ixy="1.01472e-07" ixz="5.87405e-09" iyy="0.000679239" iyz="-1.22301e-05" izz="0.00145511"/>
    </inertial>
    <visual>
      <origin rpy="0 0 0" xyz="0 0 0"/>
      <geometry>
        <mesh filename="/export/home/strahl/dev/gaikpy/resources/urdf/nicol/meshes/RH8D/left/forearm.stl" scale="0.001 0.001 0.001"/>
      </geometry>
      <material name="l_forearm_color">
        <color rgba="0.74902 0.74902 0.74902 1.0"/>
      </material>
    </visual>
    <collision>
      <origin rpy="0 0 0" xyz="0 0 0"/>
      <geometry>
        <mesh filename="/export/home/strahl/dev/gaikpy/resources/urdf/nicol/meshes/RH8D/left/forearm.stl" scale="0.001 0.001 0.001"/>
      </geometry>
    </collision>
  </link>
  <!-- l_forearm_base joint is fixed in nias version : manipulator joint4 and 6 are used for wrist rot -->
  <joint name="l_forearm__base" type="fixed">
    <origin rpy="0 -1.57079632679 0" xyz="0 -0.019 0.000"/>
    <parent link="l_RH8D_base"/>
    <child link="l_forearm"/>
  </joint>
  <link name="l_palm axis">
    <inertial>
      <origin rpy="0 0 0" xyz="0 0.008585 0.0125"/>
      <mass value="0.0484983"/>
      <inertia ixx="9.46434e-06" ixy="0.0" ixz="0.0" iyy="1.22209e-05" iyz="-2.49433e-17" izz="1.71183e-05"/>
    </inertial>
    <visual>
      <origin rpy="0 0 0" xyz="0 0 0.0125"/>
      <geometry>
        <mesh filename="/export/home/strahl/dev/gaikpy/resources/urdf/nicol/meshes/RH8D/left/palm_axis.stl" scale="0.001 0.001 0.001"/>
      </geometry>
      <material name="l_palm axis_color">
        <color rgba="0.74902 0.74902 0.74902 1.0"/>
      </material>
    </visual>
    <collision>
      <origin rpy="0 0 0" xyz="0 0 0.0125"/>
      <geometry>
        <mesh filename="/export/home/strahl/dev/gaikpy/resources/urdf/nicol/meshes/RH8D/left/palm_axis.stl" scale="0.001 0.001 0.001"/>
      </geometry>
    </collision>
  </link>
  <joint name="l_joint7" type="revolute">
    <origin rpy="0 0 0" xyz="0 -0.165 -0.01275"/>
    <axis xyz="0.0 0.0 -1.0"/>
    <parent link="l_forearm"/>
    <child link="l_palm axis"/>
    <dynamics damping="0.01"/>
    <limit effort="0.5" lower="-0.785398163395" upper="0.785398163395" velocity="1.0"/>
  </joint>
  <transmission name="tranl_7">
    <type>transmission_interface/SimpleTransmission</type>
    <joint name="l_joint7">
      <hardwareInterface>hardware_interface/PositionJointInterface</hardwareInterface>
    </joint>
    <actuator name="motorl_7">
      <hardwareInterface>hardware_interface/PositionJointInterface</hardwareInterface>
      <mechanicalReduction>1</mechanicalReduction>
    </actuator>
  </transmission>
  <link name="l_palm">
    <inertial>
      <origin rpy="0 3.05 0" xyz="-0.02226623 -0.04266 -0.002"/>
      <mass value="0.0886716"/>
      <inertia ixx="3.49499e-05" ixy="1.90978e-06" ixz="3.02331e-06" iyy="5.90827e-05" iyz="-2.26784e-07" izz="8.80157e-05"/>
    </inertial>
    <visual>
      <origin rpy="0 0 0" xyz="-0.0265 0 0"/>
      <geometry>
        <mesh filename="/export/home/strahl/dev/gaikpy/resources/urdf/nicol/meshes/RH8D/left/palmL.stl" scale="0.001 0.001 0.001"/>
      </geometry>
      <material name="l_palm_color">
        <color rgba="0.74902 0.74902 0.74902 1.0"/>
      </material>
    </visual>
    <collision>
      <origin rpy="0 0 0" xyz="-0.0265 0 0"/>
      <geometry>
        <mesh filename="/export/home/strahl/dev/gaikpy/resources/urdf/nicol/meshes/RH8D/left/palmL.stl" scale="0.001 0.001 0.001"/>
      </geometry>
    </collision>
  </link>
  <joint name="l_joint8" type="revolute">
    <origin rpy="3.14159265359 0 3.14159265359" xyz="-0.0265 0 0.0125"/>
    <axis xyz="-1.0 0.0 0.0"/>
    <parent link="l_palm axis"/>
    <child link="l_palm"/>
    <dynamics damping="0.01"/>
    <limit effort="0.5" lower="-0.785398163395" upper="0.785398163395" velocity="1.0"/>
  </joint>
  <transmission name="tranl_8">
    <type>transmission_interface/SimpleTransmission</type>
    <joint name="l_joint8">
      <hardwareInterface>hardware_interface/PositionJointInterface</hardwareInterface>
    </joint>
    <actuator name="motorl_8">
      <hardwareInterface>hardware_interface/PositionJointInterface</hardwareInterface>
      <mechanicalReduction>1</mechanicalReduction>
    </actuator>
  </transmission>
  <!-- Ringfinger -->
  <link name="l_Rproximal">
    <inertial>
      <origin rpy="0 0 0" xyz="-0.00506265498327 0.000178411167835 -0.0113952992502"/>
      <mass value="0.0046468"/>
      <inertia ixx="3.60659e-07" ixy="2.95375e-10" ixz="3.96643e-12" iyy="4.02251e-07" iyz="7.4602e-09" izz="1.59669e-07"/>
    </inertial>
    <visual>
      <origin rpy="0 0 0" xyz="-0.00506240757284 1.38824747468e-07 -0.0129383335759"/>
      <geometry>
        <mesh filename="/export/home/strahl/dev/gaikpy/resources/urdf/nicol/meshes/RH8D/left/phalanx.stl" scale="0.001 0.001 0.001"/>
      </geometry>
      <material name="l_Rproximal_color">
        <color rgba="0.74902 0.74902 0.74902 1.0"/>
      </material>
    </visual>
    <collision>
      <origin rpy="0 0 0" xyz="-0.00506240757284 1.38824747468e-07 -0.0129383335759"/>
      <geometry>
        <mesh filename="/export/home/strahl/dev/gaikpy/resources/urdf/nicol/meshes/RH8D/left/phalanx.stl" scale="0.001 0.001 0.001"/>
      </geometry>
    </collision>
  </link>
  <!-- joint l_Rproximal__palm  -->
  <joint name="l_jointR1" type="revolute">
    <origin rpy="-1.75269165877 0.0686359653419 -0.101002048759" xyz="-0.03444198 -0.082386 0.00076556"/>
    <axis xyz="-1.0 0.0 0.0"/>
    <parent link="l_palm"/>
    <child link="l_Rproximal"/>
    <dynamics damping="0.01"/>
    <limit effort="0.5" lower="0" upper="1.57079632679" velocity="1.0"/>
  </joint>
  <transmission name="tranl_R1">
    <type>transmission_interface/SimpleTransmission</type>
    <joint name="l_jointR1">
      <hardwareInterface>hardware_interface/PositionJointInterface</hardwareInterface>
    </joint>
    <actuator name="motorl_R1">
      <hardwareInterface>hardware_interface/PositionJointInterface</hardwareInterface>
      <mechanicalReduction>1</mechanicalReduction>
    </actuator>
  </transmission>
  <link name="l_Rmiddle">
    <inertial>
      <origin rpy="0 0 0" xyz="-0.0050627375168 0.000178703837342 -0.0113961050151"/>
      <mass value="0.0046468"/>
      <inertia ixx="3.60659e-07" ixy="2.95375e-10" ixz="3.96643e-12" iyy="4.02251e-07" iyz="7.4602e-09" izz="1.59669e-07"/>
    </inertial>
    <visual>
      <origin rpy="0 0 0" xyz="-0.0050623870358 1.46929686314e-07 -0.0129383300348"/>
      <geometry>
        <mesh filename="/export/home/strahl/dev/gaikpy/resources/urdf/nicol/meshes/RH8D/left/phalanx.stl" scale="0.001 0.001 0.001"/>
      </geometry>
      <material name="l_Rmiddle_color">
        <color rgba="0.74902 0.74902 0.74902 1.0"/>
      </material>
    </visual>
    <collision>
      <origin rpy="0 0 0" xyz="-0.0050623870358 1.46929686314e-07 -0.0129383300348"/>
      <geometry>
        <mesh filename="/export/home/strahl/dev/gaikpy/resources/urdf/nicol/meshes/RH8D/left/phalanx.stl" scale="0.001 0.001 0.001"/>
      </geometry>
    </collision>
  </link>
  <!-- joint l_Rmiddle__l_Rproximal -->
  <joint name="l_jointR2" type="revolute">
    <origin rpy="0 0 0" xyz="6.25090808729e-05 0 -0.025874910111"/>
    <axis xyz="-1.0 0.0 0.0"/>
    <parent link="l_Rproximal"/>
    <child link="l_Rmiddle"/>
    <dynamics damping="0.001"/>
    <limit effort="0.5" lower="0" upper="1.57079632679" velocity="1.0"/>
  </joint>
  <transmission name="tranl_R2">
    <type>transmission_interface/SimpleTransmission</type>
    <joint name="l_jointR2">
      <hardwareInterface>hardware_interface/PositionJointInterface</hardwareInterface>
    </joint>
    <actuator name="motorl_R2">
      <hardwareInterface>hardware_interface/PositionJointInterface</hardwareInterface>
      <mechanicalReduction>1</mechanicalReduction>
    </actuator>
  </transmission>
  <link name="l_Rtip">
    <inertial>
      <origin rpy="0 0 0" xyz="-0.00506262889447 0.000158864121429 -0.00949029810479"/>
      <mass value="0.00398141"/>
      <inertia ixx="2.27393e-07" ixy="-4.487e-12" ixz="-6.19169e-12" iyy="2.50732e-07" iyz="3.7689e-09" izz="1.09262e-07"/>
    </inertial>
    <visual>
      <origin rpy="0 0 0" xyz="-0.0050625351673 -1.36100817935e-07 7.35728582779e-07"/>
      <geometry>
        <mesh filename="/export/home/strahl/dev/gaikpy/resources/urdf/nicol/meshes/RH8D/left/tip.stl" scale="0.001 0.001 0.001"/>
      </geometry>
      <material name="l_Rtip_color">
        <color rgba="0.74902 0.74902 0.74902 1.0"/>
      </material>
    </visual>
    <collision>
      <origin rpy="0 0 0" xyz="-0.0050625351673 -1.36100817935e-07 7.35728582779e-07"/>
      <geometry>
        <mesh filename="/export/home/strahl/dev/gaikpy/resources/urdf/nicol/meshes/RH8D/left/tip.stl" scale="0.001 0.001 0.001"/>
      </geometry>
    </collision>
  </link>
  <!-- joint l_Rtip__l_Rmiddle -->
  <joint name="l_jointR3" type="revolute">
    <origin rpy="0 0 0" xyz="6.25316406279e-05 1.7655252639e-07 -0.0258758931888"/>
    <axis xyz="-1.0 0.0 0.0"/>
    <parent link="l_Rmiddle"/>
    <child link="l_Rtip"/>
    <dynamics damping="0.001"/>
    <limit effort="0.5" lower="0" upper="1.57079632679" velocity="1.0"/>
  </joint>
  <transmission name="tranl_R3">
    <type>transmission_interface/SimpleTransmission</type>
    <joint name="l_jointR3">
      <hardwareInterface>hardware_interface/PositionJointInterface</hardwareInterface>
    </joint>
    <actuator name="motorl_R3">
      <hardwareInterface>hardware_interface/PositionJointInterface</hardwareInterface>
      <mechanicalReduction>1</mechanicalReduction>
    </actuator>
  </transmission>
  <!-- Middlefinger -->
  <link name="l_Mproximal">
    <inertial>
      <origin rpy="0 0 0" xyz="-0.00506268032219 0.000178369758776 -0.0113951959251"/>
      <mass value="0.0046468"/>
      <inertia ixx="3.60659e-07" ixy="2.95375e-10" ixz="3.96643e-12" iyy="4.02251e-07" iyz="7.4602e-09" izz="1.59669e-07"/>
    </inertial>
    <visual>
      <origin rpy="0 0 0" xyz="-0.00506247065308 0 -0.0129379251166"/>
      <geometry>
        <mesh filename="/export/home/strahl/dev/gaikpy/resources/urdf/nicol/meshes/RH8D/left/phalanx.stl" scale="0.001 0.001 0.001"/>
      </geometry>
      <material name="l_Mproximal_color">
        <color rgba="0.74902 0.74902 0.74902 1.0"/>
      </material>
    </visual>
    <collision>
      <origin rpy="0 0 0" xyz="-0.00506247065308 0 -0.0129379251166"/>
      <geometry>
        <mesh filename="/export/home/strahl/dev/gaikpy/resources/urdf/nicol/meshes/RH8D/left/phalanx.stl" scale="0.001 0.001 0.001"/>
      </geometry>
    </collision>
  </link>
  <!-- joint l_Mtip__M2 -->
  <joint name="l_jointM1" type="revolute">
    <origin rpy="-1.74598210711 -0.0859373918966 0.0151910468121" xyz="-0.0095654 -0.082818 0.00164059"/>
    <axis xyz="-1.0 0.0 0.0"/>
    <parent link="l_palm"/>
    <child link="l_Mproximal"/>
    <dynamics damping="0.01"/>
    <limit effort="0.5" lower="0" upper="1.57079632679" velocity="1.0"/>
  </joint>
  <transmission name="tranl_M1">
    <type>transmission_interface/SimpleTransmission</type>
    <joint name="l_jointM1">
      <hardwareInterface>hardware_interface/PositionJointInterface</hardwareInterface>
    </joint>
    <actuator name="motorl_M1">
      <hardwareInterface>hardware_interface/PositionJointInterface</hardwareInterface>
      <mechanicalReduction>1</mechanicalReduction>
    </actuator>
  </transmission>
  <link name="l_Mmiddle">
    <inertial>
      <origin rpy="0 0 0" xyz="-0.00506269201108 0.000178473714736 -0.0113956264739"/>
      <mass value="0.0046468"/>
      <inertia ixx="3.60659e-07" ixy="2.95375e-10" ixz="3.96643e-12" iyy="4.02251e-07" iyz="7.4602e-09" izz="1.59669e-07"/>
    </inertial>
    <visual>
      <origin rpy="0 0 0" xyz="-0.00506256941423 0 -0.0129379268531"/>
      <geometry>
        <mesh filename="/export/home/strahl/dev/gaikpy/resources/urdf/nicol/meshes/RH8D/left/phalanx.stl" scale="0.001 0.001 0.001"/>
      </geometry>
      <material name="l_Mmiddle_color">
        <color rgba="0.74902 0.74902 0.74902 1.0"/>
      </material>
    </visual>
    <collision>
      <origin rpy="0 0 0" xyz="-0.00506256941423 0 -0.0129379268531"/>
      <geometry>
        <mesh filename="/export/home/strahl/dev/gaikpy/resources/urdf/nicol/meshes/RH8D/left/phalanx.stl" scale="0.001 0.001 0.001"/>
      </geometry>
    </collision>
  </link>
  <!-- joint  l_Mmiddle__Mproxima -->
  <joint name="l_jointM2" type="revolute">
    <origin rpy="0 0 0" xyz="6.25377180185e-05 0 -0.0258750444163"/>
    <axis xyz="-1.0 0.0 0.0"/>
    <parent link="l_Mproximal"/>
    <child link="l_Mmiddle"/>
    <dynamics damping="0.001"/>
    <limit effort="0.5" lower="0" upper="1.57079632679" velocity="1.0"/>
  </joint>
  <transmission name="tranl_M2">
    <type>transmission_interface/SimpleTransmission</type>
    <joint name="l_jointM2">
      <hardwareInterface>hardware_interface/PositionJointInterface</hardwareInterface>
    </joint>
    <actuator name="motorl_M2">
      <hardwareInterface>hardware_interface/PositionJointInterface</hardwareInterface>
      <mechanicalReduction>1</mechanicalReduction>
    </actuator>
  </transmission>
  <link name="l_Mtip">
    <inertial>
      <origin rpy="0 0 0" xyz="-0.0050627478165 0.00015921993426 -0.00949104619276"/>
      <mass value="0.00398141"/>
      <inertia ixx="2.27393e-07" ixy="-4.487e-12" ixz="-6.19169e-12" iyy="2.50732e-07" iyz="3.7689e-09" izz="1.09262e-07"/>
    </inertial>
    <visual>
      <origin rpy="0 0 0" xyz="-0.00506246830541 0 -3.8022196186e-07"/>
      <geometry>
        <mesh filename="/export/home/strahl/dev/gaikpy/resources/urdf/nicol/meshes/RH8D/left/optoforce.stl" scale="0.001 0.001 0.001"/>
      </geometry>
      <material name="l_Mtip_color">
        <color rgba="0.74902 0.74902 0.74902 1.0"/>
      </material>
    </visual>
    <collision>
      <origin rpy="0 0 0" xyz="-0.00506246830541 0 -3.8022196186e-07"/>
      <geometry>
        <mesh filename="/export/home/strahl/dev/gaikpy/resources/urdf/nicol/meshes/RH8D/left/optoforce.stl" scale="0.001 0.001 0.001"/>
      </geometry>
    </collision>
  </link>
  <!-- joint l_Mtip_l_Mmiddle -->
  <joint name="l_jointM3" type="revolute">
    <origin rpy="0 0 0" xyz="6.24372402321e-05 0 -0.0258750426798"/>
    <axis xyz="-1.0 0.0 0.0"/>
    <parent link="l_Mmiddle"/>
    <child link="l_Mtip"/>
    <dynamics damping="0.001"/>
    <limit effort="0.5" lower="0" upper="1.57079632679" velocity="1.0"/>
  </joint>
  <transmission name="tranl_M3">
    <type>transmission_interface/SimpleTransmission</type>
    <joint name="l_jointM3">
      <hardwareInterface>hardware_interface/PositionJointInterface</hardwareInterface>
    </joint>
    <actuator name="motorl_M3">
      <hardwareInterface>hardware_interface/PositionJointInterface</hardwareInterface>
      <mechanicalReduction>1</mechanicalReduction>
    </actuator>
  </transmission>
  <!-- Little finger -->
  <link name="l_Pproximal">
    <inertial>
      <origin rpy="0 0 0" xyz="-0.00506265004772 0.000178471691603 -0.0113954440839"/>
      <mass value="0.0046468"/>
      <inertia ixx="3.60659e-07" ixy="2.95375e-10" ixz="3.96643e-12" iyy="4.02251e-07" iyz="7.4602e-09" izz="1.59669e-07"/>
    </inertial>
    <visual>
      <origin rpy="0 0 0" xyz="-0.00506242096312 0 -0.0129379154082"/>
      <geometry>
        <mesh filename="/export/home/strahl/dev/gaikpy/resources/urdf/nicol/meshes/RH8D/left/phalanx.stl" scale="0.001 0.001 0.001"/>
      </geometry>
      <material name="l_Pproximal_color">
        <color rgba="0.74902 0.74902 0.74902 1.0"/>
      </material>
    </visual>
    <collision>
      <origin rpy="0 0 0" xyz="-0.00506242096312 0 -0.0129379154082"/>
      <geometry>
        <mesh filename="/export/home/strahl/dev/gaikpy/resources/urdf/nicol/meshes/RH8D/left/phalanx.stl" scale="0.001 0.001 0.001"/>
      </geometry>
    </collision>
  </link>
  <!-- joint l_Pproximal__palm -->
  <joint name="l_jointL1" type="revolute">
    <origin rpy="-1.77486172903 0.138702392285 -0.20406540224" xyz="-0.0591609 -0.07417 0.00246184"/>
    <axis xyz="-1.0 0.0 0.0"/>
    <parent link="l_palm"/>
    <child link="l_Pproximal"/>
    <dynamics damping="0.01"/>
    <limit effort="0.5" lower="0" upper="1.57079632679" velocity="1.0"/>
  </joint>
  <transmission name="tranl_L1">
    <type>transmission_interface/SimpleTransmission</type>
    <joint name="l_jointL1">
      <hardwareInterface>hardware_interface/PositionJointInterface</hardwareInterface>
    </joint>
    <actuator name="motorl_L1">
      <hardwareInterface>hardware_interface/PositionJointInterface</hardwareInterface>
      <mechanicalReduction>1</mechanicalReduction>
    </actuator>
  </transmission>
  <link name="l_Pmiddle">
    <inertial>
      <origin rpy="0 0 0" xyz="-0.00506271792241 0.000178454269957 -0.0113956275282"/>
      <mass value="0.0046468"/>
      <inertia ixx="3.60659e-07" ixy="2.95375e-10" ixz="3.96643e-12" iyy="4.02251e-07" iyz="7.4602e-09" izz="1.59669e-07"/>
    </inertial>
    <visual>
      <origin rpy="0 0 0" xyz="-0.00506232259591 0 -0.0129378963001"/>
      <geometry>
        <mesh filename="/export/home/strahl/dev/gaikpy/resources/urdf/nicol/meshes/RH8D/left/phalanx.stl" scale="0.001 0.001 0.001"/>
      </geometry>
      <material name="l_Pmiddle_color">
        <color rgba="0.74902 0.74902 0.74902 1.0"/>
      </material>
    </visual>
    <collision>
      <origin rpy="0 0 0" xyz="-0.00506232259591 0 -0.0129378963001"/>
      <geometry>
        <mesh filename="/export/home/strahl/dev/gaikpy/resources/urdf/nicol/meshes/RH8D/left/phalanx.stl" scale="0.001 0.001 0.001"/>
      </geometry>
    </collision>
  </link>
  <!-- joint l_Pmiddle__l_Pproximal -->
  <joint name="l_jointL2" type="revolute">
    <origin rpy="0 0 0" xyz="6.25112164948e-05 0 -0.0258751651529"/>
    <axis xyz="-1.0 0.0 0.0"/>
    <parent link="l_Pproximal"/>
    <child link="l_Pmiddle"/>
    <dynamics damping="0.001"/>
    <limit effort="0.5" lower="0" upper="1.57079632679" velocity="1.0"/>
  </joint>
  <transmission name="tranl_L2">
    <type>transmission_interface/SimpleTransmission</type>
    <joint name="l_jointL2">
      <hardwareInterface>hardware_interface/PositionJointInterface</hardwareInterface>
    </joint>
    <actuator name="motorl_L2">
      <hardwareInterface>hardware_interface/PositionJointInterface</hardwareInterface>
      <mechanicalReduction>1</mechanicalReduction>
    </actuator>
  </transmission>
  <link name="l_Ptip">
    <inertial>
      <origin rpy="0 0 0" xyz="-0.00506265913629 0.000159136938405 -0.00949076905022"/>
      <mass value="0.00398141"/>
      <inertia ixx="2.27393e-07" ixy="-4.487e-12" ixz="-6.19169e-12" iyy="2.50732e-07" iyz="3.7689e-09" izz="1.09262e-07"/>
    </inertial>
    <visual>
      <origin rpy="0 0 0" xyz="-0.00506253237144 0 0"/>
      <geometry>
        <mesh filename="/export/home/strahl/dev/gaikpy/resources/urdf/nicol/meshes/RH8D/left/tip.stl" scale="0.001 0.001 0.001"/>
      </geometry>
      <material name="l_Ptip_color">
        <color rgba="0.74902 0.74902 0.74902 1.0"/>
      </material>
    </visual>
    <collision>
      <origin rpy="0 0 0" xyz="-0.00506253237144 0 0"/>
      <geometry>
        <mesh filename="/export/home/strahl/dev/gaikpy/resources/urdf/nicol/meshes/RH8D/left/tip.stl" scale="0.001 0.001 0.001"/>
      </geometry>
    </collision>
  </link>
  <!-- joint l_Ptip__Pmiddle -->
  <joint name="l_jointL3" type="revolute">
    <origin rpy="0 0 0" xyz="6.26026708029e-05 0 -0.0258751560801"/>
    <axis xyz="-1.0 0.0 0.0"/>
    <parent link="l_Pmiddle"/>
    <child link="l_Ptip"/>
    <dynamics damping="0.001"/>
    <limit effort="0.5" lower="0" upper="1.57079632679" velocity="1.0"/>
  </joint>
  <transmission name="tranl_L3">
    <type>transmission_interface/SimpleTransmission</type>
    <joint name="l_jointL3">
      <hardwareInterface>hardware_interface/PositionJointInterface</hardwareInterface>
    </joint>
    <actuator name="motorl_L3">
      <hardwareInterface>hardware_interface/PositionJointInterface</hardwareInterface>
      <mechanicalReduction>1</mechanicalReduction>
    </actuator>
  </transmission>
  <!-- Thumb -->
  <link name="l_thumb base">
    <inertial>
      <origin rpy="-0.392699081699 0 0" xyz="5.41241550495e-07 -0.0139591752938 0.0075370998152"/>
      <mass value="0.00705621"/>
      <inertia ixx="5.42596e-07" ixy="4.46196e-11" ixz="-1.43331e-11" iyy="3.55499e-07" iyz="4.00664e-08" izz="5.38335e-07"/>
    </inertial>
    <visual>
      <origin rpy="0 0 0" xyz="2.08727329871e-07 -0.0143541114376 0.0211785487783"/>
      <geometry>
        <mesh filename="/export/home/strahl/dev/gaikpy/resources/urdf/nicol/meshes/RH8D/left/thumb base.stl" scale="0.001 0.001 0.001"/>
      </geometry>
      <material name="l_thumb base_color">
        <color rgba="0.74902 0.74902 0.74902 1.0"/>
      </material>
    </visual>
    <collision>
      <origin rpy="0 0 0" xyz="2.08727329871e-07 -0.0143541114376 0.0211785487783"/>
      <geometry>
        <mesh filename="/export/home/strahl/dev/gaikpy/resources/urdf/nicol/meshes/RH8D/left/thumb base.stl" scale="0.001 0.001 0.001"/>
      </geometry>
    </collision>
  </link>
  <!-- joint palm_thumb_base -->
  <joint name="l_jointT0" type="revolute">
    <origin rpy="-1.57079652646 -1.26729978315 -1.81210600928" xyz="-0.0078751 -0.035115 0.00101669"/>
    <axis xyz="0.0 0.866025655797 -0.5000003546"/>
    <parent link="l_palm"/>
    <child link="l_thumb base"/>
    <dynamics damping="0.01"/>
    <limit effort="0.5" lower="0" upper="1.57079632679" velocity="1.0"/>
  </joint>
  <transmission name="tranl_T0">
    <type>transmission_interface/SimpleTransmission</type>
    <joint name="l_jointT0">
      <hardwareInterface>hardware_interface/PositionJointInterface</hardwareInterface>
    </joint>
    <actuator name="motorl_T0">
      <hardwareInterface>hardware_interface/PositionJointInterface</hardwareInterface>
      <mechanicalReduction>1</mechanicalReduction>
    </actuator>
  </transmission>
  <link name="l_Tproximal">
    <inertial>
      <origin rpy="0 0 0" xyz="0.00509118037371 -0.000108367330619 -0.00917567646424"/>
      <mass value="0.00379261"/>
      <inertia ixx="3.44891e-07" ixy="-5.85841e-09" ixz="-1.40349e-09" iyy="2.90581e-07" iyz="-9.57879e-09" izz="2.1814e-07"/>
    </inertial>
    <visual>
      <origin rpy="0 0 0" xyz="0.00506267871976 -5.69675469075e-07 -0.0107931270549"/>
      <geometry>
        <mesh filename="/export/home/strahl/dev/gaikpy/resources/urdf/nicol/meshes/RH8D/left/thumb_phalanx.stl" scale="0.001 0.001 0.001"/>
      </geometry>
      <material name="l_Tproximal_color">
        <color rgba="0.74902 0.74902 0.74902 1.0"/>
      </material>
    </visual>
    <collision>
      <origin rpy="0 0 0" xyz="0.00506267871976 -5.69675469075e-07 -0.0107931270549"/>
      <geometry>
        <mesh filename="/export/home/strahl/dev/gaikpy/resources/urdf/nicol/meshes/RH8D/left/thumb_phalanx.stl" scale="0.001 0.001 0.001"/>
      </geometry>
    </collision>
  </link>
  <!-- joint l_Tproximal_thumb_base -->
  <joint name="l_jointT1" type="revolute">
    <origin rpy="3.14159265359 0 0" xyz="-0.00512499670326 -0.0143547805534 0.0211783500758"/>
    <axis xyz="-1.0 0.0 0.0"/>
    <parent link="l_thumb base"/>
    <child link="l_Tproximal"/>
    <dynamics damping="0.01"/>
    <limit effort="0.5" lower="0" upper="1.57079632679" velocity="1.0"/>
  </joint>
  <transmission name="tranl_T1">
    <type>transmission_interface/SimpleTransmission</type>
    <joint name="l_jointT1">
      <hardwareInterface>hardware_interface/PositionJointInterface</hardwareInterface>
    </joint>
    <actuator name="motorl_T1">
      <hardwareInterface>hardware_interface/PositionJointInterface</hardwareInterface>
      <mechanicalReduction>1</mechanicalReduction>
    </actuator>
  </transmission>
  <link name="l_Tmiddle">
    <inertial>
      <origin rpy="0 0 0" xyz="0.00509145714593 -0.000109508075581 -0.00917619264503"/>
      <mass value="0.00379261"/>
      <inertia ixx="3.44891e-07" ixy="-5.85841e-09" ixz="-1.40349e-09" iyy="2.90581e-07" iyz="-9.57879e-09" izz="2.1814e-07"/>
    </inertial>
    <visual>
      <origin rpy="0 0 0" xyz="0.00506239138307 3.57868434941e-07 -0.0107928880801"/>
      <geometry>
        <mesh filename="/export/home/strahl/dev/gaikpy/resources/urdf/nicol/meshes/RH8D/left/thumb_phalanx.stl" scale="0.001 0.001 0.001"/>
      </geometry>
      <material name="l_Tmiddle_color">
        <color rgba="0.74902 0.74902 0.74902 1.0"/>
      </material>
    </visual>
    <collision>
      <origin rpy="0 0 0" xyz="0.00506239138307 3.57868434941e-07 -0.0107928880801"/>
      <geometry>
        <mesh filename="/export/home/strahl/dev/gaikpy/resources/urdf/nicol/meshes/RH8D/left/thumb_phalanx.stl" scale="0.001 0.001 0.001"/>
      </geometry>
    </collision>
  </link>
  <!-- joint Tmiddle__l_Tproximal -->
  <joint name="l_jointT2" type="revolute">
    <origin rpy="0 0 0" xyz="-0.000562285554381 -6.82918828571e-07 -0.021586139018"/>
    <axis xyz="-1.0 0.0 0.0"/>
    <parent link="l_Tproximal"/>
    <child link="l_Tmiddle"/>
    <dynamics damping="0.001"/>
    <limit effort="0.5" lower="0" upper="1.57079632679" velocity="1.0"/>
  </joint>
  <transmission name="tranl_T2">
    <type>transmission_interface/SimpleTransmission</type>
    <joint name="l_jointT2">
      <hardwareInterface>hardware_interface/PositionJointInterface</hardwareInterface>
    </joint>
    <actuator name="motorl_T2">
      <hardwareInterface>hardware_interface/PositionJointInterface</hardwareInterface>
      <mechanicalReduction>1</mechanicalReduction>
    </actuator>
  </transmission>
  <link name="l_Ttip">
    <inertial>
      <origin rpy="0 0 0" xyz="0.00506285640086 0.000158437874597 -0.00949116013742"/>
      <mass value="0.00398141"/>
      <inertia ixx="2.27393e-07" ixy="-4.487e-12" ixz="-6.19169e-12" iyy="2.50732e-07" iyz="3.7689e-09" izz="1.09262e-07"/>
    </inertial>
    <visual>
      <origin rpy="0 0 0" xyz="0.00506245947166 1.1554397894e-07 0"/>
      <geometry>
        <mesh filename="/export/home/strahl/dev/gaikpy/resources/urdf/nicol/meshes/RH8D/left/tip.stl" scale="0.001 0.001 0.001"/>
      </geometry>
      <material name="l_Ttip_color">
        <color rgba="0.74902 0.74902 0.74902 1.0"/>
      </material>
    </visual>
    <collision>
      <origin rpy="0 0 0" xyz="0.00506245947166 1.1554397894e-07 0"/>
      <geometry>
        <mesh filename="/export/home/strahl/dev/gaikpy/resources/urdf/nicol/meshes/RH8D/left/tip.stl" scale="0.001 0.001 0.001"/>
      </geometry>
    </collision>
  </link>
  <!-- joint l_Ttip__T2 -->
  <joint name="l_jointT3" type="revolute">
    <origin rpy="0 0 0" xyz="-6.26114843445e-05 3.61581448449e-07 -0.0215859828359"/>
    <axis xyz="-1.0 0.0 0.0"/>
    <parent link="l_Tmiddle"/>
    <child link="l_Ttip"/>
    <dynamics damping="0.001"/>
    <limit effort="0.5" lower="0" upper="1.57079632679" velocity="1.0"/>
  </joint>
  <transmission name="tranl_T3">
    <type>transmission_interface/SimpleTransmission</type>
    <joint name="l_jointT3">
      <hardwareInterface>hardware_interface/PositionJointInterface</hardwareInterface>
    </joint>
    <actuator name="motorl_T3">
      <hardwareInterface>hardware_interface/PositionJointInterface</hardwareInterface>
      <mechanicalReduction>1</mechanicalReduction>
    </actuator>
  </transmission>
  <!-- Index finger -->
  <link name="l_Iproximal">
    <inertial>
      <origin rpy="0 0 0" xyz="-0.00506269303095 0.000178661194879 -0.0113960183486"/>
      <mass value="0.0046468"/>
      <inertia ixx="3.60659e-07" ixy="2.95375e-10" ixz="3.96643e-12" iyy="4.02251e-07" iyz="7.4602e-09" izz="1.59669e-07"/>
    </inertial>
    <visual>
      <origin rpy="0 0 0" xyz="-0.00506252426882 0 -0.0129374369629"/>
      <geometry>
        <mesh filename="/export/home/strahl/dev/gaikpy/resources/urdf/nicol/meshes/RH8D/left/phalanx.stl" scale="0.001 0.001 0.001"/>
      </geometry>
      <material name="l_Iproximal_color">
        <color rgba="0.74902 0.74902 0.74902 1.0"/>
      </material>
    </visual>
    <collision>
      <origin rpy="0 0 0" xyz="-0.00506252426882 0 -0.0129374369629"/>
      <geometry>
        <mesh filename="/export/home/strahl/dev/gaikpy/resources/urdf/nicol/meshes/RH8D/left/phalanx.stl" scale="0.001 0.001 0.001"/>
      </geometry>
    </collision>
  </link>
  <!-- joint l_Iproximal__palm -->
  <joint name="l_jointI1" type="revolute">
    <origin rpy="-1.76215945719 -0.155855069444 0.117563149369" xyz="0.015314 -0.080697 0.00509984"/>
    <axis xyz="-1.0 0.0 0.0"/>
    <parent link="l_palm"/>
    <child link="l_Iproximal"/>
    <dynamics damping="0.01"/>
    <limit effort="0.5" lower="0" upper="1.57079632679" velocity="1.0"/>
  </joint>
  <transmission name="tranl_I1">
    <type>transmission_interface/SimpleTransmission</type>
    <joint name="l_jointI1">
      <hardwareInterface>hardware_interface/PositionJointInterface</hardwareInterface>
    </joint>
    <actuator name="motorl_I1">
      <hardwareInterface>hardware_interface/PositionJointInterface</hardwareInterface>
      <mechanicalReduction>1</mechanicalReduction>
    </actuator>
  </transmission>
  <link name="l_Imiddle">
    <inertial>
      <origin rpy="0 0 0" xyz="-0.00506266070615 0.000178528721729 -0.0113957955067"/>
      <mass value="0.0046468"/>
      <inertia ixx="3.60659e-07" ixy="2.95375e-10" ixz="3.96643e-12" iyy="4.02251e-07" iyz="7.4602e-09" izz="1.59669e-07"/>
    </inertial>
    <visual>
      <origin rpy="0 0 0" xyz="-0.00506251340308 0 -0.0129374501153"/>
      <geometry>
        <mesh filename="/export/home/strahl/dev/gaikpy/resources/urdf/nicol/meshes/RH8D/left/phalanx.stl" scale="0.001 0.001 0.001"/>
      </geometry>
      <material name="l_Imiddle_color">
        <color rgba="0.74902 0.74902 0.74902 1.0"/>
      </material>
    </visual>
    <collision>
      <origin rpy="0 0 0" xyz="-0.00506251340308 0 -0.0129374501153"/>
      <geometry>
        <mesh filename="/export/home/strahl/dev/gaikpy/resources/urdf/nicol/meshes/RH8D/left/phalanx.stl" scale="0.001 0.001 0.001"/>
      </geometry>
    </collision>
  </link>
  <!-- joint Imiddle__L1imal -->
  <joint name="l_jointI2" type="revolute">
    <origin rpy="0 0 0" xyz="6.2440782901e-05 0 -0.025875292969"/>
    <axis xyz="-1.0 0.0 0.0"/>
    <parent link="l_Iproximal"/>
    <child link="l_Imiddle"/>
    <dynamics damping="0.001"/>
    <limit effort="0.5" lower="0" upper="1.57079632679" velocity="1.0"/>
  </joint>
  <transmission name="tranl_I2">
    <type>transmission_interface/SimpleTransmission</type>
    <joint name="l_jointI2">
      <hardwareInterface>hardware_interface/PositionJointInterface</hardwareInterface>
    </joint>
    <actuator name="motorl_I2">
      <hardwareInterface>hardware_interface/PositionJointInterface</hardwareInterface>
      <mechanicalReduction>1</mechanicalReduction>
    </actuator>
  </transmission>
  <link name="l_Itip">
    <inertial>
      <origin rpy="0 0 0" xyz="-0.00506271582253 0.000159256228073 -0.00949120545948"/>
      <mass value="0.00398141"/>
      <inertia ixx="2.27393e-07" ixy="-4.487e-12" ixz="-6.19169e-12" iyy="2.50732e-07" iyz="3.7689e-09" izz="1.09262e-07"/>
    </inertial>
    <visual>
      <origin rpy="0 0 0" xyz="-0.00506254118036 1.43997639479e-07 -3.82707825153e-07"/>
      <geometry>
        <mesh filename="/export/home/strahl/dev/gaikpy/resources/urdf/nicol/meshes/RH8D/left/tip.stl" scale="0.001 0.001 0.001"/>
      </geometry>
      <material name="l_Itip_color">
        <color rgba="0.74902 0.74902 0.74902 1.0"/>
      </material>
    </visual>
    <collision>
      <origin rpy="0 0 0" xyz="-0.00506254118036 1.43997639479e-07 -3.82707825153e-07"/>
      <geometry>
        <mesh filename="/export/home/strahl/dev/gaikpy/resources/urdf/nicol/meshes/RH8D/left/tip.stl" scale="0.001 0.001 0.001"/>
      </geometry>
    </collision>
  </link>
  <!-- joint Itip__L2 -->
  <joint name="l_jointI3" type="revolute">
    <origin rpy="0 0 0" xyz="6.2578385226e-05 -2.1183475668e-07 -0.0258743408417"/>
    <axis xyz="-1.0 0.0 0.0"/>
    <parent link="l_Imiddle"/>
    <child link="l_Itip"/>
    <dynamics damping="0.001"/>
    <limit effort="0.5" lower="0" upper="1.57079632679" velocity="1.0"/>
  </joint>
  <transmission name="tranl_I3">
    <type>transmission_interface/SimpleTransmission</type>
    <joint name="l_jointI3">
      <hardwareInterface>hardware_interface/PositionJointInterface</hardwareInterface>
    </joint>
    <actuator name="motorl_I3">
      <hardwareInterface>hardware_interface/PositionJointInterface</hardwareInterface>
      <mechanicalReduction>1</mechanicalReduction>
    </actuator>
  </transmission>
  <!-- link 1 -->
  <link name="l_link1">
    <collision>
      <origin rpy="0 0 0" xyz="0 0 0"/>
      <geometry>
        <mesh filename="/export/home/strahl/dev/gaikpy/resources/urdf/nicol/meshes/open_manipulator/link_1.stl" scale="0.001 0.001 0.001"/>
      </geometry>
    </collision>
    <visual>
      <origin rpy="0 0 0" xyz="0 0 0"/>
      <geometry>
        <mesh filename="/export/home/strahl/dev/gaikpy/resources/urdf/nicol/meshes/open_manipulator/link_1.stl" scale="0.001 0.001 0.001"/>
      </geometry>
      <material name="grey"/>
    </visual>
    <inertial>
      <origin rpy="0 0 0" xyz="0.00023 0.00000 0.06223"/>
      <mass value="0.85644"/>
      <inertia ixx="1.0" ixy="0.0" ixz="0.0" iyy="1.0" iyz="0.0" izz="1.0"/>
      <!--<inertia ixx="0.00121064" ixy="0.0" ixz="0.00001100" iyy="0.00120886" iyz="0.0" izz="0.00038103" />-->
    </inertial>
  </link>
  <!-- Joint 1 -->
  <joint name="l_joint1" type="revolute">
    <parent link="l_link1"/>
    <child link="l_link2"/>
    <origin rpy="0 0 3.14159265359" xyz="0.0 0.0 0.126"/>
    <axis xyz="0 0 1"/>
    <limit effort="1000" lower="-1.57079632679" upper="1.57079632679" velocity="6.5"/>
    <dynamics damping="0.7"/>
    <!-- <safety_controller k_velocity="10" k_position="15" soft_lower_limit="-2.0" soft_upper_limit="0.5" /> -->
  </joint>
  <transmission name="tranl_1">
    <type>transmission_interface/SimpleTransmission</type>
    <joint name="l_joint1">
      <hardwareInterface>hardware_interface/PositionJointInterface</hardwareInterface>
    </joint>
    <actuator name="motorl_1">
      <hardwareInterface>hardware_interface/PositionJointInterface</hardwareInterface>
      <mechanicalReduction>1</mechanicalReduction>
    </actuator>
  </transmission>
  <!-- link 2 -->
  <link name="l_link2">
    <collision>
      <origin rpy="0 0 0" xyz="0 0 0"/>
      <geometry>
        <mesh filename="/export/home/strahl/dev/gaikpy/resources/urdf/nicol/meshes/open_manipulator/link_2.stl" scale="0.001 0.001 0.001"/>
      </geometry>
    </collision>
    <visual>
      <origin rpy="0 0 0" xyz="0 0 0"/>
      <geometry>
        <mesh filename="/export/home/strahl/dev/gaikpy/resources/urdf/nicol/meshes/open_manipulator/link_2.stl" scale="0.001 0.001 0.001"/>
      </geometry>
      <material name="grey"/>
    </visual>
    <inertial>
      <origin rpy="0 0 0" xyz="0.00000 0.00080 0.03183"/>
      <!--<origin xyz="0.00000 -0.06820 -0.00117" rpy="0 0 0"/>-->
      <mass value="0.94658"/>
      <inertia ixx="1.0" ixy="0.0" ixz="0.0" iyy="1.0" iyz="0.0" izz="1.0"/>
      <!--<inertia ixx="0.00152547" ixy="0.0" ixz="0.0" iyy="0.00045954" iyz="-0.00001086" izz="0.00151740" />-->
    </inertial>
  </link>
  <!-- Joint 2 -->
  <joint name="l_joint2" type="revolute">
    <parent link="l_link2"/>
    <child link="l_link3"/>
    <origin rpy="0 0 0" xyz="0.0 0.069 0.033"/>
    <axis xyz="0 1 0"/>
    <limit effort="1000" lower="-1.57079632679" upper="1.57079632679" velocity="6.5"/>
    <dynamics damping="0.7"/>
  </joint>
  <transmission name="tranl_2">
    <type>transmission_interface/SimpleTransmission</type>
    <joint name="l_joint2">
      <hardwareInterface>hardware_interface/PositionJointInterface</hardwareInterface>
    </joint>
    <actuator name="motorl_2">
      <hardwareInterface>hardware_interface/PositionJointInterface</hardwareInterface>
      <mechanicalReduction>1</mechanicalReduction>
    </actuator>
  </transmission>
  <!-- link 3 -->
  <link name="l_link3">
    <collision>
      <origin rpy="0 0 0" xyz="0 0 0"/>
      <geometry>
        <mesh filename="/export/home/strahl/dev/gaikpy/resources/urdf/nicol/meshes/open_manipulator/link_3.stl" scale="0.001 0.001 0.001"/>
      </geometry>
    </collision>
    <visual>
      <origin rpy="0 0 0" xyz="0 0 0"/>
      <geometry>
        <mesh filename="/export/home/strahl/dev/gaikpy/resources/urdf/nicol/meshes/open_manipulator/link_3.stl" scale="0.001 0.001 0.001"/>
      </geometry>
      <material name="grey"/>
    </visual>
    <inertial>
      <origin rpy="0 0 0" xyz="0.01768 -0.06881 0.20524"/>
      <!--<origin xyz="-0.01232 -0.05731 -0.05876" rpy="0 0 0"/>-->
      <mass value="1.30260"/>
      <inertia ixx="1.0" ixy="0.0" ixz="0.0" iyy="1.0" iyz="0.0" izz="1.0"/>
      <!--<inertia ixx="0.01111021" ixy="0.00001331" ixz="-0.00134208" iyy="0.01046642" iyz="0.00016235" izz="0.00202081" />-->
    </inertial>
  </link>
  <!-- Joint 3 -->
  <joint name="l_joint3" type="revolute">
    <parent link="l_link3"/>
    <child link="l_link4"/>
    <origin rpy="0 0 0" xyz="0.03000 -0.01150 0.26400"/>
    <axis xyz="0 1 0"/>
    <limit effort="1000" lower="-1.57079632679" upper="1.57079632679" velocity="6.5"/>
    <dynamics damping="0.7"/>
  </joint>
  <transmission name="tranl_3">
    <type>transmission_interface/SimpleTransmission</type>
    <joint name="l_joint3">
      <hardwareInterface>hardware_interface/PositionJointInterface</hardwareInterface>
    </joint>
    <actuator name="motorl_3">
      <hardwareInterface>hardware_interface/PositionJointInterface</hardwareInterface>
      <mechanicalReduction>1</mechanicalReduction>
    </actuator>
  </transmission>
  <!-- link 4 -->
  <link name="l_link4">
    <collision>
      <origin rpy="0 0 0" xyz="0 0 0"/>
      <geometry>
        <mesh filename="/export/home/strahl/dev/gaikpy/resources/urdf/nicol/meshes/open_manipulator/link_4.stl" scale="0.001 0.001 0.001"/>
      </geometry>
    </collision>
    <visual>
      <origin rpy="0 0 0" xyz="0 0 0"/>
      <geometry>
        <mesh filename="/export/home/strahl/dev/gaikpy/resources/urdf/nicol/meshes/open_manipulator/link_4.stl" scale="0.001 0.001 0.001"/>
      </geometry>
      <material name="grey"/>
    </visual>
    <inertial>
      <origin rpy="0 0 0" xyz="0.12475 -0.05716 0.02979"/>
      <!--<origin xyz="-0.07025 0.00034 -0.00021" rpy="0 0 0"/>-->
      <mass value="1.15977"/>
      <inertia ixx="1.0" ixy="0.0" ixz="0.0" iyy="1.0" iyz="0.0" izz="1.0"/>
      <!--<inertia ixx="0.00096726" ixy="0.00004383" ixz="-0.00002771" iyy="0.00318801" iyz="0.00000627" izz="0.00341484" />-->
    </inertial>
  </link>
  <!-- Joint 4 -->
  <joint name="l_joint4" type="revolute">
    <parent link="l_link4"/>
    <child link="l_link5"/>
    <origin rpy="0 0 0" xyz="0.19500 -0.05750 0.03000"/>
    <axis xyz="1 0 0"/>
    <limit effort="1000" lower="-1.57079632679" upper="1.57079632679" velocity="6.5"/>
    <dynamics damping="0.1"/>
  </joint>
  <transmission name="tranl_4">
    <type>transmission_interface/SimpleTransmission</type>
    <joint name="l_joint4">
      <hardwareInterface>hardware_interface/PositionJointInterface</hardwareInterface>
    </joint>
    <actuator name="motorl_4">
      <hardwareInterface>hardware_interface/PositionJointInterface</hardwareInterface>
      <mechanicalReduction>1</mechanicalReduction>
    </actuator>
  </transmission>
  <!-- link 5 -->
  <link name="l_link5">
    <collision>
      <origin rpy="0 0 0" xyz="0 0 0"/>
      <geometry>
        <mesh filename="/export/home/strahl/dev/gaikpy/resources/urdf/nicol/meshes/open_manipulator/link_5.stl" scale="0.001 0.001 0.001"/>
      </geometry>
    </collision>
    <visual>
      <origin rpy="0 0 0" xyz="0 0 0"/>
      <geometry>
        <mesh filename="/export/home/strahl/dev/gaikpy/resources/urdf/nicol/meshes/open_manipulator/link_5.stl" scale="0.001 0.001 0.001"/>
      </geometry>
      <material name="grey"/>
    </visual>
    <inertial>
      <origin rpy="0 0 0" xyz="0.05642 -0.00217 0.00002"/>
      <!--<origin xyz="-0.00658 -0.04717 0.00002" rpy="0 0 0"/>-->
      <mass value="0.44688"/>
      <inertia ixx="1.0" ixy="0.0" ixz="0.0" iyy="1.0" iyz="0.0" izz="1.0"/>
      <!--<inertia ixx="0.00030285" ixy="0.00000761" ixz="0.00000031" iyy="0.00022339" iyz="-0.00000001" izz="0.00039766" />-->
    </inertial>
  </link>
  <!-- Joint 5 -->
  <joint name="l_joint5" type="revolute">
    <parent link="l_link5"/>
    <child link="l_link6"/>
    <origin rpy="0 0 0" xyz="0.06300 0.04500 0.00000"/>
    <axis xyz="0 1 0"/>
    <limit effort="1000" lower="-1.57079632679" upper="1.57079632679" velocity="6.5"/>
    <dynamics damping="0.1"/>
  </joint>
  <transmission name="tranl_5">
    <type>transmission_interface/SimpleTransmission</type>
    <joint name="l_joint5">
      <hardwareInterface>hardware_interface/PositionJointInterface</hardwareInterface>
    </joint>
    <actuator name="motorl_5">
      <hardwareInterface>hardware_interface/PositionJointInterface</hardwareInterface>
      <mechanicalReduction>1</mechanicalReduction>
    </actuator>
  </transmission>
  <!-- link 6 -->
  <link name="l_link6">
    <collision>
      <origin rpy="0 0 0" xyz="0 0 0"/>
      <geometry>
        <mesh filename="/export/home/strahl/dev/gaikpy/resources/urdf/nicol/meshes/open_manipulator/link_6.stl" scale="0.001 0.001 0.001"/>
      </geometry>
    </collision>
    <visual>
      <origin rpy="0 0 0" xyz="0 0 0"/>
      <geometry>
        <mesh filename="/export/home/strahl/dev/gaikpy/resources/urdf/nicol/meshes/open_manipulator/link_6.stl" scale="0.001 0.001 0.001"/>
      </geometry>
      <material name="grey"/>
    </visual>
    <inertial>
      <origin rpy="0 0 0" xyz="0.06831 -0.04457 0.00000"/>
      <!--<origin xyz="-0.05469 0.00043 0.00000" rpy="0 0 0"/>-->
      <mass value="0.43273"/>
      <inertia ixx="1.0" ixy="0.0" ixz="0.0" iyy="1.0" iyz="0.0" izz="1.0"/>
      <!--<inertia ixx="0.00021512" ixy="0.00001009" ixz="0.00000000" iyy="0.00042827" iyz="0.00000000" izz="0.00051436" />-->
    </inertial>
  </link>
  <!-- Joint 6 connects to hand base -->
  <joint name="l_joint6" type="revolute">
    <parent link="l_link6"/>
    <child link="l_RH8D_base"/>
    <origin rpy="0 1.57079632679 1.57079632679" xyz="0.12300 -0.04500 0.00000"/>
    <axis xyz="0 1 0"/>
    <limit effort="1000" lower="-1.57079632679" upper="1.57079632679" velocity="6.5"/>
    <dynamics damping="0.1"/>
  </joint>
  <transmission name="tranl_6">
    <type>transmission_interface/SimpleTransmission</type>
    <joint name="l_joint6">
      <hardwareInterface>hardware_interface/PositionJointInterface</hardwareInterface>
    </joint>
    <actuator name="motorl_6">
      <hardwareInterface>hardware_interface/PositionJointInterface</hardwareInterface>
      <mechanicalReduction>1</mechanicalReduction>
    </actuator>
  </transmission>
  <!-- Append right open_manipulator_p to robot_frame -->
  <joint name="r_base_joint" type="fixed">
    <origin rpy="1.57079632679 3.14159265359 0" xyz="-0.027 -0.0605 1.173"/>
    <parent link="world"/>
    <child link="r_link1"/>
  </joint>
  <!-- Append left open_manipulator_p to robot_frame -->
  <joint name="l_base_joint" type="fixed">
    <origin rpy="-1.57079632679 3.14159265359 0" xyz="-0.027 0.0605 1.173"/>
    <parent link="world"/>
    <child link="l_link1"/>
  </joint>
</robot>

